Workbook
Name _Order1: 255
Name _Sort: #REF!
Name _Sort: #REF!
Name JBA_CODE: [1]JBA_CODE!$A$2:$A$3134
Name JBA_CODE: [2]Allocation!$AC$2:$AC$3234
Name status_gray: #REF!
Name vertex42_copyright: "© 2015 Vertex42 LLC"
Name vertex42_id: "purchase-order-tracker.xlsx"
Name vertex42_title: "Purchase Order Tracker"

Sheet Optional tours_SUM
A1: *As of 27 Aug
A2: GROUP A2 | B2: SEP 14TH - A2 K-HERITAGE | J2: Min 25pax | K2: Closed
B3: GROUP | C3: OPTIONAL TOURS | D3: PICK-UP TIME | E3: ADULT | F3: CHD | G3: KID | H3: INFANT | I3: UPDATE STATUS
A4: LOTTE | B4: A2 | C4: K-HERITAGE | D4: 0.36111111 | E4: 9 | F4: 0 | G4: 0
A5: THE PLAZA | B5: A2 | C5: K-HERITAGE | D5: 0.36111111 | E5: 24 | F5: 0 | G5: 0
A6: INTER PARNAS | B6: A2 | C6: K-HERITAGE | D6: 0.29166667 | E6: 2 | F6: 0 | G6: 0
A7: TOTAL FOR A2 K-HERITAGE | E7: =SUM(E4:E6) -> 35 | F7: =SUM(F4:F6) -> 0 | G7: =SUM(G4:G6) -> 0
A9: GROUP A2 | B9: SEP 14TH - A2 K-NATURE | J9: Min 25pax | K9: 12 seats available
B10: GROUP | C10: OPTIONAL TOURS | D10: PICK-UP TIME | E10: ADULT | F10: CHD | G10: KID | H10: INFANT | I10: UPDATE STATUS
A11: LOTTE | B11: A2 | C11: K-NATURE | D11: 0.34027778 | E11: 14 | F11: 0 | G11: 0 | I11: 22Aug: Adult 16 -> 17 23Aug: Adult 17 -> 14/Child 1->0 (4 paxs change to K-wellness)
A12: THE PLAZA | B12: A2 | C12: K-NATURE | D12: 0.34027778 | E12: 7 | F12: 0 | G12: 0
A13: INTER PARNAS | B13: A2 | C13: K-NATURE | D13: 0.29166667 | E13: 2 | F13: 0 | G13: 0
A14: TOTAL FOR A2 K-NATURE | E14: =SUM(E11:E13) -> 23 | F14: =SUM(F11:F13) -> 0 | G14: =SUM(G11:G13) -> 0
A16: GROUP A1 | B16: SEP 15TH - A1 H-HERITAGE | J16: Min 25pax | K16: Closed
B17: GROUP | C17: OPTIONAL TOURS | D17: PICK-UP TIME | E17: ADULT | F17: CHD | G17: KID | H17: INFANT | I17: UPDATE STATUS
A18: FAIRMONT | B18: A1 | C18: K-HERITAGE | D18: 0.34722222 | E18: 55 | F18: 4 | G18: 0 | I18: 27Aug: Adult 49 -> 51 (2 new paxs)
A19: JW MARRIOTT | B19: A1 | C19: K-HERITAGE | D19: 0.375 | E19: 15 | F19: 0 | G19: 0 | I19: 27Aug: 1pax cancel, 1 new pax
A20: TOTAL FOR A1 K-HERITAGE | E20: =SUM(E18:E19) -> 70 | F20: =SUM(F18:F19) -> 4 | G20: =SUM(G18:G19) -> 0
A22: GROUP A1 | B22: SEP 15TH - A1 K-NATURE | J22: Min 25pax | K22: 10 seat available
B23: GROUP | C23: OPTIONAL TOURS | D23: PICK-UP TIME | E23: ADULT | F23: CHD | G23: KID | H23: INFANT | I23: UPDATE STATUS
A24: FAIRMONT | B24: A1 | C24: K-NATURE | D24: 0.33333333 | E24: 10 | F24: 0 | G24: 1
A25: JW MARRIOTT | B25: A1 | C25: K-NATURE | D25: 0.375 | E25: 13 | F25: 1 | G25: 0
A26: TOTAL FOR A1 K-NATURE | E26: =SUM(E24:E25) -> 23 | F26: =SUM(F24:F25) -> 1 | G26: =SUM(G24:G25) -> 1
A28: GROUP A1 & A2 | B28: SEP 16TH - A1 & A2 K-FOOD | J28: Min 15pax
B29: GROUP | C29: OPTIONAL TOURS | D29: PICK-UP TIME | E29: ADULT | F29: CHD | G29: KID | H29: INFANT | I29: UPDATE STATUS
A30: FAIRMONT | B30: A1 | C30: K-FOOD | D30: 0.35416667 | E30: 7 | F30: 1 | G30: 0
A31: JW MARRIOTT | B31: A1 | C31: K-FOOD | D31: 0.34722222 | E31: 20 | F31: 1 | G31: 0 | I31: 27Aug: 1pax cancel, 1 new pax
A32: TOTAL FOR A1 K-FOOD | E32: =SUM(E30:E31) -> 27 | F32: =SUM(F30:F31) -> 2 | G32: =SUM(G30:G31) -> 0 | K32: 1 seat available
A33: LOTTE | B33: A2 | C33: K-FOOD | D33: 0.38194444 | E33: 7 | F33: 0 | G33: 0
A34: THE PLAZA | B34: A2 | C34: K-FOOD | D34: 0.38194444 | E34: 2 | F34: 0 | G34: 0
A35: INTER PARNAS | B35: A2 | C35: K-FOOD | D35: 0.36805556 | E35: 7 | F35: 1 | G35: 0
A36: TOTAL FOR A2 K-FOOD | E36: =SUM(E33:E35) -> 16 | F36: =SUM(F33:F35) -> 1 | G36: =SUM(G33:G35) -> 0 | K36: Closed
A38: GROUP A1 & A2 | B38: SEP 16TH - A1 & A2 K-WELLNESS | J38: Min 25pax
B39: GROUP | C39: OPTIONAL TOURS | D39: PICK-UP TIME | E39: ADULT | F39: CHD | G39: KID | H39: INFANT | I39: UPDATE STATUS
A40: FAIRMONT | B40: A1 | C40: K-WELLNESS | D40: 0.35416667 | E40: 14 | F40: 0 | G40: 0 | K40: Lotte / Plaza / Fairmont — 3 seats available
A41: JW MARRIOTT | B41: A1 | C41: K-WELLNESS | D41: 0.33333333 | E41: 8 | F41: 0 | G41: 0
A42: TOTAL FOR A1 K-WELLNESS | E42: =SUM(E40:E41) -> 22 | F42: =SUM(F40:F41) -> 0 | G42: =SUM(G40:G41) -> 0 | K42: 1 seat available
A43: LOTTE | B43: A2 | C43: K-WELLNESS | D43: 0.38194444 | E43: 5 | F43: 1 | G43: 0 | I43: 22Aug: Adult 1 -> 2 23Aug: Adult 2->5/Child 0->1 (4 paxs change from K-Nature to K-Wellness) | K43: Lotte / Plaza / Fairmont — 3 seats available
A44: THE PLAZA | B44: A2 | C44: K-WELLNESS | D44: 0.38194444 | E44: 12 | F44: 0 | G44: 0 | K44: Lotte / Plaza / Fairmont — 3 seats available
A45: INTER PARNAS | B45: A2 | C45: K-WELLNESS | D45: 0.35416667 | E45: 2 | F45: 0 | G45: 0
...

Sheet DEPARTURE TIME
E1: GROUP A | F1: SUB-GROUP | G1: DATE | I1: GROUP B | J1: SUB-GROUP | K1: DATE
B2: K-Heritage | C2: Fairmont | E2: 0.34722222 | F2: A1 | G2: 15 SEP 25 | I2: 0.34722222 | J2: B1 | K2: 21 SEP 25
C3: JW Marriott | E3: 0.375 | F3: A1 | G3: 15 SEP 25 | I3: 0.375 | J3: B1 | K3: 21 SEP 25
C4: Inter Parnas | E4: 0.29166667 | F4: A2 | G4: 14 SEP 25 | I4: 0.3125 | J4: B2 | K4: 19 SEP 25
C5: Lotte | E5: 0.36111111 | F5: A2 | G5: 14 SEP 25 | I5: 0.36111111 | J5: B2 | K5: 19 SEP 25
C6: The Plaza | E6: 0.36111111 | F6: A2 | G6: 14 SEP 25 | I6: 0.36111111 | J6: B2 | K6: 19 SEP 25
B8: K-Nature | C8: Fairmont | E8: 0.33333333 | F8: A1 | G8: 15 SEP 25 | I8: 0.33333333 | J8: B1 | K8: 21 SEP 25
C9: JW Marriott | E9: 0.375 | F9: A1 | G9: 15 SEP 25 | I9: 0.375 | J9: B1 | K9: 21 SEP 25
C10: Inter Parnas | E10: 0.29166667 | F10: A2 | G10: 14 SEP 25 | I10: 0.29166667 | J10: B2 | K10: No Available
C11: Lotte | E11: 0.34027778 | F11: A2 | G11: 14 SEP 25 | I11: 0.34027778 | J11: B2 | K11: No Available
C12: The Plaza | E12: 0.34027778 | F12: A2 | G12: 14 SEP 25 | I12: 0.34027778 | J12: B2 | K12: No Available
B14: K-Food | C14: Fairmont | E14: 0.35416667 | F14: A1 | G14: 16 SEP 25 | I14: 0.35416667 | J14: B1 | K14: 20 SEP 25
C15: Lotte | E15: 0.38194444 | F15: A1 | G15: 16 SEP 25 | I15: 0.38194444 | J15: B1 | K15: 20 SEP 25
C16: The Plaza | E16: 0.38194444 | F16: A2 | G16: 16 SEP 25 | I16: 0.38194444 | J16: B2 | K16: 20 SEP 25
C17: JW Marriott | E17: 0.34722222 | F17: A2 | G17: 16 SEP 25 | I17: 0.34722222 | J17: B2 | K17: 20 SEP 25
C18: Inter Parnas | E18: 0.36805556 | F18: A2 | G18: 16 SEP 25 | I18: 0.36805556 | J18: B2 | K18: 20 SEP 25
B20: K-Wellness | C20: Fairmont | E20: 0.35416667 | F20: A1 | G20: 16 SEP 25 | I20: 0.35416667 | J20: B1 | K20: 20 SEP 25
C21: Lotte | E21: 0.38194444 | F21: A1 | G21: 16 SEP 25 | I21: 0.38194444 | J21: B1 | K21: 20 SEP 25
C22: The Plaza | E22: 0.38194444 | F22: A2 | G22: 16 SEP 25 | I22: 0.38194444 | J22: B2 | K22: 20 SEP 25
C23: JW Marriott | E23: 0.33333333 | F23: A2 | G23: 16 SEP 25 | I23: 0.33333333 | J23: B2 | K23: 20 SEP 25
C24: Inter Parnas | E24: 0.35416667 | F24: A2 | G24: 16 SEP 25 | I24: 0.35416667 | J24: B2 | K24: 20 SEP 25

Sheet PASSENGER LIST 27Aug_SUM
A1: Sub-Group | B1: Confirmation | C1: Primary registrant | D1: First Name | E1: Last Name | F1: Gender | G1: Passport Country | H1: AGE | I1: HOTEL | J1: Full day | K1: Half-day 1 | L1: Vegan | M1: REMARKS
A2: A2 | B2: CSNMQ7XNY2S | C2: CSNMQ7XNY2S | D2: Adeolu | E2: Durotoye | F2: Male | G2: Canada | H2: 55 | I2: LOTTE | L2: No | M2: Upgrade - Junior Suite
A3: A2 | B3: BQN5YMBRTZ9 | C3: BQN5YMBRTZ9 | D3: Olanrewaju | E3: Ogunkoya | F3: Male | G3: USA | H3: 55 | I3: LOTTE | L3: No
A4: A2 | B4: 8SNRDRCQPHQ | C4: BQN5YMBRTZ9 | D4: Bridget | E4: Taylor | F4: Female | G4: USA | H4: 55 | I4: LOTTE | L4: No
A5: A2 | B5: FLN6XZFQTLH | C5: FLN6XZFQTLH | D5: Abolade | E5: Akinropo | F5: Female | G5: USA | H5: 53 | I5: LOTTE | L5: No
A6: A2 | B6: VRNPD384X6N | C6: FLN6XZFQTLH | D6: Shola Jumoke | E6: Olori | F6: Female | G6: USA | H6: 65 | I6: LOTTE | L6: No
A7: A2 | B7: 4BNHL9C6RWT | C7: 4BNHL9C6RWT | D7: Onuwabhagbe Ayemere | E7: Ogudo | F7: Male | G7: Canada | H7: 46 | I7: LOTTE | L7: No
A8: A2 | B8: VCNYDFDGQ8C | C8: 4BNHL9C6RWT | D8: Jeffrey Jafaru | E8: Usman | F8: Male | G8: Canada | H8: 44 | I8: LOTTE | L8: No
A9: A2 | B9: 3FNT9CQ6CWC | C9: 3FNT9CQ6CWC | D9: Paul | E9: Adeyeye | F9: Male | G9: Canada | H9: 39 | I9: LOTTE | L9: No
A10: A2 | B10: D5NZNQTZ4S6 | C10: 3FNT9CQ6CWC | D10: Idowu Adekola | E10: Nafiu | F10: Male | G10: Canada | H10: 46 | I10: LOTTE
A11: A2 | B11: 64NQP9SW72V | C11: 64NQP9SW72V | D11: Folashade | E11: Awosanmi | F11: Female | G11: Canada | H11: 59 | I11: LOTTE | L11: No
A12: A2 | B12: 98NGTVNHG2X | C12: 64NQP9SW72V | D12: Sheri | E12: Agunbiade | F12: Female | G12: USA | H12: 54 | I12: LOTTE
A13: A2 | B13: FDNK6HN7Z9W | C13: FDNK6HN7Z9W | D13: Reynolds | E13: Edokpayi | F13: Male | G13: Canada | H13: 35 | I13: LOTTE | L13: No
A14: A2 | B14: MGNWBNQ27JY | C14: FDNK6HN7Z9W | D14: Osasogie Deborah | E14: Edokpayi | F14: Female | G14: Nigeria | H14: 31 | I14: LOTTE | L14: No
A15: A2 | B15: CQN557DDSNP | C15: FDNK6HN7Z9W | D15: Asher Nosamudiana | E15: Edokpayi | F15: Male | G15: Canada | H15: 1 | I15: LOTTE
A16: A2 | B16: P9NMQHFQRD2 | C16: P9NMQHFQRD2 | D16: Matthew Oluwasegun | E16: Adekoya | F16: Male | G16: Canada | H16: 29 | I16: LOTTE | L16: No
A17: A2 | B17: NWNWRK2YBF9 | C17: P9NMQHFQRD2 | D17: Michael Chinonso | E17: Okoro | F17: Male | G17: Nigeria | H17: 30 | I17: LOTTE | L17: No
A18: A2 | B18: RJNVLTN9XQ6 | C18: RJNVLTN9XQ6 | D18: Martins | E18: Onwuanimkwu | F18: Male | G18: Canada | H18: 55 | I18: LOTTE | L18: No
A19: A2 | B19: JXNK3R3NSZ7 | C19: RJNVLTN9XQ6 | D19: Blessing | E19: Onwuanimkwu | F19: Female | G19: Canada | H19: 47 | I19: LOTTE | L19: No
A20: A2 | B20: F8N53FQYVT4 | C20: F8N53FQYVT4 | D20: Aderonke | E20: Akingbola | F20: Female | G20: USA | H20: 64 | I20: LOTTE | L20: No
A21: A2 | B21: 7GN9XXSZTLX | C21: F8N53FQYVT4 | D21: Olugbenga | E21: Akingbola | F21: Male | G21: USA | H21: 69 | I21: LOTTE | L21: No
A22: A2 | B22: 3YND655CK6B | C22: F8N53FQYVT4 | D22: Cossi Modeste | E22: Yekpe | F22: Male | G22: USA | H22: 51 | I22: LOTTE | L22: No
A23: A2 | B23: XBN5PGXS4J8 | C23: F8N53FQYVT4 | D23: Florence | E23: Akouegnon | F23: Female | G23: USA | H23: 49 | I23: LOTTE | L23: No
A24: A2 | B24: 5XNV5YJQZ5J | C24: F8N53FQYVT4 | D24: Claudia Odiri | E24: Ukpolo | F24: Female | G24: USA | H24: 62 | I24: LOTTE | L24: No
A25: A2 | B25: 7WNV938LLQS | C25: F8N53FQYVT4 | D25: Adaeze Nwamaka | E25: Udezue | F25: Female | G25: USA | H25: 55 | I25: LOTTE | L25: No
A26: A2 | B26: VFNCKSMCL6W | C26: VFNCKSMCL6W | D26: Anuoluwapo Sarah | E26: Ayankoya | F26: Female | G26: Canada | H26: 54 | I26: LOTTE | L26: No
A27: A2 | B27: FXN27DWD69X | C27: VFNCKSMCL6W | D27: Babatunde Olufemi | E27: Ayankoya | F27: Male | G27: Canada | H27: 56 | I27: LOTTE | L27: No
... A33: A2 | B33: P8NSJDPN4XX | C33: NPNGSRN48GW | D33: Kofo Monsurah | E33: Keshinro | F33: Female | G33: USA | H33: 42 | I33: LOTTE | L33: No
A34: A1 | B34: NZN2Z5XYY4M | C34: NZN2Z5XYY4M | D34: Himawan | E34: Brasali | F34: Male | G34: USA | H34: 60 | I34: FAIRMONT | L34: No | M34: Busan -> Incheon Airport train station, @ 18:00
A35: A1 | B35: W9NWGQ5DD7L | C35: NZN2Z5XYY4M | D35: Liliana Chandra | E35: Brasali | F35: Female | G35: USA | H35: 61 | I35: FAIRMONT | L35: No | M35: Busan -> Incheon Airport train station, @ 18:00
A36: A1 | B36: PYN6VPQG6T9 | C36: PYN6VPQG6T9 | D36: Shoufie Rusli | E36: Nakamura | F36: Female | G36: USA | H36: 64 | I36: FAIRMONT | L36: No | M36: Busan -> Incheon Airport train station, @ 18:00
A37: A1 | B37: 6NN3YPYWJMF | C37: PYN6VPQG6T9 | D37: Kennedydouglas | E37: Jean | F37: Female | G37: USA | H37: 70 | I37: FAIRMONT | L37: No | M37: Busan -> Incheon Airport train station, @ 18:00
A38: A1 | B38: BCNVYRX63CS | C38: BCNVYRX63CS | D38: Anhvu Tran | E38: Nguyen | F38: Male | G38: USA | H38: 34 | I38: FAIRMONT | L38: Yes | M38: arrive on 19Sep, pick-up on 18Sep @ 17:50, ICN-T1
A39: A1 | B39: B3NJRY93FX2 | C39: BCNVYRX63CS | D39: Ya Chen | E39: Chen | F39: Female | G39: Taiwan | H39: 36 | I39: FAIRMONT | L39: Yes | M39: arrive on 19Sep, pick-up on 18Sep @ 17:50, ICN-T1
A40: A1 | B40: JQNQMVF25YP | C40: JQNQMVF25YP | D40: Brian Mercado | E40: Berdiago | F40: Male | G40: USA | H40: 34 | I40: FAIRMONT | L40: No
A41: A1 | B41: CXNRJSK5PKF | C41: JQNQMVF25YP | D41: Alexis | E41: Camacho Sibrian | F41: Male | G41: USA | H41: 23 | I41: FAIRMONT | L41: No
A42: A1 | B42: 95NN33GQCFZ | C42: 95NN33GQCFZ | D42: Daniel Gregory | E42: Chabino | F42: Male | G42: USA | H42: 54 | I42: FAIRMONT | L42: No
A43: A1 | B43: D5NXLDNW5BB | C43: 95NN33GQCFZ | D43: Nheza Mirasol | E43: Samia | F43: Female | I43: FAIRMONT | L43: No
A44: A1 | B44: X7NFCHMYRSC | C44: X7NFCHMYRSC | D44: Gerald Cabatbat | E44: Pugal | F44: Male | G44: USA | H44: 40 | I44: FAIRMONT | L44: No
A45: A1 | B45: XMNGSK9RJW2 | C45: X7NFCHMYRSC | D45: Jennifermae Castillo | E45: Regacho | F45: Female | G45: USA | H45: 42 | I45: FAIRMONT | L45: No
...

Sheet 14SEP.HERITAGE.A2
B1: 45914 | C1: K-HERITAGE | D1: A2
A2: NO. | B2: Sub-Group | C2: Confirmation | D2: Primary registrant | E2: First Name | F2: Last Name | G2: Gender | H2: Passport Country | I2: AGE | J2: HOTEL | K2: Full day | L2: Vegan | M2: TOURING DATE | N2: REMARKS
A3: 1 | B3: {=INDEX('PASSENGER LIST 27Aug_SUM'!$A$1:$L$3170,MATCH('14SEP.HERITAGE.A2'!$C3,'PASSENGER LIST 27Aug_SUM'!$B$1:$B$3170,0),MATCH('14SEP.HERITAGE.A2'!B$2,'PASSENGER LIST 27Aug_SUM'!$A$1:$L$1,0))} -> A2 | C3: RVNL4BVJVN6 | D3: {=INDEX('PASSENGER LIST 27Aug_SUM'!$A$1:$L$3170,MATCH('14SEP.HERITAGE.A2'!$C3,'PASSENGER LIST 27Aug_SUM'!$B$1:$B$3170,0),MATCH('14SEP.HERITAGE.A2'!D$2,'PASSENGER LIST 27Aug_SUM'!$A$1:$L$1,0))} -> RVNL4BVJVN6 | E3: {=INDEX('PASSENGER LIST 27Aug_SUM'!$A$1:$L$3170,MATCH('14SEP.HERITAGE.A2'!$C3,'PASSENGER LIST 27Aug_SUM'!$B$1:$B$3170,0),MATCH('14SEP.HERITAGE.A2'!E$2,'PASSENGER LIST 27Aug_SUM'!$A$1:$L$1,0))} -> Sonia Y | F3: {=INDEX('PASSENGER LIST 27Aug_SUM'!$A$1:$L$3170,MATCH('14SEP.HERITAGE.A2'!$C3,'PASSENGER LIST 27Aug_SUM'!$B$1:$B$3170,0),MATCH('14SEP.HERITAGE.A2'!F$2,'PASSENGER LIST 27Aug_SUM'!$A$1:$L$1,0))} -> Barocio | G3: {=INDEX('PASSENGER LIST 27Aug_SUM'!$A$1:$L$3170,MATCH('14SEP.HERITAGE.A2'!$C3,'PASSENGER LIST 27Aug_SUM'!$B$1:$B$3170,0),MATCH('14SEP.HERITAGE.A2'!G$2,'PASSENGER LIST 27Aug_SUM'!$A$1:$L$1,0))} -> Female | H3: {=INDEX('PASSENGER LIST 27Aug_SUM'!$A$1:$L$3170,MATCH('14SEP.HERITAGE.A2'!$C3,'PASSENGER LIST 27Aug_SUM'!$B$1:$B$3170,0),MATCH('14SEP.HERITAGE.A2'!H$2,'PASSENGER LIST 27Aug_SUM'!$A$1:$L$1,0))} -> USA | I3: {=INDEX('PASSENGER LIST 27Aug_SUM'!$A$1:$L$3170,MATCH('14SEP.HERITAGE.A2'!$C3,'PASSENGER LIST 27Aug_SUM'!$B$1:$B$3170,0),MATCH('14SEP.HERITAGE.A2'!I$2,'PASSENGER LIST 27Aug_SUM'!$A$1:$L$1,0))} -> 54 | J3: {=INDEX('PASSENGER LIST 27Aug_SUM'!$A$1:$L$3170,MATCH('14SEP.HERITAGE.A2'!$C3,'PASSENGER LIST 27Aug_SUM'!$B$1:$B$3170,0),MATCH('14SEP.HERITAGE.A2'!J$2,'PASSENGER LIST 27Aug_SUM'!$A$1:$L$1,0))} -> INTER PARNAS | K3: {=INDEX('PASSENGER LIST 27Aug_SUM'!$A$1:$L$3170,MATCH('14SEP.HERITAGE.A2'!$C3,'PASSENGER LIST 27Aug_SUM'!$B$1:$B$3170,0),MATCH('14SEP.HERITAGE.A2'!K$2,'PASSENGER LIST 27Aug_SUM'!$A$1:$L$1,0))} -> K-HERITAGE | L3: {=INDEX('PASSENGER LIST 27Aug_SUM'!$A$1:$L$3170,MATCH('14SEP.HERITAGE.A2'!$C3,'PASSENGER LIST 27Aug_SUM'!$B$1:$B$3170,0),MATCH('14SEP.HERITAGE.A2'!L$2,'PASSENGER LIST 27Aug_SUM'!$A$1:$L$1,0))} -> No | M3: 45914 | N3: {=INDEX('PASSENGER LIST 27Aug_SUM'!$A$1:$M$3170,MATCH('14SEP.HERITAGE.A2'!$C3,'PASSENGER LIST 27Aug_SUM'!$B$1:$B$3170,0),MATCH('14SEP.HERITAGE.A2'!N$2,'PASSENGER LIST 27Aug_SUM'!$A$1:$M$1,0))} -> 0
A4: 2 | B4: {=INDEX('PASSENGER LIST 27Aug_SUM'!$A$1:$L$3170,MATCH('14SEP.HERITAGE.A2'!$C4,'PASSENGER LIST 27Aug_SUM'!$B$1:$B$3170,0),MATCH('14SEP.HERITAGE.A2'!B$2,'PASSENGER LIST 27Aug_SUM'!$A$1:$L$1,0))} -> A2 | C4: VZNG24RK2Y5 | D4: {=INDEX('PASSENGER LIST 27Aug_SUM'!$A$1:$L$3170,MATCH('14SEP.HERITAGE.A2'!$C4,'PASSENGER LIST 27Aug_SUM'!$B$1:$B$3170,0),MATCH('14SEP.HERITAGE.A2'!D$2,'PASSENGER LIST 27Aug_SUM'!$A$1:$L$1,0))} -> RVNL4BVJVN6 | E4: {=INDEX('PASSENGER LIST 27Aug_SUM'!$A$1:$L$3170,MATCH('14SEP.HERITAGE.A2'!$C4,'PASSENGER LIST 27Aug_SUM'!$B$1:$B$3170,0),MATCH('14SEP.HERITAGE.A2'!E$2,'PASSENGER LIST 27Aug_SUM'!$A$1:$L$1,0))} -> Mauricio | F4: {=INDEX('PASSENGER LIST 27Aug_SUM'!$A$1:$L$3170,MATCH('14SEP.HERITAGE.A2'!$C4,'PASSENGER LIST 27Aug_SUM'!$B$1:$B$3170,0),MATCH('14SEP.HERITAGE.A2'!F$2,'PASSENGER LIST 27Aug_SUM'!$A$1:$L$1,0))} -> Quintero Ramirez | G4: {=INDEX('PASSENGER LIST 27Aug_SUM'!$A$1:$L$3170,MATCH('14SEP.HERITAGE.A2'!$C4,'PASSENGER LIST 27Aug_SUM'!$B$1:$B$3170,0),MATCH('14SEP.HERITAGE.A2'!G$2,'PASSENGER LIST 27Aug_SUM'!$A$1:$L$1,0))} -> Male | H4: {=INDEX('PASSENGER LIST 27Aug_SUM'!$A$1:$L$3170,MATCH('14SEP.HERITAGE.A2'!$C4,'PASSENGER LIST 27Aug_SUM'!$B$1:$B$3170,0),MATCH('14SEP.HERITAGE.A2'!H$2,'PASSENGER LIST 27Aug_SUM'!$A$1:$L$1,0))} -> Costa Rica | I4: {=INDEX('PASSENGER LIST 27Aug_SUM'!$A$1:$L$3170,MATCH('14SEP.HERITAGE.A2'!$C4,'PASSENGER LIST 27Aug_SUM'!$B$1:$B$3170,0),MATCH('14SEP.HERITAGE.A2'!I$2,'PASSENGER LIST 27Aug_SUM'!$A$1:$L$1,0))} -> 57 | J4: {=INDEX('PASSENGER LIST 27Aug_SUM'!$A$1:$L$3170,MATCH('14SEP.HERITAGE.A2'!$C4,'PASSENGER LIST 27Aug_SUM'!$B$1:$B$3170,0),MATCH('14SEP.HERITAGE.A2'!J$2,'PASSENGER LIST 27Aug_SUM'!$A$1:$L$1,0))} -> INTER PARNAS | K4: {=INDEX('PASSENGER LIST 27Aug_SUM'!$A$1:$L$3170,MATCH('14SEP.HERITAGE.A2'!$C4,'PASSENGER LIST 27Aug_SUM'!$B$1:$B$3170,0),MATCH('14SEP.HERITAGE.A2'!K$2,'PASSENGER LIST 27Aug_SUM'!$A$1:$L$1,0))} -> K-HERITAGE | L4: {=INDEX('PASSENGER LIST 27Aug_SUM'!$A$1:$L$3170,MATCH('14SEP.HERITAGE.A2'!$C4,'PASSENGER LIST 27Aug_SUM'!$B$1:$B$3170,0),MATCH('14SEP.HERITAGE.A2'!L$2,'PASSENGER LIST 27Aug_SUM'!$A$1:$L$1,0))} -> No | M4: 45914 | N4: {=INDEX('PASSENGER LIST 27Aug_SUM'!$A$1:$M$3170,MATCH('14SEP.HERITAGE.A2'!$C4,'PASSENGER LIST 27Aug_SUM'!$B$1:$B$3170,0),MATCH('14SEP.HERITAGE.A2'!N$2,'PASSENGER LIST 27Aug_SUM'!$A$1:$M$1,0))} -> 0
A5: 3 | B5: {=INDEX('PASSENGER LIST 27Aug_SUM'!$A$1:$L$3170,MATCH('14SEP.HERITAGE.A2'!$C5,'PASSENGER LIST 27Aug_SUM'!$B$1:$B$3170,0),MATCH('14SEP.HERITAGE.A2'!B$2,'PASSENGER LIST 27Aug_SUM'!$A$1:$L$1,0))} -> A2 | C5: V2NCDC2LQB4 | D5: {=INDEX('PASSENGER LIST 27Aug_SUM'!$A$1:$L$3170,MATCH('14SEP.HERITAGE.A2'!$C5,'PASSENGER LIST 27Aug_SUM'!$B$1:$B$3170,0),MATCH('14SEP.HERITAGE.A2'!D$2,'PASSENGER LIST 27Aug_SUM'!$A$1:$L$1,0))} -> V2NCDC2LQB4 | E5: {=INDEX('PASSENGER LIST 27Aug_SUM'!$A$1:$L$3170,MATCH('14SEP.HERITAGE.A2'!$C5,'PASSENGER LIST 27Aug_SUM'!$B$1:$B$3170,0),MATCH('14SEP.HERITAGE.A2'!E$2,'PASSENGER LIST 27Aug_SUM'!$A$1:$L$1,0))} -> Soo-Lian Eng | F5: {=INDEX('PASSENGER LIST 27Aug_SUM'!$A$1:$L$3170,MATCH('14SEP.HERITAGE.A2'!$C5,'PASSENGER LIST 27Aug_SUM'!$B$1:$B$3170,0),MATCH('14SEP.HERITAGE.A2'!F$2,'PASSENGER LIST 27Aug_SUM'!$A$1:$L$1,0))} -> Ervin | G5: {=INDEX('PASSENGER LIST 27Aug_SUM'!$A$1:$L$3170,MATCH('14SEP.HERITAGE.A2'!$C5,'PASSENGER LIST 27Aug_SUM'!$B$1:$B$3170,0),MATCH('14SEP.HERITAGE.A2'!G$2,'PASSENGER LIST 27Aug_SUM'!$A$1:$L$1,0))} -> Female | H5: {=INDEX('PASSENGER LIST 27Aug_SUM'!$A$1:$L$3170,MATCH('14SEP.HERITAGE.A2'!$C5,'PASSENGER LIST 27Aug_SUM'!$B$1:$B$3170,0),MATCH('14SEP.HERITAGE.A2'!H$2,'PASSENGER LIST 27Aug_SUM'!$A$1:$L$1,0))} -> USA | I5: {=INDEX('PASSENGER LIST 27Aug_SUM'!$A$1:$L$3170,MATCH('14SEP.HERITAGE.A2'!$C5,'PASSENGER LIST 27Aug_SUM'!$B$1:$B$3170,0),MATCH('14SEP.HERITAGE.A2'!I$2,'PASSENGER LIST 27Aug_SUM'!$A$1:$L$1,0))} -> 65 | J5: {=INDEX('PASSENGER LIST 27Aug_SUM'!$A$1:$L$3170,MATCH('14SEP.HERITAGE.A2'!$C5,'PASSENGER LIST 27Aug_SUM'!$B$1:$B$3170,0),MATCH('14SEP.HERITAGE.A2'!J$2,'PASSENGER LIST 27Aug_SUM'!$A$1:$L$1,0))} -> THE PLAZA | K5: {=INDEX('PASSENGER LIST 27Aug_SUM'!$A$1:$L$3170,MATCH('14SEP.HERITAGE.A2'!$C5,'PASSENGER LIST 27Aug_SUM'!$B$1:$B$3170,0),MATCH('14SEP.HERITAGE.A2'!K$2,'PASSENGER LIST 27Aug_SUM'!$A$1:$L$1,0))} -> K-HERITAGE | L5: {=INDEX('PASSENGER LIST 27Aug_SUM'!$A$1:$L$3170,MATCH('14SEP.HERITAGE.A2'!$C5,'PASSENGER LIST 27Aug_SUM'!$B$1:$B$3170,0),MATCH('14SEP.HERITAGE.A2'!L$2,'PASSENGER LIST 27Aug_SUM'!$A$1:$L$1,0))} -> No | M5: 45914 | N5: {=INDEX('PASSENGER LIST 27Aug_SUM'!$A$1:$M$3170,MATCH('14SEP.HERITAGE.A2'!$C5,'PASSENGER LIST 27Aug_SUM'!$B$1:$B$3170,0),MATCH('14SEP.HERITAGE.A2'!N$2,'PASSENGER LIST 27Aug_SUM'!$A$1:$M$1,0))} -> Pre: 1 night for 1 DBL on Sept 12
A6: 4 | B6: {=INDEX('PASSENGER LIST 27Aug_SUM'!$A$1:$L$3170,MATCH('14SEP.HERITAGE.A2'!$C6,'PASSENGER LIST 27Aug_SUM'!$B$1:$B$3170,0),MATCH('14SEP.HERITAGE.A2'!B$2,'PASSENGER LIST 27Aug_SUM'!$A$1:$L$1,0))} -> A2 | C6: J8N48YT5KF3 | D6: {=INDEX('PASSENGER LIST 27Aug_SUM'!$A$1:$L$3170,MATCH('14SEP.HERITAGE.A2'!$C6,'PASSENGER LIST 27Aug_SUM'!$B$1:$B$3170,0),MATCH('14SEP.HERITAGE.A2'!D$2,'PASSENGER LIST 27Aug_SUM'!$A$1:$L$1,0))} -> V2NCDC2LQB4 | E6: {=INDEX('PASSENGER LIST 27Aug_SUM'!$A$1:$L$3170,MATCH('14SEP.HERITAGE.A2'!$C6,'PASSENGER LIST 27Aug_SUM'!$B$1:$B$3170,0),MATCH('14SEP.HERITAGE.A2'!E$2,'PASSENGER LIST 27Aug_SUM'!$A$1:$L$1,0))} -> Leroy | F6: {=INDEX('PASSENGER LIST 27Aug_SUM'!$A$1:$L$3170,MATCH('14SEP.HERITAGE.A2'!$C6,'PASSENGER LIST 27Aug_SUM'!$B$1:$B$3170,0),MATCH('14SEP.HERITAGE.A2'!F$2,'PASSENGER LIST 27Aug_SUM'!$A$1:$L$1,0))} -> Ervin | G6: {=INDEX('PASSENGER LIST 27Aug_SUM'!$A$1:$L$3170,MATCH('14SEP.HERITAGE.A2'!$C6,'PASSENGER LIST 27Aug_SUM'!$B$1:$B$3170,0),MATCH('14SEP.HERITAGE.A2'!G$2,'PASSENGER LIST 27Aug_SUM'!$A$1:$L$1,0))} -> Male | H6: {=INDEX('PASSENGER LIST 27Aug_SUM'!$A$1:$L$3170,MATCH('14SEP.HERITAGE.A2'!$C6,'PASSENGER LIST 27Aug_SUM'!$B$1:$B$3170,0),MATCH('14SEP.HERITAGE.A2'!H$2,'PASSENGER LIST 27Aug_SUM'!$A$1:$L$1,0))} -> USA | I6: {=INDEX('PASSENGER LIST 27Aug_SUM'!$A$1:$L$3170,MATCH('14SEP.HERITAGE.A2'!$C6,'PASSENGER LIST 27Aug_SUM'!$B$1:$B$3170,0),MATCH('14SEP.HERITAGE.A2'!I$2,'PASSENGER LIST 27Aug_SUM'!$A$1:$L$1,0))} -> 74 | J6: {=INDEX('PASSENGER LIST 27Aug_SUM'!$A$1:$L$3170,MATCH('14SEP.HERITAGE.A2'!$C6,'PASSENGER LIST 27Aug_SUM'!$B$1:$B$3170,0),MATCH('14SEP.HERITAGE.A2'!J$2,'PASSENGER LIST 27Aug_SUM'!$A$1:$L$1,0))} -> THE PLAZA | K6: {=INDEX('PASSENGER LIST 27Aug_SUM'!$A$1:$L$3170,MATCH('14SEP.HERITAGE.A2'!$C6,'PASSENGER LIST 27Aug_SUM'!$B$1:$B$3170,0),MATCH('14SEP.HERITAGE.A2'!K$2,'PASSENGER LIST 27Aug_SUM'!$A$1:$L$1,0))} -> K-HERITAGE | L6: {=INDEX('PASSENGER LIST 27Aug_SUM'!$A$1:$L$3170,MATCH('14SEP.HERITAGE.A2'!$C6,'PASSENGER LIST 27Aug_SUM'!$B$1:$B$3170,0),MATCH('14SEP.HERITAGE.A2'!L$2,'PASSENGER LIST 27Aug_SUM'!$A$1:$L$1,0))} -> No | M6: 45914 | N6: {=INDEX('PASSENGER LIST 27Aug_SUM'!$A$1:$M$3170,MATCH('14SEP.HERITAGE.A2'!$C6,'PASSENGER LIST 27Aug_SUM'!$B$1:$B$3170,0),MATCH('14SEP.HERITAGE.A2'!N$2,'PASSENGER LIST 27Aug_SUM'!$A$1:$M$1,0))} -> Pre: 1 night for 1 DBL on Sept 12
A7: 5 | B7: {=INDEX('PASSENGER LIST 27Aug_SUM'!$A$1:$L$3170,MATCH('14SEP.HERITAGE.A2'!$C7,'PASSENGER LIST 27Aug_SUM'!$B$1:$B$3170,0),MATCH('14SEP.HERITAGE.A2'!B$2,'PASSENGER LIST 27Aug_SUM'!$A$1:$L$1,0))} -> A2 | C7: Z3NLQQK7RWT | D7: {=INDEX('PASSENGER LIST 27Aug_SUM'!$A$1:$L$3170,MATCH('14SEP.HERITAGE.A2'!$C7,'PASSENGER LIST 27Aug_SUM'!$B$1:$B$3170,0),MATCH('14SEP.HERITAGE.A2'!D$2,'PASSENGER LIST 27Aug_SUM'!$A$1:$L$1,0))} -> Z3NLQQK7RWT | E7: {=INDEX('PASSENGER LIST 27Aug_SUM'!$A$1:$L$3170,MATCH('14SEP.HERITAGE.A2'!$C7,'PASSENGER LIST 27Aug_SUM'!$B$1:$B$3170,0),MATCH('14SEP.HERITAGE.A2'!E$2,'PASSENGER LIST 27Aug_SUM'!$A$1:$L$1,0))} -> Dian Meity | F7: {=INDEX('PASSENGER LIST 27Aug_SUM'!$A$1:$L$3170,MATCH('14SEP.HERITAGE.A2'!$C7,'PASSENGER LIST 27Aug_SUM'!$B$1:$B$3170,0),MATCH('14SEP.HERITAGE.A2'!F$2,'PASSENGER LIST 27Aug_SUM'!$A$1:$L$1,0))} -> Liswani | G7: {=INDEX('PASSENGER LIST 27Aug_SUM'!$A$1:$L$3170,MATCH('14SEP.HERITAGE.A2'!$C7,'PASSENGER LIST 27Aug_SUM'!$B$1:$B$3170,0),MATCH('14SEP.HERITAGE.A2'!G$2,'PASSENGER LIST 27Aug_SUM'!$A$1:$L$1,0))} -> Female | H7: {=INDEX('PASSENGER LIST 27Aug_SUM'!$A$1:$L$3170,MATCH('14SEP.HERITAGE.A2'!$C7,'PASSENGER LIST 27Aug_SUM'!$B$1:$B$3170,0),MATCH('14SEP.HERITAGE.A2'!H$2,'PASSENGER LIST 27Aug_SUM'!$A$1:$L$1,0))} -> USA | I7: {=INDEX('PASSENGER LIST 27Aug_SUM'!$A$1:$L$3170,MATCH('14SEP.HERITAGE.A2'!$C7,'PASSENGER LIST 27Aug_SUM'!$B$1:$B$3170,0),MATCH('14SEP.HERITAGE.A2'!I$2,'PASSENGER LIST 27Aug_SUM'!$A$1:$L$1,0))} -> 53 | J7: {=INDEX('PASSENGER LIST 27Aug_SUM'!$A$1:$L$3170,MATCH('14SEP.HERITAGE.A2'!$C7,'PASSENGER LIST 27Aug_SUM'!$B$1:$B$3170,0),MATCH('14SEP.HERITAGE.A2'!J$2,'PASSENGER LIST 27Aug_SUM'!$A$1:$L$1,0))} -> THE PLAZA | K7: {=INDEX('PASSENGER LIST 27Aug_SUM'!$A$1:$L$3170,MATCH('14SEP.HERITAGE.A2'!$C7,'PASSENGER LIST 27Aug_SUM'!$B$1:$B$3170,0),MATCH('14SEP.HERITAGE.A2'!K$2,'PASSENGER LIST 27Aug_SUM'!$A$1:$L$1,0))} -> K-HERITAGE | L7: {=INDEX('PASSENGER LIST 27Aug_SUM'!$A$1:$L$3170,MATCH('14SEP.HERITAGE.A2'!$C7,'PASSENGER LIST 27Aug_SUM'!$B$1:$B$3170,0),MATCH('14SEP.HERITAGE.A2'!L$2,'PASSENGER LIST 27Aug_SUM'!$A$1:$L$1,0))} -> No | M7: 45914 | N7: {=INDEX('PASSENGER LIST 27Aug_SUM'!$A$1:$M$3170,MATCH('14SEP.HERITAGE.A2'!$C7,'PASSENGER LIST 27Aug_SUM'!$B$1:$B$3170,0),MATCH('14SEP.HERITAGE.A2'!N$2,'PASSENGER LIST 27Aug_SUM'!$A$1:$M$1,0))} -> 0
A8: 6 | B8: {=INDEX('PASSENGER LIST 27Aug_SUM'!$A$1:$L$3170,MATCH('14SEP.HERITAGE.A2'!$C8,'PASSENGER LIST 27Aug_SUM'!$B$1:$B$3170,0),MATCH('14SEP.HERITAGE.A2'!B$2,'PASSENGER LIST 27Aug_SUM'!$A$1:$L$1,0))} -> A2 | C8: XVNY5BD84W2 | D8: {=INDEX('PASSENGER LIST 27Aug_SUM'!$A$1:$L$3170,MATCH('14SEP.HERITAGE.A2'!$C8,'PASSENGER LIST 27Aug_SUM'!$B$1:$B$3170,0),MATCH('14SEP.HERITAGE.A2'!D$2,'PASSENGER LIST 27Aug_SUM'!$A$1:$L$1,0))} -> Z3NLQQK7RWT | E8: {=INDEX('PASSENGER LIST 27Aug_SUM'!$A$1:$L$3170,MATCH('14SEP.HERITAGE.A2'!$C8,'PASSENGER LIST 27Aug_SUM'!$B$1:$B$3170,0),MATCH('14SEP.HERITAGE.A2'!E$2,'PASSENGER LIST 27Aug_SUM'!$A$1:$L$1,0))} -> Everton Uriah | F8: {=INDEX('PASSENGER LIST 27Aug_SUM'!$A$1:$L$3170,MATCH('14SEP.HERITAGE.A2'!$C8,'PASSENGER LIST 27Aug_SUM'!$B$1:$B$3170,0),MATCH('14SEP.HERITAGE.A2'!F$2,'PASSENGER LIST 27Aug_SUM'!$A$1:$L$1,0))} -> Christie | G8: {=INDEX('PASSENGER LIST 27Aug_SUM'!$A$1:$L$3170,MATCH('14SEP.HERITAGE.A2'!$C8,'PASSENGER LIST 27Aug_SUM'!$B$1:$B$3170,0),MATCH('14SEP.HERITAGE.A2'!G$2,'PASSENGER LIST 27Aug_SUM'!$A$1:$L$1,0))} -> Male | H8: {=INDEX('PASSENGER LIST 27Aug_SUM'!$A$1:$L$3170,MATCH('14SEP.HERITAGE.A2'!$C8,'PASSENGER LIST 27Aug_SUM'!$B$1:$B$3170,0),MATCH('14SEP.HERITAGE.A2'!H$2,'PASSENGER LIST 27Aug_SUM'!$A$1:$L$1,0))} -> USA | I8: {=INDEX('PASSENGER LIST 27Aug_SUM'!$A$1:$L$3170,MATCH('14SEP.HERITAGE.A2'!$C8,'PASSENGER LIST 27Aug_SUM'!$B$1:$B$3170,0),MATCH('14SEP.HERITAGE.A2'!I$2,'PASSENGER LIST 27Aug_SUM'!$A$1:$L$1,0))} -> 57 | J8: {=INDEX('PASSENGER LIST 27Aug_SUM'!$A$1:$L$3170,MATCH('14SEP.HERITAGE.A2'!$C8,'PASSENGER LIST 27Aug_SUM'!$B$1:$B$3170,0),MATCH('14SEP.HERITAGE.A2'!J$2,'PASSENGER LIST 27Aug_SUM'!$A$1:$L$1,0))} -> THE PLAZA | K8: {=INDEX('PASSENGER LIST 27Aug_SUM'!$A$1:$L$3170,MATCH('14SEP.HERITAGE.A2'!$C8,'PASSENGER LIST 27Aug_SUM'!$B$1:$B$3170,0),MATCH('14SEP.HERITAGE.A2'!K$2,'PASSENGER LIST 27Aug_SUM'!$A$1:$L$1,0))} -> K-HERITAGE | L8: {=INDEX('PASSENGER LIST 27Aug_SUM'!$A$1:$L$3170,MATCH('14SEP.HERITAGE.A2'!$C8,'PASSENGER LIST 27Aug_SUM'!$B$1:$B$3170,0),MATCH('14SEP.HERITAGE.A2'!L$2,'PASSENGER LIST 27Aug_SUM'!$A$1:$L$1,0))} -> No | M8: 45914 | N8: {=INDEX('PASSENGER LIST 27Aug_SUM'!$A$1:$M$3170,MATCH('14SEP.HERITAGE.A2'!$C8,'PASSENGER LIST 27Aug_SUM'!$B$1:$B$3170,0),MATCH('14SEP.HERITAGE.A2'!N$2,'PASSENGER LIST 27Aug_SUM'!$A$1:$M$1,0))} -> 0
A9: 7 | B9: {=INDEX('PASSENGER LIST 27Aug_SUM'!$A$1:$L$3170,MATCH('14SEP.HERITAGE.A2'!$C9,'PASSENGER LIST 27Aug_SUM'!$B$1:$B$3170,0),MATCH('14SEP.HERITAGE.A2'!B$2,'PASSENGER LIST 27Aug_SUM'!$A$1:$L$1,0))} -> A2 | C9: GHN9MNWHL3Q | D9: {=INDEX('PASSENGER LIST 27Aug_SUM'!$A$1:$L$3170,MATCH('14SEP.HERITAGE.A2'!$C9,'PASSENGER LIST 27Aug_SUM'!$B$1:$B$3170,0),MATCH('14SEP.HERITAGE.A2'!D$2,'PASSENGER LIST 27Aug_SUM'!$A$1:$L$1,0))} -> GHN9MNWHL3Q | E9: {=INDEX('PASSENGER LIST 27Aug_SUM'!$A$1:$L$3170,MATCH('14SEP.HERITAGE.A2'!$C9,'PASSENGER LIST 27Aug_SUM'!$B$1:$B$3170,0),MATCH('14SEP.HERITAGE.A2'!E$2,'PASSENGER LIST 27Aug_SUM'!$A$1:$L$1,0))} -> Donna Eartha | F9: {=INDEX('PASSENGER LIST 27Aug_SUM'!$A$1:$L$3170,MATCH('14SEP.HERITAGE.A2'!$C9,'PASSENGER LIST 27Aug_SUM'!$B$1:$B$3170,0),MATCH('14SEP.HERITAGE.A2'!F$2,'PASSENGER LIST 27Aug_SUM'!$A$1:$L$1,0))} -> Watson | G9: {=INDEX('PASSENGER LIST 27Aug_SUM'!$A$1:$L$3170,MATCH('14SEP.HERITAGE.A2'!$C9,'PASSENGER LIST 27Aug_SUM'!$B$1:$B$3170,0),MATCH('14SEP.HERITAGE.A2'!G$2,'PASSENGER LIST 27Aug_SUM'!$A$1:$L$1,0))} -> Female | H9: {=INDEX('PASSENGER LIST 27Aug_SUM'!$A$1:$L$3170,MATCH('14SEP.HERITAGE.A2'!$C9,'PASSENGER LIST 27Aug_SUM'!$B$1:$B$3170,0),MATCH('14SEP.HERITAGE.A2'!H$2,'PASSENGER LIST 27Aug_SUM'!$A$1:$L$1,0))} -> USA | I9: {=INDEX('PASSENGER LIST 27Aug_SUM'!$A$1:$L$3170,MATCH('14SEP.HERITAGE.A2'!$C9,'PASSENGER LIST 27Aug_SUM'!$B$1:$B$3170,0),MATCH('14SEP.HERITAGE.A2'!I$2,'PASSENGER LIST 27Aug_SUM'!$A$1:$L$1,0))} -> 67 | J9: {=INDEX('PASSENGER LIST 27Aug_SUM'!$A$1:$L$3170,MATCH('14SEP.HERITAGE.A2'!$C9,'PASSENGER LIST 27Aug_SUM'!$B$1:$B$3170,0),MATCH('14SEP.HERITAGE.A2'!J$2,'PASSENGER LIST 27Aug_SUM'!$A$1:$L$1,0))} -> THE PLAZA | K9: {=INDEX('PASSENGER LIST 27Aug_SUM'!$A$1:$L$3170,MATCH('14SEP.HERITAGE.A2'!$C9,'PASSENGER LIST 27Aug_SUM'!$B$1:$B$3170,0),MATCH('14SEP.HERITAGE.A2'!K$2,'PASSENGER LIST 27Aug_SUM'!$A$1:$L$1,0))} -> K-HERITAGE | L9: {=INDEX('PASSENGER LIST 27Aug_SUM'!$A$1:$L$3170,MATCH('14SEP.HERITAGE.A2'!$C9,'PASSENGER LIST 27Aug_SUM'!$B$1:$B$3170,0),MATCH('14SEP.HERITAGE.A2'!L$2,'PASSENGER LIST 27Aug_SUM'!$A$1:$L$1,0))} -> No | M9: 45914 | N9: {=INDEX('PASSENGER LIST 27Aug_SUM'!$A$1:$M$3170,MATCH('14SEP.HERITAGE.A2'!$C9,'PASSENGER LIST 27Aug_SUM'!$B$1:$B$3170,0),MATCH('14SEP.HERITAGE.A2'!N$2,'PASSENGER LIST 27Aug_SUM'!$A$1:$M$1,0))} -> 0
A10: 8 | B10: {=INDEX('PASSENGER LIST 27Aug_SUM'!$A$1:$L$3170,MATCH('14SEP.HERITAGE.A2'!$C10,'PASSENGER LIST 27Aug_SUM'!$B$1:$B$3170,0),MATCH('14SEP.HERITAGE.A2'!B$2,'PASSENGER LIST 27Aug_SUM'!$A$1:$L$1,0))} -> A2 | C10: ZZNXXKFP8KF | D10: {=INDEX('PASSENGER LIST 27Aug_SUM'!$A$1:$L$3170,MATCH('14SEP.HERITAGE.A2'!$C10,'PASSENGER LIST 27Aug_SUM'!$B$1:$B$3170,0),MATCH('14SEP.HERITAGE.A2'!D$2,'PASSENGER LIST 27Aug_SUM'!$A$1:$L$1,0))} -> GHN9MNWHL3Q | E10: {=INDEX('PASSENGER LIST 27Aug_SUM'!$A$1:$L$3170,MATCH('14SEP.HERITAGE.A2'!$C10,'PASSENGER LIST 27Aug_SUM'!$B$1:$B$3170,0),MATCH('14SEP.HERITAGE.A2'!E$2,'PASSENGER LIST 27Aug_SUM'!$A$1:$L$1,0))} -> Basil Barrington | F10: {=INDEX('PASSENGER LIST 27Aug_SUM'!$A$1:$L$3170,MATCH('14SEP.HERITAGE.A2'!$C10,'PASSENGER LIST 27Aug_SUM'!$B$1:$B$3170,0),MATCH('14SEP.HERITAGE.A2'!F$2,'PASSENGER LIST 27Aug_SUM'!$A$1:$L$1,0))} -> Watson | G10: {=INDEX('PASSENGER LIST 27Aug_SUM'!$A$1:$L$3170,MATCH('14SEP.HERITAGE.A2'!$C10,'PASSENGER LIST 27Aug_SUM'!$B$1:$B$3170,0),MATCH('14SEP.HERITAGE.A2'!G$2,'PASSENGER LIST 27Aug_SUM'!$A$1:$L$1,0))} -> Male | H10: {=INDEX('PASSENGER LIST 27Aug_SUM'!$A$1:$L$3170,MATCH('14SEP.HERITAGE.A2'!$C10,'PASSENGER LIST 27Aug_SUM'!$B$1:$B$3170,0),MATCH('14SEP.HERITAGE.A2'!H$2,'PASSENGER LIST 27Aug_SUM'!$A$1:$L$1,0))} -> USA | I10: {=INDEX('PASSENGER LIST 27Aug_SUM'!$A$1:$L$3170,MATCH('14SEP.HERITAGE.A2'!$C10,'PASSENGER LIST 27Aug_SUM'!$B$1:$B$3170,0),MATCH('14SEP.HERITAGE.A2'!I$2,'PASSENGER LIST 27Aug_SUM'!$A$1:$L$1,0))} -> 67 | J10: {=INDEX('PASSENGER LIST 27Aug_SUM'!$A$1:$L$3170,MATCH('14SEP.HERITAGE.A2'!$C10,'PASSENGER LIST 27Aug_SUM'!$B$1:$B$3170,0),MATCH('14SEP.HERITAGE.A2'!J$2,'PASSENGER LIST 27Aug_SUM'!$A$1:$L$1,0))} -> THE PLAZA | K10: {=INDEX('PASSENGER LIST 27Aug_SUM'!$A$1:$L$3170,MATCH('14SEP.HERITAGE.A2'!$C10,'PASSENGER LIST 27Aug_SUM'!$B$1:$B$3170,0),MATCH('14SEP.HERITAGE.A2'!K$2,'PASSENGER LIST 27Aug_SUM'!$A$1:$L$1,0))} -> K-HERITAGE | L10: {=INDEX('PASSENGER LIST 27Aug_SUM'!$A$1:$L$3170,MATCH('14SEP.HERITAGE.A2'!$C10,'PASSENGER LIST 27Aug_SUM'!$B$1:$B$3170,0),MATCH('14SEP.HERITAGE.A2'!L$2,'PASSENGER LIST 27Aug_SUM'!$A$1:$L$1,0))} -> No | M10: 45914 | N10: {=INDEX('PASSENGER LIST 27Aug_SUM'!$A$1:$M$3170,MATCH('14SEP.HERITAGE.A2'!$C10,'PASSENGER LIST 27Aug_SUM'!$B$1:$B$3170,0),MATCH('14SEP.HERITAGE.A2'!N$2,'PASSENGER LIST 27Aug_SUM'!$A$1:$M$1,0))} -> 0
A11: 9 | B11: {=INDEX('PASSENGER LIST 27Aug_SUM'!$A$1:$L$3170,MATCH('14SEP.HERITAGE.A2'!$C11,'PASSENGER LIST 27Aug_SUM'!$B$1:$B$3170,0),MATCH('14SEP.HERITAGE.A2'!B$2,'PASSENGER LIST 27Aug_SUM'!$A$1:$L$1,0))} -> A2 | C11: H3NS3M547V3 | D11: {=INDEX('PASSENGER LIST 27Aug_SUM'!$A$1:$L$3170,MATCH('14SEP.HERITAGE.A2'!$C11,'PASSENGER LIST 27Aug_SUM'!$B$1:$B$3170,0),MATCH('14SEP.HERITAGE.A2'!D$2,'PASSENGER LIST 27Aug_SUM'!$A$1:$L$1,0))} -> H3NS3M547V3 | E11: {=INDEX('PASSENGER LIST 27Aug_SUM'!$A$1:$L$3170,MATCH('14SEP.HERITAGE.A2'!$C11,'PASSENGER LIST 27Aug_SUM'!$B$1:$B$3170,0),MATCH('14SEP.HERITAGE.A2'!E$2,'PASSENGER LIST 27Aug_SUM'!$A$1:$L$1,0))} -> Everton | F11: {=INDEX('PASSENGER LIST 27Aug_SUM'!$A$1:$L$3170,MATCH('14SEP.HERITAGE.A2'!$C11,'PASSENGER LIST 27Aug_SUM'!$B$1:$B$3170,0),MATCH('14SEP.HERITAGE.A2'!F$2,'PASSENGER LIST 27Aug_SUM'!$A$1:$L$1,0))} -> Barrett | G11: {=INDEX('PASSENGER LIST 27Aug_SUM'!$A$1:$L$3170,MATCH('14SEP.HERITAGE.A2'!$C11,'PASSENGER LIST 27Aug_SUM'!$B$1:$B$3170,0),MATCH('14SEP.HERITAGE.A2'!G$2,'PASSENGER LIST 27Aug_SUM'!$A$1:$L$1,0))} -> Male | H11: {=INDEX('PASSENGER LIST 27Aug_SUM'!$A$1:$L$3170,MATCH('14SEP.HERITAGE.A2'!$C11,'PASSENGER LIST 27Aug_SUM'!$B$1:$B$3170,0),MATCH('14SEP.HERITAGE.A2'!H$2,'PASSENGER LIST 27Aug_SUM'!$A$1:$L$1,0))} -> USA | I11: {=INDEX('PASSENGER LIST 27Aug_SUM'!$A$1:$L$3170,MATCH('14SEP.HERITAGE.A2'!$C11,'PASSENGER LIST 27Aug_SUM'!$B$1:$B$3170,0),MATCH('14SEP.HERITAGE.A2'!I$2,'PASSENGER LIST 27Aug_SUM'!$A$1:$L$1,0))} -> 60 | J11: {=INDEX('PASSENGER LIST 27Aug_SUM'!$A$1:$L$3170,MATCH('14SEP.HERITAGE.A2'!$C11,'PASSENGER LIST 27Aug_SUM'!$B$1:$B$3170,0),MATCH('14SEP.HERITAGE.A2'!J$2,'PASSENGER LIST 27Aug_SUM'!$A$1:$L$1,0))} -> THE PLAZA | K11: {=INDEX('PASSENGER LIST 27Aug_SUM'!$A$1:$L$3170,MATCH('14SEP.HERITAGE.A2'!$C11,'PASSENGER LIST 27Aug_SUM'!$B$1:$B$3170,0),MATCH('14SEP.HERITAGE.A2'!K$2,'PASSENGER LIST 27Aug_SUM'!$A$1:$L$1,0))} -> K-HERITAGE | L11: {=INDEX('PASSENGER LIST 27Aug_SUM'!$A$1:$L$3170,MATCH('14SEP.HERITAGE.A2'!$C11,'PASSENGER LIST 27Aug_SUM'!$B$1:$B$3170,0),MATCH('14SEP.HERITAGE.A2'!L$2,'PASSENGER LIST 27Aug_SUM'!$A$1:$L$1,0))} -> No | M11: 45914 | N11: {=INDEX('PASSENGER LIST 27Aug_SUM'!$A$1:$M$3170,MATCH('14SEP.HERITAGE.A2'!$C11,'PASSENGER LIST 27Aug_SUM'!$B$1:$B$3170,0),MATCH('14SEP.HERITAGE.A2'!N$2,'PASSENGER LIST 27Aug_SUM'!$A$1:$M$1,0))} -> 0
A12: 10 | B12: {=INDEX('PASSENGER LIST 27Aug_SUM'!$A$1:$L$3170,MATCH('14SEP.HERITAGE.A2'!$C12,'PASSENGER LIST 27Aug_SUM'!$B$1:$B$3170,0),MATCH('14SEP.HERITAGE.A2'!B$2,'PASSENGER LIST 27Aug_SUM'!$A$1:$L$1,0))} -> A2 | C12: H3N5QYZWRFN | D12: {=INDEX('PASSENGER LIST 27Aug_SUM'!$A$1:$L$3170,MATCH('14SEP.HERITAGE.A2'!$C12,'PASSENGER LIST 27Aug_SUM'!$B$1:$B$3170,0),MATCH('14SEP.HERITAGE.A2'!D$2,'PASSENGER LIST 27Aug_SUM'!$A$1:$L$1,0))} -> H3NS3M547V3 | E12: {=INDEX('PASSENGER LIST 27Aug_SUM'!$A$1:$L$3170,MATCH('14SEP.HERITAGE.A2'!$C12,'PASSENGER LIST 27Aug_SUM'!$B$1:$B$3170,0),MATCH('14SEP.HERITAGE.A2'!E$2,'PASSENGER LIST 27Aug_SUM'!$A$1:$L$1,0))} -> Alicia | F12: {=INDEX('PASSENGER LIST 27Aug_SUM'!$A$1:$L$3170,MATCH('14SEP.HERITAGE.A2'!$C12,'PASSENGER LIST 27Aug_SUM'!$B$1:$B$3170,0),MATCH('14SEP.HERITAGE.A2'!F$2,'PASSENGER LIST 27Aug_SUM'!$A$1:$L$1,0))} -> Barrett | G12: {=INDEX('PASSENGER LIST 27Aug_SUM'!$A$1:$L$3170,MATCH('14SEP.HERITAGE.A2'!$C12,'PASSENGER LIST 27Aug_SUM'!$B$1:$B$3170,0),MATCH('14SEP.HERITAGE.A2'!G$2,'PASSENGER LIST 27Aug_SUM'!$A$1:$L$1,0))} -> Female | H12: {=INDEX('PASSENGER LIST 27Aug_SUM'!$A$1:$L$3170,MATCH('14SEP.HERITAGE.A2'!$C12,'PASSENGER LIST 27Aug_SUM'!$B$1:$B$3170,0),MATCH('14SEP.HERITAGE.A2'!H$2,'PASSENGER LIST 27Aug_SUM'!$A$1:$L$1,0))} -> USA | I12: {=INDEX('PASSENGER LIST 27Aug_SUM'!$A$1:$L$3170,MATCH('14SEP.HERITAGE.A2'!$C12,'PASSENGER LIST 27Aug_SUM'!$B$1:$B$3170,0),MATCH('14SEP.HERITAGE.A2'!I$2,'PASSENGER LIST 27Aug_SUM'!$A$1:$L$1,0))} -> 35 | J12: {=INDEX('PASSENGER LIST 27Aug_SUM'!$A$1:$L$3170,MATCH('14SEP.HERITAGE.A2'!$C12,'PASSENGER LIST 27Aug_SUM'!$B$1:$B$3170,0),MATCH('14SEP.HERITAGE.A2'!J$2,'PASSENGER LIST 27Aug_SUM'!$A$1:$L$1,0))} -> THE PLAZA | K12: {=INDEX('PASSENGER LIST 27Aug_SUM'!$A$1:$L$3170,MATCH('14SEP.HERITAGE.A2'!$C12,'PASSENGER LIST 27Aug_SUM'!$B$1:$B$3170,0),MATCH('14SEP.HERITAGE.A2'!K$2,'PASSENGER LIST 27Aug_SUM'!$A$1:$L$1,0))} -> K-HERITAGE | L12: {=INDEX('PASSENGER LIST 27Aug_SUM'!$A$1:$L$3170,MATCH('14SEP.HERITAGE.A2'!$C12,'PASSENGER LIST 27Aug_SUM'!$B$1:$B$3170,0),MATCH('14SEP.HERITAGE.A2'!L$2,'PASSENGER LIST 27Aug_SUM'!$A$1:$L$1,0))} -> No | M12: 45914 | N12: {=INDEX('PASSENGER LIST 27Aug_SUM'!$A$1:$M$3170,MATCH('14SEP.HERITAGE.A2'!$C12,'PASSENGER LIST 27Aug_SUM'!$B$1:$B$3170,0),MATCH('14SEP.HERITAGE.A2'!N$2,'PASSENGER LIST 27Aug_SUM'!$A$1:$M$1,0))} -> 0
A13: 11 | B13: {=INDEX('PASSENGER LIST 27Aug_SUM'!$A$1:$L$3170,MATCH('14SEP.HERITAGE.A2'!$C13,'PASSENGER LIST 27Aug_SUM'!$B$1:$B$3170,0),MATCH('14SEP.HERITAGE.A2'!B$2,'PASSENGER LIST 27Aug_SUM'!$A$1:$L$1,0))} -> A2 | C13: RWNBCP2RHMT | D13: {=INDEX('PASSENGER LIST 27Aug_SUM'!$A$1:$L$3170,MATCH('14SEP.HERITAGE.A2'!$C13,'PASSENGER LIST 27Aug_SUM'!$B$1:$B$3170,0),MATCH('14SEP.HERITAGE.A2'!D$2,'PASSENGER LIST 27Aug_SUM'!$A$1:$L$1,0))} -> RWNBCP2RHMT | E13: {=INDEX('PASSENGER LIST 27Aug_SUM'!$A$1:$L$3170,MATCH('14SEP.HERITAGE.A2'!$C13,'PASSENGER LIST 27Aug_SUM'!$B$1:$B$3170,0),MATCH('14SEP.HERITAGE.A2'!E$2,'PASSENGER LIST 27Aug_SUM'!$A$1:$L$1,0))} -> Marie Angela | F13: {=INDEX('PASSENGER LIST 27Aug_SUM'!$A$1:$L$3170,MATCH('14SEP.HERITAGE.A2'!$C13,'PASSENGER LIST 27Aug_SUM'!$B$1:$B$3170,0),MATCH('14SEP.HERITAGE.A2'!F$2,'PASSENGER LIST 27Aug_SUM'!$A$1:$L$1,0))} -> Peart | G13: {=INDEX('PASSENGER LIST 27Aug_SUM'!$A$1:$L$3170,MATCH('14SEP.HERITAGE.A2'!$C13,'PASSENGER LIST 27Aug_SUM'!$B$1:$B$3170,0),MATCH('14SEP.HERITAGE.A2'!G$2,'PASSENGER LIST 27Aug_SUM'!$A$1:$L$1,0))} -> Female | H13: {=INDEX('PASSENGER LIST 27Aug_SUM'!$A$1:$L$3170,MATCH('14SEP.HERITAGE.A2'!$C13,'PASSENGER LIST 27Aug_SUM'!$B$1:$B$3170,0),MATCH('14SEP.HERITAGE.A2'!H$2,'PASSENGER LIST 27Aug_SUM'!$A$1:$L$1,0))} -> USA | I13: {=INDEX('PASSENGER LIST 27Aug_SUM'!$A$1:$L$3170,MATCH('14SEP.HERITAGE.A2'!$C13,'PASSENGER LIST 27Aug_SUM'!$B$1:$B$3170,0),MATCH('14SEP.HERITAGE.A2'!I$2,'PASSENGER LIST 27Aug_SUM'!$A$1:$L$1,0))} -> 64 | J13: {=INDEX('PASSENGER LIST 27Aug_SUM'!$A$1:$L$3170,MATCH('14SEP.HERITAGE.A2'!$C13,'PASSENGER LIST 27Aug_SUM'!$B$1:$B$3170,0),MATCH('14SEP.HERITAGE.A2'!J$2,'PASSENGER LIST 27Aug_SUM'!$A$1:$L$1,0))} -> THE PLAZA | K13: {=INDEX('PASSENGER LIST 27Aug_SUM'!$A$1:$L$3170,MATCH('14SEP.HERITAGE.A2'!$C13,'PASSENGER LIST 27Aug_SUM'!$B$1:$B$3170,0),MATCH('14SEP.HERITAGE.A2'!K$2,'PASSENGER LIST 27Aug_SUM'!$A$1:$L$1,0))} -> K-HERITAGE | L13: {=INDEX('PASSENGER LIST 27Aug_SUM'!$A$1:$L$3170,MATCH('14SEP.HERITAGE.A2'!$C13,'PASSENGER LIST 27Aug_SUM'!$B$1:$B$3170,0),MATCH('14SEP.HERITAGE.A2'!L$2,'PASSENGER LIST 27Aug_SUM'!$A$1:$L$1,0))} -> No | M13: 45914 | N13: {=INDEX('PASSENGER LIST 27Aug_SUM'!$A$1:$M$3170,MATCH('14SEP.HERITAGE.A2'!$C13,'PASSENGER LIST 27Aug_SUM'!$B$1:$B$3170,0),MATCH('14SEP.HERITAGE.A2'!N$2,'PASSENGER LIST 27Aug_SUM'!$A$1:$M$1,0))} -> 0
A14: 12 | B14: {=INDEX('PASSENGER LIST 27Aug_SUM'!$A$1:$L$3170,MATCH('14SEP.HERITAGE.A2'!$C14,'PASSENGER LIST 27Aug_SUM'!$B$1:$B$3170,0),MATCH('14SEP.HERITAGE.A2'!B$2,'PASSENGER LIST 27Aug_SUM'!$A$1:$L$1,0))} -> A2 | C14: 7PN8LK9HMGZ | D14: {=INDEX('PASSENGER LIST 27Aug_SUM'!$A$1:$L$3170,MATCH('14SEP.HERITAGE.A2'!$C14,'PASSENGER LIST 27Aug_SUM'!$B$1:$B$3170,0),MATCH('14SEP.HERITAGE.A2'!D$2,'PASSENGER LIST 27Aug_SUM'!$A$1:$L$1,0))} -> RWNBCP2RHMT | E14: {=INDEX('PASSENGER LIST 27Aug_SUM'!$A$1:$L$3170,MATCH('14SEP.HERITAGE.A2'!$C14,'PASSENGER LIST 27Aug_SUM'!$B$1:$B$3170,0),MATCH('14SEP.HERITAGE.A2'!E$2,'PASSENGER LIST 27Aug_SUM'!$A$1:$L$1,0))} -> Alethea Renee | F14: {=INDEX('PASSENGER LIST 27Aug_SUM'!$A$1:$L$3170,MATCH('14SEP.HERITAGE.A2'!$C14,'PASSENGER LIST 27Aug_SUM'!$B$1:$B$3170,0),MATCH('14SEP.HERITAGE.A2'!F$2,'PASSENGER LIST 27Aug_SUM'!$A$1:$L$1,0))} -> Bonello | G14: {=INDEX('PASSENGER LIST 27Aug_SUM'!$A$1:$L$3170,MATCH('14SEP.HERITAGE.A2'!$C14,'PASSENGER LIST 27Aug_SUM'!$B$1:$B$3170,0),MATCH('14SEP.HERITAGE.A2'!G$2,'PASSENGER LIST 27Aug_SUM'!$A$1:$L$1,0))} -> Female | H14: {=INDEX('PASSENGER LIST 27Aug_SUM'!$A$1:$L$3170,MATCH('14SEP.HERITAGE.A2'!$C14,'PASSENGER LIST 27Aug_SUM'!$B$1:$B$3170,0),MATCH('14SEP.HERITAGE.A2'!H$2,'PASSENGER LIST 27Aug_SUM'!$A$1:$L$1,0))} -> USA | I14: {=INDEX('PASSENGER LIST 27Aug_SUM'!$A$1:$L$3170,MATCH('14SEP.HERITAGE.A2'!$C14,'PASSENGER LIST 27Aug_SUM'!$B$1:$B$3170,0),MATCH('14SEP.HERITAGE.A2'!I$2,'PASSENGER LIST 27Aug_SUM'!$A$1:$L$1,0))} -> 49 | J14: {=INDEX('PASSENGER LIST 27Aug_SUM'!$A$1:$L$3170,MATCH('14SEP.HERITAGE.A2'!$C14,'PASSENGER LIST 27Aug_SUM'!$B$1:$B$3170,0),MATCH('14SEP.HERITAGE.A2'!J$2,'PASSENGER LIST 27Aug_SUM'!$A$1:$L$1,0))} -> THE PLAZA | K14: {=INDEX('PASSENGER LIST 27Aug_SUM'!$A$1:$L$3170,MATCH('14SEP.HERITAGE.A2'!$C14,'PASSENGER LIST 27Aug_SUM'!$B$1:$B$3170,0),MATCH('14SEP.HERITAGE.A2'!K$2,'PASSENGER LIST 27Aug_SUM'!$A$1:$L$1,0))} -> K-HERITAGE | L14: {=INDEX('PASSENGER LIST 27Aug_SUM'!$A$1:$L$3170,MATCH('14SEP.HERITAGE.A2'!$C14,'PASSENGER LIST 27Aug_SUM'!$B$1:$B$3170,0),MATCH('14SEP.HERITAGE.A2'!L$2,'PASSENGER LIST 27Aug_SUM'!$A$1:$L$1,0))} -> No | M14: 45914 | N14: {=INDEX('PASSENGER LIST 27Aug_SUM'!$A$1:$M$3170,MATCH('14SEP.HERITAGE.A2'!$C14,'PASSENGER LIST 27Aug_SUM'!$B$1:$B$3170,0),MATCH('14SEP.HERITAGE.A2'!N$2,'PASSENGER LIST 27Aug_SUM'!$A$1:$M$1,0))} -> 0
... A37: 35 | B37: {=INDEX('PASSENGER LIST 27Aug_SUM'!$A$1:$L$3170,MATCH('14SEP.HERITAGE.A2'!$C37,'PASSENGER LIST 27Aug_SUM'!$B$1:$B$3170,0),MATCH('14SEP.HERITAGE.A2'!B$2,'PASSENGER LIST 27Aug_SUM'!$A$1:$L$1,0))} -> A2 | C37: YLNZBWJY37W | D37: {=INDEX('PASSENGER LIST 27Aug_SUM'!$A$1:$L$3170,MATCH('14SEP.HERITAGE.A2'!$C37,'PASSENGER LIST 27Aug_SUM'!$B$1:$B$3170,0),MATCH('14SEP.HERITAGE.A2'!D$2,'PASSENGER LIST 27Aug_SUM'!$A$1:$L$1,0))} -> M3NS38Y2WSP | E37: {=INDEX('PASSENGER LIST 27Aug_SUM'!$A$1:$L$3170,MATCH('14SEP.HERITAGE.A2'!$C37,'PASSENGER LIST 27Aug_SUM'!$B$1:$B$3170,0),MATCH('14SEP.HERITAGE.A2'!E$2,'PASSENGER LIST 27Aug_SUM'!$A$1:$L$1,0))} -> Youngran | F37: {=INDEX('PASSENGER LIST 27Aug_SUM'!$A$1:$L$3170,MATCH('14SEP.HERITAGE.A2'!$C37,'PASSENGER LIST 27Aug_SUM'!$B$1:$B$3170,0),MATCH('14SEP.HERITAGE.A2'!F$2,'PASSENGER LIST 27Aug_SUM'!$A$1:$L$1,0))} -> Baek | G37: {=INDEX('PASSENGER LIST 27Aug_SUM'!$A$1:$L$3170,MATCH('14SEP.HERITAGE.A2'!$C37,'PASSENGER LIST 27Aug_SUM'!$B$1:$B$3170,0),MATCH('14SEP.HERITAGE.A2'!G$2,'PASSENGER LIST 27Aug_SUM'!$A$1:$L$1,0))} -> Female | H37: {=INDEX('PASSENGER LIST 27Aug_SUM'!$A$1:$L$3170,MATCH('14SEP.HERITAGE.A2'!$C37,'PASSENGER LIST 27Aug_SUM'!$B$1:$B$3170,0),MATCH('14SEP.HERITAGE.A2'!H$2,'PASSENGER LIST 27Aug_SUM'!$A$1:$L$1,0))} -> Republic of Korea | I37: {=INDEX('PASSENGER LIST 27Aug_SUM'!$A$1:$L$3170,MATCH('14SEP.HERITAGE.A2'!$C37,'PASSENGER LIST 27Aug_SUM'!$B$1:$B$3170,0),MATCH('14SEP.HERITAGE.A2'!I$2,'PASSENGER LIST 27Aug_SUM'!$A$1:$L$1,0))} -> 60 | J37: {=INDEX('PASSENGER LIST 27Aug_SUM'!$A$1:$L$3170,MATCH('14SEP.HERITAGE.A2'!$C37,'PASSENGER LIST 27Aug_SUM'!$B$1:$B$3170,0),MATCH('14SEP.HERITAGE.A2'!J$2,'PASSENGER LIST 27Aug_SUM'!$A$1:$L$1,0))} -> LOTTE | K37: {=INDEX('PASSENGER LIST 27Aug_SUM'!$A$1:$L$3170,MATCH('14SEP.HERITAGE.A2'!$C37,'PASSENGER LIST 27Aug_SUM'!$B$1:$B$3170,0),MATCH('14SEP.HERITAGE.A2'!K$2,'PASSENGER LIST 27Aug_SUM'!$A$1:$L$1,0))} -> K-HERITAGE | L37: {=INDEX('PASSENGER LIST 27Aug_SUM'!$A$1:$L$3170,MATCH('14SEP.HERITAGE.A2'!$C37,'PASSENGER LIST 27Aug_SUM'!$B$1:$B$3170,0),MATCH('14SEP.HERITAGE.A2'!L$2,'PASSENGER LIST 27Aug_SUM'!$A$1:$L$1,0))} -> No | M37: 45914 | N37: {=INDEX('PASSENGER LIST 27Aug_SUM'!$A$1:$M$3170,MATCH('14SEP.HERITAGE.A2'!$C37,'PASSENGER LIST 27Aug_SUM'!$B$1:$B$3170,0),MATCH('14SEP.HERITAGE.A2'!N$2,'PASSENGER LIST 27Aug_SUM'!$A$1:$M$1,0))} -> Airport transfer: All 6 pax NO NEED, living in Seoul

Sheet 14SEP.NATURE.A2
A1: d | B1: 45914 | C1: K-NATURE | D1: A2
A2: No. | B2: Sub-Group | C2: Confirmation | D2: Primary registrant | E2: First Name | F2: Last Name | G2: Gender | H2: Passport Country | I2: AGE | J2: HOTEL | K2: Full day | L2: Vegan | M2: TOURING DATE | N2: REMARKS
A3: 1 | B3: {=INDEX('PASSENGER LIST 27Aug_SUM'!$A$1:$L$3170,MATCH($C3,'PASSENGER LIST 27Aug_SUM'!$B$1:$B$3170,0),MATCH('14SEP.NATURE.A2'!B$2,'PASSENGER LIST 27Aug_SUM'!$A$1:$L$1,0))} -> A2 | C3: 32N3X3VKNF2 | D3: {=INDEX('PASSENGER LIST 27Aug_SUM'!$A$1:$K$3170,MATCH($C3,'PASSENGER LIST 27Aug_SUM'!$B$1:$B$3170,0),MATCH('14SEP.NATURE.A2'!D$2,'PASSENGER LIST 27Aug_SUM'!$A$1:$K$1,0))} -> 32N3X3VKNF2 | E3: {=INDEX('PASSENGER LIST 27Aug_SUM'!$A$1:$K$3170,MATCH($C3,'PASSENGER LIST 27Aug_SUM'!$B$1:$B$3170,0),MATCH('14SEP.NATURE.A2'!E$2,'PASSENGER LIST 27Aug_SUM'!$A$1:$K$1,0))} -> Chamna | F3: {=INDEX('PASSENGER LIST 27Aug_SUM'!$A$1:$K$3170,MATCH($C3,'PASSENGER LIST 27Aug_SUM'!$B$1:$B$3170,0),MATCH('14SEP.NATURE.A2'!F$2,'PASSENGER LIST 27Aug_SUM'!$A$1:$K$1,0))} -> Vong | G3: {=INDEX('PASSENGER LIST 27Aug_SUM'!$A$1:$L$3170,MATCH($C3,'PASSENGER LIST 27Aug_SUM'!$B$1:$B$3170,0),MATCH('14SEP.NATURE.A2'!G$2,'PASSENGER LIST 27Aug_SUM'!$A$1:$L$1,0))} -> Male | H3: {=INDEX('PASSENGER LIST 27Aug_SUM'!$A$1:$L$3170,MATCH($C3,'PASSENGER LIST 27Aug_SUM'!$B$1:$B$3170,0),MATCH('14SEP.NATURE.A2'!H$2,'PASSENGER LIST 27Aug_SUM'!$A$1:$L$1,0))} -> USA | I3: {=INDEX('PASSENGER LIST 27Aug_SUM'!$A$1:$L$3170,MATCH($C3,'PASSENGER LIST 27Aug_SUM'!$B$1:$B$3170,0),MATCH('14SEP.NATURE.A2'!I$2,'PASSENGER LIST 27Aug_SUM'!$A$1:$L$1,0))} -> 38 | J3: {=INDEX('PASSENGER LIST 27Aug_SUM'!$A$1:$L$3170,MATCH($C3,'PASSENGER LIST 27Aug_SUM'!$B$1:$B$3170,0),MATCH('14SEP.NATURE.A2'!J$2,'PASSENGER LIST 27Aug_SUM'!$A$1:$L$1,0))} -> INTER PARNAS | K3: {=INDEX('PASSENGER LIST 27Aug_SUM'!$A$1:$L$3170,MATCH($C3,'PASSENGER LIST 27Aug_SUM'!$B$1:$B$3170,0),MATCH('14SEP.NATURE.A2'!K$2,'PASSENGER LIST 27Aug_SUM'!$A$1:$L$1,0))} -> K-NATURE | L3: {=INDEX('PASSENGER LIST 27Aug_SUM'!$A$1:$L$3170,MATCH($C3,'PASSENGER LIST 27Aug_SUM'!$B$1:$B$3170,0),MATCH('14SEP.NATURE.A2'!L$2,'PASSENGER LIST 27Aug_SUM'!$A$1:$L$1,0))} -> No | M3: 45914 | N3: {=INDEX('PASSENGER LIST 27Aug_SUM'!$A$1:$M$3170,MATCH($C3,'PASSENGER LIST 27Aug_SUM'!$B$1:$B$3170,0),MATCH('14SEP.NATURE.A2'!N$2,'PASSENGER LIST 27Aug_SUM'!$A$1:$M$1,0))} -> 0
A4: 2 | B4: {=INDEX('PASSENGER LIST 27Aug_SUM'!$A$1:$L$3170,MATCH($C4,'PASSENGER LIST 27Aug_SUM'!$B$1:$B$3170,0),MATCH('14SEP.NATURE.A2'!B$2,'PASSENGER LIST 27Aug_SUM'!$A$1:$L$1,0))} -> A2 | C4: X2NWSPH6J4K | D4: {=INDEX('PASSENGER LIST 27Aug_SUM'!$A$1:$K$3170,MATCH($C4,'PASSENGER LIST 27Aug_SUM'!$B$1:$B$3170,0),MATCH('14SEP.NATURE.A2'!D$2,'PASSENGER LIST 27Aug_SUM'!$A$1:$K$1,0))} -> 32N3X3VKNF2 | E4: {=INDEX('PASSENGER LIST 27Aug_SUM'!$A$1:$K$3170,MATCH($C4,'PASSENGER LIST 27Aug_SUM'!$B$1:$B$3170,0),MATCH('14SEP.NATURE.A2'!E$2,'PASSENGER LIST 27Aug_SUM'!$A$1:$K$1,0))} -> Sarah Lorraine | F4: {=INDEX('PASSENGER LIST 27Aug_SUM'!$A$1:$K$3170,MATCH($C4,'PASSENGER LIST 27Aug_SUM'!$B$1:$B$3170,0),MATCH('14SEP.NATURE.A2'!F$2,'PASSENGER LIST 27Aug_SUM'!$A$1:$K$1,0))} -> Go | G4: {=INDEX('PASSENGER LIST 27Aug_SUM'!$A$1:$L$3170,MATCH($C4,'PASSENGER LIST 27Aug_SUM'!$B$1:$B$3170,0),MATCH('14SEP.NATURE.A2'!G$2,'PASSENGER LIST 27Aug_SUM'!$A$1:$L$1,0))} -> Female | H4: {=INDEX('PASSENGER LIST 27Aug_SUM'!$A$1:$L$3170,MATCH($C4,'PASSENGER LIST 27Aug_SUM'!$B$1:$B$3170,0),MATCH('14SEP.NATURE.A2'!H$2,'PASSENGER LIST 27Aug_SUM'!$A$1:$L$1,0))} -> USA | I4: {=INDEX('PASSENGER LIST 27Aug_SUM'!$A$1:$L$3170,MATCH($C4,'PASSENGER LIST 27Aug_SUM'!$B$1:$B$3170,0),MATCH('14SEP.NATURE.A2'!I$2,'PASSENGER LIST 27Aug_SUM'!$A$1:$L$1,0))} -> 34 | J4: {=INDEX('PASSENGER LIST 27Aug_SUM'!$A$1:$L$3170,MATCH($C4,'PASSENGER LIST 27Aug_SUM'!$B$1:$B$3170,0),MATCH('14SEP.NATURE.A2'!J$2,'PASSENGER LIST 27Aug_SUM'!$A$1:$L$1,0))} -> INTER PARNAS | K4: {=INDEX('PASSENGER LIST 27Aug_SUM'!$A$1:$L$3170,MATCH($C4,'PASSENGER LIST 27Aug_SUM'!$B$1:$B$3170,0),MATCH('14SEP.NATURE.A2'!K$2,'PASSENGER LIST 27Aug_SUM'!$A$1:$L$1,0))} -> K-NATURE | L4: {=INDEX('PASSENGER LIST 27Aug_SUM'!$A$1:$L$3170,MATCH($C4,'PASSENGER LIST 27Aug_SUM'!$B$1:$B$3170,0),MATCH('14SEP.NATURE.A2'!L$2,'PASSENGER LIST 27Aug_SUM'!$A$1:$L$1,0))} -> No | M4: 45914 | N4: {=INDEX('PASSENGER LIST 27Aug_SUM'!$A$1:$M$3170,MATCH($C4,'PASSENGER LIST 27Aug_SUM'!$B$1:$B$3170,0),MATCH('14SEP.NATURE.A2'!N$2,'PASSENGER LIST 27Aug_SUM'!$A$1:$M$1,0))} -> 0
A5: 3 | B5: {=INDEX('PASSENGER LIST 27Aug_SUM'!$A$1:$L$3170,MATCH($C5,'PASSENGER LIST 27Aug_SUM'!$B$1:$B$3170,0),MATCH('14SEP.NATURE.A2'!B$2,'PASSENGER LIST 27Aug_SUM'!$A$1:$L$1,0))} -> A2 | C5: FKNCZSG8SYP | D5: {=INDEX('PASSENGER LIST 27Aug_SUM'!$A$1:$K$3170,MATCH($C5,'PASSENGER LIST 27Aug_SUM'!$B$1:$B$3170,0),MATCH('14SEP.NATURE.A2'!D$2,'PASSENGER LIST 27Aug_SUM'!$A$1:$K$1,0))} -> FKNCZSG8SYP | E5: {=INDEX('PASSENGER LIST 27Aug_SUM'!$A$1:$K$3170,MATCH($C5,'PASSENGER LIST 27Aug_SUM'!$B$1:$B$3170,0),MATCH('14SEP.NATURE.A2'!E$2,'PASSENGER LIST 27Aug_SUM'!$A$1:$K$1,0))} -> Xuezhi | F5: {=INDEX('PASSENGER LIST 27Aug_SUM'!$A$1:$K$3170,MATCH($C5,'PASSENGER LIST 27Aug_SUM'!$B$1:$B$3170,0),MATCH('14SEP.NATURE.A2'!F$2,'PASSENGER LIST 27Aug_SUM'!$A$1:$K$1,0))} -> Dai | G5: {=INDEX('PASSENGER LIST 27Aug_SUM'!$A$1:$L$3170,MATCH($C5,'PASSENGER LIST 27Aug_SUM'!$B$1:$B$3170,0),MATCH('14SEP.NATURE.A2'!G$2,'PASSENGER LIST 27Aug_SUM'!$A$1:$L$1,0))} -> Female | H5: {=INDEX('PASSENGER LIST 27Aug_SUM'!$A$1:$L$3170,MATCH($C5,'PASSENGER LIST 27Aug_SUM'!$B$1:$B$3170,0),MATCH('14SEP.NATURE.A2'!H$2,'PASSENGER LIST 27Aug_SUM'!$A$1:$L$1,0))} -> USA | I5: {=INDEX('PASSENGER LIST 27Aug_SUM'!$A$1:$L$3170,MATCH($C5,'PASSENGER LIST 27Aug_SUM'!$B$1:$B$3170,0),MATCH('14SEP.NATURE.A2'!I$2,'PASSENGER LIST 27Aug_SUM'!$A$1:$L$1,0))} -> 61 | J5: {=INDEX('PASSENGER LIST 27Aug_SUM'!$A$1:$L$3170,MATCH($C5,'PASSENGER LIST 27Aug_SUM'!$B$1:$B$3170,0),MATCH('14SEP.NATURE.A2'!J$2,'PASSENGER LIST 27Aug_SUM'!$A$1:$L$1,0))} -> THE PLAZA | K5: {=INDEX('PASSENGER LIST 27Aug_SUM'!$A$1:$L$3170,MATCH($C5,'PASSENGER LIST 27Aug_SUM'!$B$1:$B$3170,0),MATCH('14SEP.NATURE.A2'!K$2,'PASSENGER LIST 27Aug_SUM'!$A$1:$L$1,0))} -> K-NATURE | L5: {=INDEX('PASSENGER LIST 27Aug_SUM'!$A$1:$L$3170,MATCH($C5,'PASSENGER LIST 27Aug_SUM'!$B$1:$B$3170,0),MATCH('14SEP.NATURE.A2'!L$2,'PASSENGER LIST 27Aug_SUM'!$A$1:$L$1,0))} -> No | M5: 45914 | N5: {=INDEX('PASSENGER LIST 27Aug_SUM'!$A$1:$M$3170,MATCH($C5,'PASSENGER LIST 27Aug_SUM'!$B$1:$B$3170,0),MATCH('14SEP.NATURE.A2'!N$2,'PASSENGER LIST 27Aug_SUM'!$A$1:$M$1,0))} -> Upgrade - Plaza Suite
A6: 4 | B6: {=INDEX('PASSENGER LIST 27Aug_SUM'!$A$1:$L$3170,MATCH($C6,'PASSENGER LIST 27Aug_SUM'!$B$1:$B$3170,0),MATCH('14SEP.NATURE.A2'!B$2,'PASSENGER LIST 27Aug_SUM'!$A$1:$L$1,0))} -> A2 | C6: BFN7JYRNGH3 | D6: {=INDEX('PASSENGER LIST 27Aug_SUM'!$A$1:$K$3170,MATCH($C6,'PASSENGER LIST 27Aug_SUM'!$B$1:$B$3170,0),MATCH('14SEP.NATURE.A2'!D$2,'PASSENGER LIST 27Aug_SUM'!$A$1:$K$1,0))} -> FKNCZSG8SYP | E6: {=INDEX('PASSENGER LIST 27Aug_SUM'!$A$1:$K$3170,MATCH($C6,'PASSENGER LIST 27Aug_SUM'!$B$1:$B$3170,0),MATCH('14SEP.NATURE.A2'!E$2,'PASSENGER LIST 27Aug_SUM'!$A$1:$K$1,0))} -> Libo | F6: {=INDEX('PASSENGER LIST 27Aug_SUM'!$A$1:$K$3170,MATCH($C6,'PASSENGER LIST 27Aug_SUM'!$B$1:$B$3170,0),MATCH('14SEP.NATURE.A2'!F$2,'PASSENGER LIST 27Aug_SUM'!$A$1:$K$1,0))} -> Cai | G6: {=INDEX('PASSENGER LIST 27Aug_SUM'!$A$1:$L$3170,MATCH($C6,'PASSENGER LIST 27Aug_SUM'!$B$1:$B$3170,0),MATCH('14SEP.NATURE.A2'!G$2,'PASSENGER LIST 27Aug_SUM'!$A$1:$L$1,0))} -> Male | H6: {=INDEX('PASSENGER LIST 27Aug_SUM'!$A$1:$L$3170,MATCH($C6,'PASSENGER LIST 27Aug_SUM'!$B$1:$B$3170,0),MATCH('14SEP.NATURE.A2'!H$2,'PASSENGER LIST 27Aug_SUM'!$A$1:$L$1,0))} -> USA | I6: {=INDEX('PASSENGER LIST 27Aug_SUM'!$A$1:$L$3170,MATCH($C6,'PASSENGER LIST 27Aug_SUM'!$B$1:$B$3170,0),MATCH('14SEP.NATURE.A2'!I$2,'PASSENGER LIST 27Aug_SUM'!$A$1:$L$1,0))} -> 63 | J6: {=INDEX('PASSENGER LIST 27Aug_SUM'!$A$1:$L$3170,MATCH($C6,'PASSENGER LIST 27Aug_SUM'!$B$1:$B$3170,0),MATCH('14SEP.NATURE.A2'!J$2,'PASSENGER LIST 27Aug_SUM'!$A$1:$L$1,0))} -> THE PLAZA | K6: {=INDEX('PASSENGER LIST 27Aug_SUM'!$A$1:$L$3170,MATCH($C6,'PASSENGER LIST 27Aug_SUM'!$B$1:$B$3170,0),MATCH('14SEP.NATURE.A2'!K$2,'PASSENGER LIST 27Aug_SUM'!$A$1:$L$1,0))} -> K-NATURE | L6: {=INDEX('PASSENGER LIST 27Aug_SUM'!$A$1:$L$3170,MATCH($C6,'PASSENGER LIST 27Aug_SUM'!$B$1:$B$3170,0),MATCH('14SEP.NATURE.A2'!L$2,'PASSENGER LIST 27Aug_SUM'!$A$1:$L$1,0))} -> No | M6: 45914 | N6: {=INDEX('PASSENGER LIST 27Aug_SUM'!$A$1:$M$3170,MATCH($C6,'PASSENGER LIST 27Aug_SUM'!$B$1:$B$3170,0),MATCH('14SEP.NATURE.A2'!N$2,'PASSENGER LIST 27Aug_SUM'!$A$1:$M$1,0))} -> 0
A7: 5 | B7: {=INDEX('PASSENGER LIST 27Aug_SUM'!$A$1:$L$3170,MATCH($C7,'PASSENGER LIST 27Aug_SUM'!$B$1:$B$3170,0),MATCH('14SEP.NATURE.A2'!B$2,'PASSENGER LIST 27Aug_SUM'!$A$1:$L$1,0))} -> A2 | C7: CWNGKCGNHSR | D7: {=INDEX('PASSENGER LIST 27Aug_SUM'!$A$1:$K$3170,MATCH($C7,'PASSENGER LIST 27Aug_SUM'!$B$1:$B$3170,0),MATCH('14SEP.NATURE.A2'!D$2,'PASSENGER LIST 27Aug_SUM'!$A$1:$K$1,0))} -> CWNGKCGNHSR | E7: {=INDEX('PASSENGER LIST 27Aug_SUM'!$A$1:$K$3170,MATCH($C7,'PASSENGER LIST 27Aug_SUM'!$B$1:$B$3170,0),MATCH('14SEP.NATURE.A2'!E$2,'PASSENGER LIST 27Aug_SUM'!$A$1:$K$1,0))} -> Jeffrey Fei | F7: {=INDEX('PASSENGER LIST 27Aug_SUM'!$A$1:$K$3170,MATCH($C7,'PASSENGER LIST 27Aug_SUM'!$B$1:$B$3170,0),MATCH('14SEP.NATURE.A2'!F$2,'PASSENGER LIST 27Aug_SUM'!$A$1:$K$1,0))} -> Jin | G7: {=INDEX('PASSENGER LIST 27Aug_SUM'!$A$1:$L$3170,MATCH($C7,'PASSENGER LIST 27Aug_SUM'!$B$1:$B$3170,0),MATCH('14SEP.NATURE.A2'!G$2,'PASSENGER LIST 27Aug_SUM'!$A$1:$L$1,0))} -> Male | H7: {=INDEX('PASSENGER LIST 27Aug_SUM'!$A$1:$L$3170,MATCH($C7,'PASSENGER LIST 27Aug_SUM'!$B$1:$B$3170,0),MATCH('14SEP.NATURE.A2'!H$2,'PASSENGER LIST 27Aug_SUM'!$A$1:$L$1,0))} -> USA | I7: {=INDEX('PASSENGER LIST 27Aug_SUM'!$A$1:$L$3170,MATCH($C7,'PASSENGER LIST 27Aug_SUM'!$B$1:$B$3170,0),MATCH('14SEP.NATURE.A2'!I$2,'PASSENGER LIST 27Aug_SUM'!$A$1:$L$1,0))} -> 53 | J7: {=INDEX('PASSENGER LIST 27Aug_SUM'!$A$1:$L$3170,MATCH($C7,'PASSENGER LIST 27Aug_SUM'!$B$1:$B$3170,0),MATCH('14SEP.NATURE.A2'!J$2,'PASSENGER LIST 27Aug_SUM'!$A$1:$L$1,0))} -> THE PLAZA | K7: {=INDEX('PASSENGER LIST 27Aug_SUM'!$A$1:$L$3170,MATCH($C7,'PASSENGER LIST 27Aug_SUM'!$B$1:$B$3170,0),MATCH('14SEP.NATURE.A2'!K$2,'PASSENGER LIST 27Aug_SUM'!$A$1:$L$1,0))} -> K-NATURE | L7: {=INDEX('PASSENGER LIST 27Aug_SUM'!$A$1:$L$3170,MATCH($C7,'PASSENGER LIST 27Aug_SUM'!$B$1:$B$3170,0),MATCH('14SEP.NATURE.A2'!L$2,'PASSENGER LIST 27Aug_SUM'!$A$1:$L$1,0))} -> No | M7: 45914 | N7: {=INDEX('PASSENGER LIST 27Aug_SUM'!$A$1:$M$3170,MATCH($C7,'PASSENGER LIST 27Aug_SUM'!$B$1:$B$3170,0),MATCH('14SEP.NATURE.A2'!N$2,'PASSENGER LIST 27Aug_SUM'!$A$1:$M$1,0))} -> 0
A8: 6 | B8: {=INDEX('PASSENGER LIST 27Aug_SUM'!$A$1:$L$3170,MATCH($C8,'PASSENGER LIST 27Aug_SUM'!$B$1:$B$3170,0),MATCH('14SEP.NATURE.A2'!B$2,'PASSENGER LIST 27Aug_SUM'!$A$1:$L$1,0))} -> A2 | C8: 2GNB7WXN7XN | D8: {=INDEX('PASSENGER LIST 27Aug_SUM'!$A$1:$K$3170,MATCH($C8,'PASSENGER LIST 27Aug_SUM'!$B$1:$B$3170,0),MATCH('14SEP.NATURE.A2'!D$2,'PASSENGER LIST 27Aug_SUM'!$A$1:$K$1,0))} -> CWNGKCGNHSR | E8: {=INDEX('PASSENGER LIST 27Aug_SUM'!$A$1:$K$3170,MATCH($C8,'PASSENGER LIST 27Aug_SUM'!$B$1:$B$3170,0),MATCH('14SEP.NATURE.A2'!E$2,'PASSENGER LIST 27Aug_SUM'!$A$1:$K$1,0))} -> Xiaoying | F8: {=INDEX('PASSENGER LIST 27Aug_SUM'!$A$1:$K$3170,MATCH($C8,'PASSENGER LIST 27Aug_SUM'!$B$1:$B$3170,0),MATCH('14SEP.NATURE.A2'!F$2,'PASSENGER LIST 27Aug_SUM'!$A$1:$K$1,0))} -> Shang | G8: {=INDEX('PASSENGER LIST 27Aug_SUM'!$A$1:$L$3170,MATCH($C8,'PASSENGER LIST 27Aug_SUM'!$B$1:$B$3170,0),MATCH('14SEP.NATURE.A2'!G$2,'PASSENGER LIST 27Aug_SUM'!$A$1:$L$1,0))} -> Female | H8: {=INDEX('PASSENGER LIST 27Aug_SUM'!$A$1:$L$3170,MATCH($C8,'PASSENGER LIST 27Aug_SUM'!$B$1:$B$3170,0),MATCH('14SEP.NATURE.A2'!H$2,'PASSENGER LIST 27Aug_SUM'!$A$1:$L$1,0))} -> USA | I8: {=INDEX('PASSENGER LIST 27Aug_SUM'!$A$1:$L$3170,MATCH($C8,'PASSENGER LIST 27Aug_SUM'!$B$1:$B$3170,0),MATCH('14SEP.NATURE.A2'!I$2,'PASSENGER LIST 27Aug_SUM'!$A$1:$L$1,0))} -> 53 | J8: {=INDEX('PASSENGER LIST 27Aug_SUM'!$A$1:$L$3170,MATCH($C8,'PASSENGER LIST 27Aug_SUM'!$B$1:$B$3170,0),MATCH('14SEP.NATURE.A2'!J$2,'PASSENGER LIST 27Aug_SUM'!$A$1:$L$1,0))} -> THE PLAZA | K8: {=INDEX('PASSENGER LIST 27Aug_SUM'!$A$1:$L$3170,MATCH($C8,'PASSENGER LIST 27Aug_SUM'!$B$1:$B$3170,0),MATCH('14SEP.NATURE.A2'!K$2,'PASSENGER LIST 27Aug_SUM'!$A$1:$L$1,0))} -> K-NATURE | L8: {=INDEX('PASSENGER LIST 27Aug_SUM'!$A$1:$L$3170,MATCH($C8,'PASSENGER LIST 27Aug_SUM'!$B$1:$B$3170,0),MATCH('14SEP.NATURE.A2'!L$2,'PASSENGER LIST 27Aug_SUM'!$A$1:$L$1,0))} -> No | M8: 45914 | N8: {=INDEX('PASSENGER LIST 27Aug_SUM'!$A$1:$M$3170,MATCH($C8,'PASSENGER LIST 27Aug_SUM'!$B$1:$B$3170,0),MATCH('14SEP.NATURE.A2'!N$2,'PASSENGER LIST 27Aug_SUM'!$A$1:$M$1,0))} -> 0
A9: 7 | B9: {=INDEX('PASSENGER LIST 27Aug_SUM'!$A$1:$L$3170,MATCH($C9,'PASSENGER LIST 27Aug_SUM'!$B$1:$B$3170,0),MATCH('14SEP.NATURE.A2'!B$2,'PASSENGER LIST 27Aug_SUM'!$A$1:$L$1,0))} -> A2 | C9: D9N5CHFZLVR | D9: {=INDEX('PASSENGER LIST 27Aug_SUM'!$A$1:$K$3170,MATCH($C9,'PASSENGER LIST 27Aug_SUM'!$B$1:$B$3170,0),MATCH('14SEP.NATURE.A2'!D$2,'PASSENGER LIST 27Aug_SUM'!$A$1:$K$1,0))} -> D9N5CHFZLVR | E9: {=INDEX('PASSENGER LIST 27Aug_SUM'!$A$1:$K$3170,MATCH($C9,'PASSENGER LIST 27Aug_SUM'!$B$1:$B$3170,0),MATCH('14SEP.NATURE.A2'!E$2,'PASSENGER LIST 27Aug_SUM'!$A$1:$K$1,0))} -> Prescilia Nana | F9: {=INDEX('PASSENGER LIST 27Aug_SUM'!$A$1:$K$3170,MATCH($C9,'PASSENGER LIST 27Aug_SUM'!$B$1:$B$3170,0),MATCH('14SEP.NATURE.A2'!F$2,'PASSENGER LIST 27Aug_SUM'!$A$1:$K$1,0))} -> Ndoping | G9: {=INDEX('PASSENGER LIST 27Aug_SUM'!$A$1:$L$3170,MATCH($C9,'PASSENGER LIST 27Aug_SUM'!$B$1:$B$3170,0),MATCH('14SEP.NATURE.A2'!G$2,'PASSENGER LIST 27Aug_SUM'!$A$1:$L$1,0))} -> Female | H9: {=INDEX('PASSENGER LIST 27Aug_SUM'!$A$1:$L$3170,MATCH($C9,'PASSENGER LIST 27Aug_SUM'!$B$1:$B$3170,0),MATCH('14SEP.NATURE.A2'!H$2,'PASSENGER LIST 27Aug_SUM'!$A$1:$L$1,0))} -> USA | I9: {=INDEX('PASSENGER LIST 27Aug_SUM'!$A$1:$L$3170,MATCH($C9,'PASSENGER LIST 27Aug_SUM'!$B$1:$B$3170,0),MATCH('14SEP.NATURE.A2'!I$2,'PASSENGER LIST 27Aug_SUM'!$A$1:$L$1,0))} -> 63 | J9: {=INDEX('PASSENGER LIST 27Aug_SUM'!$A$1:$L$3170,MATCH($C9,'PASSENGER LIST 27Aug_SUM'!$B$1:$B$3170,0),MATCH('14SEP.NATURE.A2'!J$2,'PASSENGER LIST 27Aug_SUM'!$A$1:$L$1,0))} -> THE PLAZA | K9: {=INDEX('PASSENGER LIST 27Aug_SUM'!$A$1:$L$3170,MATCH($C9,'PASSENGER LIST 27Aug_SUM'!$B$1:$B$3170,0),MATCH('14SEP.NATURE.A2'!K$2,'PASSENGER LIST 27Aug_SUM'!$A$1:$L$1,0))} -> K-NATURE | L9: {=INDEX('PASSENGER LIST 27Aug_SUM'!$A$1:$L$3170,MATCH($C9,'PASSENGER LIST 27Aug_SUM'!$B$1:$B$3170,0),MATCH('14SEP.NATURE.A2'!L$2,'PASSENGER LIST 27Aug_SUM'!$A$1:$L$1,0))} -> No | M9: 45914 | N9: {=INDEX('PASSENGER LIST 27Aug_SUM'!$A$1:$M$3170,MATCH($C9,'PASSENGER LIST 27Aug_SUM'!$B$1:$B$3170,0),MATCH('14SEP.NATURE.A2'!N$2,'PASSENGER LIST 27Aug_SUM'!$A$1:$M$1,0))} -> 0
