Workbook
Name Header: '[1]List Tracking'!$C$9:$BS$9

Sheet Master booking sum
D2: Journey Beyond Asia (JBA)
F7: MASTER BOOKING SUMMARY
F8: GROUP B
E10: Hotel: | F10: LOTTE SEOUL HOTEL
E11: Attention: | F11: David Koo
E13: Submitted Date: | F13: 45905
E16: Dear Sir/Madam,
E18: Greetings from Journey Beyond Asia (JBA)
E20: We are pleased to send you the total number of confirmed room for main group, including pre- & post-night bookings, as details in the rooming list on the next sheet.
D23: NO. | E23: ROOM TYPE | F23: NUMBER OF ROOM | I23: EXTRA SERVICES | K23: PERIOD OF STAY | N23: NOTES
F24: Single | G24: Double room | H24: Twin room | I24: Extra bed | J24: CHILD (4 - under 12 ys) | K24: CHECK-IN | L24: CHECK-OUT | M24: No of NIGHT | N24: CONTRACT RATE | O24: NEW RATE | P24: NOTES
D25: 1 | E25: ROH | F25: ='Rooming list'!J5 -> 15 | G25: ='Rooming list'!K5 -> 74 | H25: ='Rooming list'!L5 -> 48 | I25: ='Rooming list'!M5 -> 0 | J25: ='Rooming list'!Q5 -> 10 | K25: 45918 | L25: 45923 | M25: =L25-K25 -> 5
D26: 2 | E26: 1 PRE-NIGHT | G26: 1 | K26: 45917 | L26: 45918 | M26: =L26-K26 -> 1
D27: 3 | E27: 1 POST-NIGHT | K27: 45923 | L27: 45924 | M27: 1
D28: 4 | E28: 2 PRE-NIGHT | K28: 45916 | L28: 45918 | M28: =L28-K28 -> 2
E29: 2 POST-NIGHT | K29: 45923 | L29: 45925 | M29: 2
E30: 3 PRE-NIGHT | K30: 45915 | L30: 45918 | M30: =L30-K30 -> 3
E31: 3 POST-NIGHT | K31: 45923 | L31: 45926 | M31: 3
D32: 8 | E32: SUBTOTAL - PRE & POST | F32: =SUM(F26:F31) -> 0 | G32: =SUM(G26:G31) -> 1 | H32: =SUM(H26:H31) -> 0
D33: 5 | E33: CHILD BREAKFAST SURCHARGE | J33: =J25 -> 10
D34: TOTAL (ROOM): | F34: =F25+G25+H25 -> 137 | G34: ROOMS
D35: MAIN GROUP TOTAL ROOM NIGHTS: | F35: =F34*M25 -> 685 | G35: Room nights
D36: TOTAL PRE&POST NIGHTS: | F36: =F32+G32+H32 -> 1 | G36: Room nights
D37: GRAND TOTAL: | F37: =SUM(F35:G36) -> 686 | G37: Room nights
D41: 1. Inclusions
D42: - Room rate includes of buffet breakfast, service charge, all taxes, in-room wifi and will be settled by JBA (Master Bill)
D43: -No incidental charges may be posted to the room. Any such charges (if incurred) will be paid directly by the guest.
D45: 2. VAT invoice information: PLEASE INCLUDE BELOW INFORMATION IN THE FINAL INVOICE
D47: - Name : | F47: JBA COMPANY LIMITED
D48: - Address : | F48: 5th Floor, CJ Building, 6 Le Thanh Ton St., Sai Gon Ward, HCM City., Vietnam.
D49: - VAT code : | F49: 0314965640
D50: - Email : | F50: info@jba-dmc.com

Sheet Rooming list
D2: ROOM LIST FOR LOTTE SEOUL_GROUP B
H4: SEOUL LOTTE | I4: ROOM TOTAL | J4: SINGLE | K4: DOUBLE | L4: TWIN | M4: EXTRA BED | N4: PRE & POST NIGHTS | O4: PAX TOTAL | P4: ADULT | Q4: CHD (4 TO UNDER 12 Y/O)
H5: LOTTE | I5: =SUM(J5:L5) -> 137 | J5: =SUM(Y10:Y289) -> 15 | K5: =SUM(Z10:Z289) -> 74 | L5: =SUM(AA10:AA289) -> 48 | M5: 0 | N5: 1 | O5: =SUM(P5:Q5) -> 269 | P5: =SUM(V10:V289) -> 259 | Q5: =COUNTIFS(M10:M289,">3",M10:M289,"<12") -> 10
D6: Provided by Hotel | U6: Pax Count | X6: Room Count | AC6: International Filght | AF6: International Filght
C8: ROOM # | D8: HOTEL CONFIRM # | E8: GRP ID | F8: ROOM MATE CFM # | G8: PRIMARY CFM # | H8: FIRST NAME | I8: LAST NAME | J8: GENDER | K8: NATIONALITY | L8: DOB | M8: AGE | N8: PASSPORT | P8: ROOM TYPE | Q8: PRE & POST | R8: IN | S8: OUT | T8: RN | U8: TOTAL PAX | V8: ADULT | W8: CHILD | X8: TOTAL ROOM | Y8: SGL | Z8: DBL | AA8: TWIN | AB8: EXTRA BED | AC8: ARRIVAL | AF8: DEPARTURE | AI8: CEO | AJ8: VIP | AK8: SPECIAL REQUEST | AL8: HOTEL | AM8: GROUP | AN8: CATEGORY | AO8: ROOM SERVICE | AP8: MODIFICATION NOTES
N9: Number | O9: Expiry Date | AC9: ARR DATE | AD9: ETA | AE9: FLIGHT # | AF9: DEPT DATE | AG9: ETD | AH9: FLIGHT #
C10: 1 | D10: 15262602 | E10: LO-B01 | F10: 8WNBRPHWK2Q | G10: 8WNBRPHWK2Q | H10: Sonie | I10: Derius | J10: Female | K10: USA | L10: 29910 | M10: 43 | N10: A19847898 | O10: 48687 | P10: DOUBLE | R10: 45918 | S10: 45923 | T10: =S10-R10 -> 5 | U10: 1 | V10: 1 | W10: 0 | X10: 1 | Y10: 0 | Z10: 1 | AA10: 0 | AC10: 45918 | AD10: 0.19097222 | AE10: KE 720 | AF10: 45923 | AG10: 0.79513889 | AH10: AC 62 | AI10: Alec Chan | AL10: LOTTE | AM10: B | AN10: DD
E11: LO-B01 | F11: YQNJDWRVP3C | G11: 8WNBRPHWK2Q | H11: Josue | I11: Mezier | J11: Male | K11: USA | L11: 29631 | M11: 44 | N11: 588677965 | O11: 46949 | P11: DOUBLE | R11: 45918 | S11: 45923 | T11: =S11-R11 -> 5 | U11: 1 | V11: 1 | W11: 0 | X11: 0 | Y11: 0 | Z11: 0 | AA11: 0 | AC11: 45918 | AD11: 0.19097222 | AE11: KE 720 | AF11: 45923 | AG11: 0.79513889 | AH11: AC 62 | AI11: Alec Chan | AL11: LOTTE | AM11: B | AN11: DD
E12: LO-B01 | F12: VPNJZ36VNFD | G12: 8WNBRPHWK2Q | H12: Laureen Josie | I12: Mezier | J12: Female | K12: USA | L12: 41626 | M12: 11 | N12: A32906203 | O12: 47205 | P12: DOUBLE | R12: 45918 | S12: 45923 | T12: =S12-R12 -> 5 | U12: 1 | V12: 0 | W12: 1 | X12: 0 | Y12: 0 | Z12: 0 | AA12: 0 | AC12: 45918 | AD12: 0.19097222 | AE12: KE 720 | AF12: 45923 | AG12: 0.79513889 | AH12: AC 62 | AI12: Alec Chan | AL12: LOTTE | AM12: B | AN12: DD
C13: =IF($X13=1,COUNTIF($C$10:C12,">0")+1,"") -> 2 | D13: 15262603 | E13: LO-B01 | F13: Q6NRTQ4FF5L | G13: Q6NRTQ4FF5L | H13: Corazon Bathan | I13: Tuiza | J13: Female | K13: Canada | L13: 20461 | M13: 69 | N13: AD922864 | O13: 46732 | P13: DOUBLE | R13: 45918 | S13: 45923 | T13: =S13-R13 -> 5 | U13: 1 | V13: 1 | W13: 0 | X13: 1 | Y13: 0 | Z13: 1 | AA13: 0 | AC13: 45918 | AD13: 0.50694444 | AE13: Z2 884 | AH13: NO NEED | AI13: Alec Chan | AL13: LOTTE | AM13: B | AN13: DD
C14: =IF($X14=1,COUNTIF($C$10:C13,">0")+1,"") | E14: LO-B01 | F14: 52N8CDH3QMY | G14: Q6NRTQ4FF5L | H14: Ricardo Rivera | I14: Tuiza | J14: Male | K14: Canada | L14: 19979 | M14: 71 | N14: AR016929 | O14: 47875 | P14: DOUBLE | R14: 45918 | S14: 45923 | T14: =S14-R14 -> 5 | U14: 1 | V14: 1 | W14: 0 | X14: 0 | Y14: 0 | Z14: 0 | AA14: 0 | AC14: 45918 | AD14: 0.50694444 | AE14: Z2 884 | AH14: NO NEED | AI14: Alec Chan | AL14: LOTTE | AM14: B | AN14: DD
C15: =IF($X15=1,COUNTIF($C$10:C14,">0")+1,"") -> 3 | D15: 15262682 | E15: LO-B07 | F15: X5NV882ZWSS | G15: X5NV882ZWSS | H15: Michelle | I15: Williams | J15: Female | K15: USA | L15: 27388 | M15: 50 | N15: 640008393 | O15: 47321 | P15: SINGLE | R15: 45918 | S15: 45923 | T15: =S15-R15 -> 5 | U15: 1 | V15: 1 | W15: 0 | X15: 1 | Y15: 1 | Z15: 0 | AA15: 0 | AC15: 45918 | AD15: 0.74305556 | AE15: KE 82 | AF15: 45923 | AG15: 0.8125 | AH15: KE 85 | AI15: Nan Satt | AL15: LOTTE | AM15: B | AN15: DD
C16: =IF($X16=1,COUNTIF($C$10:C15,">0")+1,"") | E16: LO-B01 | F16: 5GNQFH4QLK8 | G16: C4NLZBY43S5 | H16: Riza | I16: Mariano | J16: Female | K16: Canada | L16: 28099 | M16: 48 | N16: AT604361 | O16: 48494 | P16: DOUBLE | R16: 45918 | S16: 45923 | T16: =S16-R16 -> 5 | U16: 1 | V16: 1 | W16: 0 | X16: 0 | Y16: 0 | Z16: 0 | AA16: 0 | AI16: Alec Chan | AL16: LOTTE | AM16: B | AN16: DD
C17: =IF($X17=1,COUNTIF($C$10:C16,">0")+1,"") -> 4 | D17: 15262605 | E17: LO-B01 | F17: LKNTWN3G59Y | G17: LKNTWN3G59Y | H17: Andrew Leigh | I17: Karas | J17: Male | K17: USA | L17: 27038 | M17: 51 | N17: 549325122 | O17: 46280 | P17: SINGLE | R17: 45918 | S17: 45923 | T17: =S17-R17 -> 5 | U17: 1 | V17: 1 | W17: 0 | X17: 1 | Y17: 1 | Z17: 0 | AA17: 0 | AC17: 45913 | AD17: 0.64583333 | AE17: AA 281 | AF17: 45924 | AG17: 0.72569444 | AH17: AA 280 | AI17: Alec Chan | AL17: LOTTE | AM17: B | AN17: DD
C18: =IF($X18=1,COUNTIF($C$10:C17,">0")+1,"") -> 5 | D18: 15262606 | E18: LO-B02 | F18: D4NCQCBVVZL | G18: D4NCQCBVVZL | H18: Danfeng | I18: Chen | J18: Female | K18: USA | L18: 30611 | M18: 41 | N18: 561139482 | O18: 46439 | P18: DOUBLE | R18: 45918 | S18: 45923 | T18: =S18-R18 -> 5 | U18: 1 | V18: 1 | W18: 0 | X18: 1 | Y18: 0 | Z18: 1 | AA18: 0 | AC18: 45918 | AD18: 0.72916667 | AE18: AC 61 | AF18: 45923 | AG18: 0.79513889 | AH18: AC 62 | AI18: Annie Chen | AJ18: CEO VIP | AL18: LOTTE | AM18: B | AN18: DD
C19: =IF($X19=1,COUNTIF($C$10:C18,">0")+1,"") | E19: LO-B02 | F19: C8NDW74RXVT | G19: D4NCQCBVVZL | H19: Fei | I19: Li | J19: Male | K19: USA | L19: 29124 | M19: 45 | N19: 565537441 | O19: 46542 | P19: DOUBLE | R19: 45918 | S19: 45923 | T19: =S19-R19 -> 5 | U19: 1 | V19: 1 | W19: 0 | X19: 0 | Y19: 0 | Z19: 0 | AA19: 0 | AC19: 45918 | AD19: 0.72916667 | AE19: AC 61 | AF19: 45923 | AG19: 0.79513889 | AH19: AC 62 | AI19: Annie Chen | AL19: LOTTE | AM19: B | AN19: DD
C20: =IF($X20=1,COUNTIF($C$10:C19,">0")+1,"") -> 6 | D20: 15262607 | E20: LO-B02 | F20: V5NGQKB2WFF | G20: V5NGQKB2WFF | H20: Qiaohua | I20: Zou | J20: Female | K20: USA | L20: 33545 | M20: 33 | N20: 651671934 | O20: 47539 | P20: SINGLE | R20: 45918 | S20: 45923 | T20: =S20-R20 -> 5 | U20: 1 | V20: 1 | W20: 0 | X20: 1 | Y20: 1 | Z20: 0 | AA20: 0 | AC20: 45918 | AD20: 0.65277778 | AE20: KE 128 | AF20: 45923 | AG20: 0.34722222 | AH20: KE 127 | AI20: Annie Chen | AL20: LOTTE | AM20: B | AN20: DD
C21: =IF($X21=1,COUNTIF($C$10:C20,">0")+1,"") -> 7 | D21: 15262608 | E21: LO-B12 | F21: 3MN8G6BW3XJ | G21: 3MN8G6BW3XJ | H21: Chito Mendoza | I21: Roxas | J21: Male | K21: USA | L21: 23087 | M21: 62 | N21: 550072142 | O21: 46398 | P21: DOUBLE | R21: 45918 | S21: 45923 | T21: =S21-R21 -> 5 | U21: 1 | V21: 1 | W21: 0 | X21: 1 | Y21: 0 | Z21: 1 | AA21: 0 | AC21: 45918 | AD21: 0.25 | AE21: PR 466 | AF21: 45923 | AG21: 0.85416667 | AH21: PR 469 | AI21: Chito Roxas | AJ21: CEO VIP | AL21: LOTTE | AM21: B | AN21: DD
C22: =IF($X22=1,COUNTIF($C$10:C21,">0")+1,"") | E22: LO-B12 | F22: YTNSLFFGMC5 | G22: 3MN8G6BW3XJ | H22: Sheila Salunga | I22: Roxas | J22: Female | K22: USA | L22: 27667 | M22: 49 | N22: 550072143 | O22: 46398 | P22: DOUBLE | R22: 45918 | S22: 45923 | T22: =S22-R22 -> 5 | U22: 1 | V22: 1 | W22: 0 | X22: 0 | Y22: 0 | Z22: 0 | AA22: 0 | AC22: 45918 | AD22: 0.25 | AE22: PR 466 | AF22: 45923 | AG22: 0.85416667 | AH22: PR 469 | AI22: Chito Roxas | AL22: LOTTE | AM22: B | AN22: DD
C23: =IF($X23=1,COUNTIF($C$10:C22,">0")+1,"") -> 8 | D23: 15262609 | E23: LO-B03 | F23: SXN8W63YJDW | G23: SXN8W63YJDW | H23: Chloe | I23: Xu | J23: Female | K23: USA | L23: 30394 | M23: 42 | N23: 566463012 | O23: 47188 | P23: TWIN | R23: 45918 | S23: 45923 | T23: =S23-R23 -> 5 | U23: 1 | V23: 1 | W23: 0 | X23: 1 | Y23: 0 | Z23: 0 | AA23: 1 | AC23: 45918 | AD23: 0.47569444 | AE23: RF 315 | AF23: 45923 | AG23: 0.89583333 | AH23: YP 131 | AI23: Chloe Xu | AJ23: CEO VIP | AL23: LOTTE | AM23: B | AN23: GT
C24: =IF($X24=1,COUNTIF($C$10:C23,">0")+1,"") | E24: LO-B03 | F24: CLN3ZSSV4Z5 | G24: SXN8W63YJDW | H24: Weiyou | I24: Chen | J24: Male | K24: China | L24: 30270 | M24: 42 | N24: EJ2675473 | O24: 47854 | P24: TWIN | R24: 45918 | S24: 45923 | T24: =S24-R24 -> 5 | U24: 1 | V24: 1 | W24: 0 | X24: 0 | Y24: 0 | Z24: 0 | AA24: 0 | AC24: 45918 | AD24: 0.47569444 | AE24: RF 315 | AF24: 45923 | AG24: 0.89583333 | AH24: YP 131 | AI24: Chloe Xu | AL24: LOTTE | AM24: B | AN24: GT
C25: =IF($X25=1,COUNTIF($C$10:C24,">0")+1,"") | E25: LO-B03 | F25: GDN2BZRCB7K | G25: SXN8W63YJDW | H25: Felix Kai | I25: Chen | J25: Male | K25: USA | L25: 42734 | M25: 8 | N25: A05570520 | O25: 46748 | P25: TWIN | R25: 45918 | S25: 45923 | T25: =S25-R25 -> 5 | U25: 1 | V25: 0 | W25: 1 | X25: 0 | Y25: 0 | Z25: 0 | AA25: 0 | AC25: 45918 | AD25: 0.47569444 | AE25: RF 315 | AF25: 45923 | AG25: 0.89583333 | AH25: YP 131 | AI25: Chloe Xu | AL25: LOTTE | AM25: B | AN25: GT
C26: =IF($X26=1,COUNTIF($C$10:C25,">0")+1,"") -> 9 | D26: 15262610 | E26: LO-B03 | F26: VLNXVYL2DKH | G26: VLNXVYL2DKH | H26: Julia | I26: Huang | J26: Female | K26: USA | L26: 36315 | M26: 26 | N26: A33566887 | O26: 48909 | P26: DOUBLE | R26: 45918 | S26: 45923 | T26: =S26-R26 -> 5 | U26: 1 | V26: 1 | W26: 0 | X26: 1 | Y26: 0 | Z26: 1 | AA26: 0 | AC26: 45918 | AD26: 0.72222222 | AE26: DL 171 | AF26: 45923 | AG26: 0.34027778 | AH26: RS 705 | AI26: Chloe Xu | AL26: LOTTE | AM26: B | AN26: GD
C27: =IF($X27=1,COUNTIF($C$10:C26,">0")+1,"") | E27: LO-B03 | F27: PSNJ9PDGZMJ | G27: VLNXVYL2DKH | H27: Matthew | I27: Williams | J27: Male | K27: USA | L27: 37210 | M27: 23 | N27: A68772515 | O27: 49461 | P27: DOUBLE | R27: 45918 | S27: 45923 | T27: =S27-R27 -> 5 | U27: 1 | V27: 1 | W27: 0 | X27: 0 | Y27: 0 | Z27: 0 | AA27: 0 | AC27: 45918 | AD27: 0.72222222 | AE27: DL 171 | AF27: 45923 | AG27: 0.34027778 | AH27: RS 705 | AI27: Chloe Xu | AL27: LOTTE | AM27: B | AN27: GD
C28: =IF($X28=1,COUNTIF($C$10:C27,">0")+1,"") -> 10 | D28: 15262611 | E28: LO-B03 | F28: RXNSXKSFMFM | G28: VLNXVYL2DKH | H28: Mei Juan | I28: Lin | J28: Female | K28: USA | L28: 26600 | M28: 52 | N28: A04383968 | O28: 48654 | P28: TWIN | R28: 45918 | S28: 45923 | T28: =S28-R28 -> 5 | U28: 1 | V28: 1 | W28: 0 | X28: 1 | Y28: 0 | Z28: 0 | AA28: 1 | AC28: 45918 | AD28: 0.52777778 | AE28: CX 434 | AF28: 45923 | AG28: 0.34722222 | AH28: KE 127 | AI28: Chloe Xu | AL28: LOTTE | AM28: B | AN28: GT
C29: =IF($X29=1,COUNTIF($C$10:C28,">0")+1,"") | E29: LO-B03 | F29: NVNDGFQL98G | G29: VLNXVYL2DKH | H29: Li Jiao | I29: Ni | J29: Female | K29: USA | L29: 27237 | M29: 51 | N29: 533938897 | O29: 45922 | P29: TWIN | R29: 45918 | S29: 45923 | T29: =S29-R29 -> 5 | U29: 1 | V29: 1 | W29: 0 | X29: 0 | Y29: 0 | Z29: 0 | AA29: 0 | AC29: 45918 | AD29: 0.52777778 | AE29: CX 434 | AF29: 45923 | AG29: 0.83680556 | AH29: CX 419 | AI29: Chloe Xu | AL29: LOTTE | AM29: B | AN29: GT
C30: =IF($X30=1,COUNTIF($C$10:C29,">0")+1,"") -> 11 | D30: 15262612 | E30: LO-B03 | F30: ZBNWDQ7DB74 | G30: ZBNWDQ7DB74 | H30: Shirley | I30: Zheng | J30: Female | K30: USA | L30: 35858 | M30: 27 | N30: 563059598 | O30: 46601 | P30: DOUBLE | R30: 45918 | S30: 45923 | T30: =S30-R30 -> 5 | U30: 1 | V30: 1 | W30: 0 | X30: 1 | Y30: 0 | Z30: 1 | AA30: 0 | AC30: 45918 | AD30: 0.70138889 | AE30: OZ 221 | AF30: 45923 | AG30: 0.87847222 | AH30: OZ 224 | AI30: Chloe Xu | AL30: LOTTE | AM30: B | AN30: GD
C31: =IF($X31=1,COUNTIF($C$10:C30,">0")+1,"") | E31: LO-B03 | F31: L8N9LNXTQRQ | G31: ZBNWDQ7DB74 | H31: Jordan | I31: Watkins | J31: Male | K31: USA | L31: 35944 | M31: 27 | N31: A45570408 | O31: 49084 | P31: DOUBLE | R31: 45918 | S31: 45923 | T31: =S31-R31 -> 5 | U31: 1 | V31: 1 | W31: 0 | X31: 0 | Y31: 0 | Z31: 0 | AA31: 0 | AC31: 45918 | AD31: 0.70138889 | AE31: OZ 221 | AF31: 45923 | AG31: 0.87847222 | AH31: OZ 224 | AI31: Chloe Xu | AL31: LOTTE | AM31: B | AN31: GD
C32: =IF($X32=1,COUNTIF($C$10:C31,">0")+1,"") -> 12 | D32: 15262613 | E32: LO-B03 | F32: 42NSVD7LF5L | G32: 42NSVD7LF5L | H32: Wenhui | I32: Liu | J32: Female | K32: USA | L32: 31742 | M32: 38 | N32: A24226857 | O32: 48888 | P32: TWIN | R32: 45918 | S32: 45923 | T32: =S32-R32 -> 5 | U32: 1 | V32: 1 | W32: 0 | X32: 1 | Y32: 0 | Z32: 0 | AA32: 1 | AC32: 45918 | AD32: 0.52777778 | AE32: CX 434 | AF32: 45923 | AG32: 0.34722222 | AH32: KE 127 | AI32: Chloe Xu | AL32: LOTTE | AM32: B | AN32: GT
C33: =IF($X33=1,COUNTIF($C$10:C32,">0")+1,"") | E33: LO-B03 | F33: GWNTV942MT9 | G33: 42NSVD7LF5L | H33: Tina | I33: Huang | J33: Female | P33: TWIN | R33: 45918 | S33: 45923 | T33: =S33-R33 -> 5 | U33: 1 | V33: 1 | W33: 0 | X33: 0 | Y33: 0 | Z33: 0 | AA33: 0 | AC33: 45918 | AD33: 0.52777778 | AE33: CX 434 | AF33: 45923 | AG33: 0.34722222 | AH33: KE 127 | AI33: Chloe Xu | AL33: LOTTE | AM33: B | AN33: GT
C34: =IF($X34=1,COUNTIF($C$10:C33,">0")+1,"") -> 13 | D34: 15262614 | E34: LO-B03 | F34: PBNYX2J99PN | G34: PBNYX2J99PN | H34: Xiaorong | I34: Zhou | J34: Female | K34: China | L34: 33586 | M34: 33 | N34: Ẹ6005397 | O34: 48546 | P34: TWIN | R34: 45918 | S34: 45923 | T34: =S34-R34 -> 5 | U34: 1 | V34: 1 | W34: 0 | X34: 1 | Y34: 0 | Z34: 0 | AA34: 1 | AC34: 45918 | AD34: 0.25694444 | AE34: OZ 223 | AF34: 45923 | AG34: 0.36805556 | AH34: KE 865 | AI34: Chloe Xu | AL34: LOTTE | AM34: B | AN34: GT
C35: =IF($X35=1,COUNTIF($C$10:C34,">0")+1,"") | E35: LO-B03 | F35: ZPNF8CSXJLF | G35: PBNYX2J99PN | H35: Phoebe | I35: Chen | J35: Female | K35: USA | L35: 41026 | M35: 13 | P35: TWIN | R35: 45918 | S35: 45923 | T35: =S35-R35 -> 5 | U35: 1 | V35: 1 | W35: 0 | X35: 0 | Y35: 0 | Z35: 0 | AA35: 0 | AC35: 45918 | AD35: 0.25694444 | AE35: OZ 223 | AF35: 45923 | AG35: 0.36805556 | AH35: KE 865 | AI35: Chloe Xu | AL35: LOTTE | AM35: B | AN35: GT
C36: =IF($X36=1,COUNTIF($C$10:C35,">0")+1,"") -> 14 | D36: 15262615 | E36: LO-B03 | F36: 26N3QGV4RLH | G36: 26N3QGV4RLH | H36: Ming Jian | I36: Zhang | J36: Male | K36: USA | L36: 27072 | M36: 51 | N36: A43934207 | O36: 49202 | P36: TWIN | R36: 45918 | S36: 45923 | T36: =S36-R36 -> 5 | U36: 1 | V36: 1 | W36: 0 | X36: 1 | Y36: 0 | Z36: 0 | AA36: 1 | AC36: 45918 | AD36: 0.70138889 | AE36: KE 38 | AF36: 45923 | AG36: 0.44444444 | AH36: KE 37 | AI36: Chloe Xu | AL36: LOTTE | AM36: B | AN36: GT
C37: =IF($X37=1,COUNTIF($C$10:C36,">0")+1,"") | E37: LO-B03 | F37: JWNHZSWJZ7C | G37: 26N3QGV4RLH | H37: Jing | I37: Li | J37: Female | K37: USA | L37: 30427 | M37: 42 | N37: 671350229 | O37: 48181 | P37: TWIN | R37: 45918 | S37: 45923 | T37: =S37-R37 -> 5 | U37: 1 | V37: 1 | W37: 0 | X37: 0 | Y37: 0 | Z37: 0 | AA37: 0 | AC37: 45918 | AD37: 0.70138889 | AE37: KE 38 | AF37: 45923 | AG37: 0.44444444 | AH37: KE 37 | AI37: Chloe Xu | AL37: LOTTE | AM37: B | AN37: GT
C38: =IF($X38=1,COUNTIF($C$10:C37,">0")+1,"") -> 15 | D38: 15262616 | E38: LO-B03 | F38: QCNCJWCTVB5 | G38: 26N3QGV4RLH | H38: Viola | I38: Zhang | J38: Female | K38: USA | L38: 40872 | M38: 13 | N38: 673329615 | O38: 46354 | P38: TWIN | R38: 45918 | S38: 45923 | T38: =S38-R38 -> 5 | U38: 1 | V38: 1 | W38: 0 | X38: 1 | Y38: 0 | Z38: 0 | AA38: 1 | AC38: 45918 | AD38: 0.70138889 | AE38: KE 38 | AF38: 45923 | AG38: 0.44444444 | AH38: KE 37 | AI38: Chloe Xu | AL38: LOTTE | AM38: B | AN38: GT
C39: =IF($X39=1,COUNTIF($C$10:C38,">0")+1,"") | E39: LO-B03 | F39: HYNXBD2YXND | G39: 26N3QGV4RLH | H39: Hongping | I39: Zhou | J39: Female | K39: China | L39: 23388 | M39: 61 | N39: EJ4279245 | O39: 48407 | P39: TWIN | R39: 45918 | S39: 45923 | T39: =S39-R39 -> 5 | U39: 1 | V39: 1 | W39: 0 | X39: 0 | Y39: 0 | Z39: 0 | AA39: 0 | AC39: 45918 | AD39: 0.70138889 | AE39: KE 38 | AF39: 45923 | AG39: 0.44444444 | AH39: KE 37 | AI39: Chloe Xu | AL39: LOTTE | AM39: B | AN39: GT
C40: =IF($X40=1,COUNTIF($C$10:C39,">0")+1,"") -> 16 | D40: 15262617 | E40: LO-B03 | F40: 2SN77VLXC56 | G40: 2SN77VLXC56 | H40: Miaoyan | I40: Yang | J40: Female | K40: USA | L40: 31213 | M40: 40 | N40: A04719220 | O40: 48524 | P40: TWIN | R40: 45918 | S40: 45923 | T40: =S40-R40 -> 5 | U40: 1 | V40: 1 | W40: 0 | X40: 1 | Y40: 0 | Z40: 0 | AA40: 1 | AC40: 45918 | AD40: 0.22569444 | AE40: KE 178 | AF40: 45923 | AG40: 0.82291667 | AH40: KE 177 | AI40: Chloe Xu | AL40: LOTTE | AM40: B | AN40: GT
C41: =IF($X41=1,COUNTIF($C$10:C40,">0")+1,"") | E41: LO-B03 | F41: KNNV8JXGMLT | G41: 2SN77VLXC56 | H41: Wai Sun | I41: Mow | J41: Female | K41: USA | L41: 25848 | M41: 54 | N41: 660682382 | O41: 47887 | P41: TWIN | R41: 45918 | S41: 45923 | T41: =S41-R41 -> 5 | U41: 1 | V41: 1 | W41: 0 | X41: 0 | Y41: 0 | Z41: 0 | AA41: 0 | AC41: 45918 | AD41: 0.28472222 | AE41: KE 672 | AF41: 45923 | AG41: 0.68055556 | AH41: KE 671 | AI41: Chloe Xu | AL41: LOTTE | AM41: B | AN41: GT
C42: =IF($X42=1,COUNTIF($C$10:C41,">0")+1,"") -> 17 | D42: 15262618 | E42: LO-B03 | F42: DNNN22S3MCL | G42: DNNN22S3MCL | H42: Molly Tingjiun | I42: Lin | J42: Female | K42: USA | L42: 27438 | M42: 50 | N42: 662835915 | O42: 47900 | P42: TWIN | R42: 45918 | S42: 45923 | T42: =S42-R42 -> 5 | U42: 1 | V42: 1 | W42: 0 | X42: 1 | Y42: 0 | Z42: 0 | AA42: 1 | AC42: 45918 | AD42: 0.46875 | AE42: CI 160 | AF42: 45923 | AG42: 0.52430556 | AH42: CI 161 | AI42: Chloe Xu | AL42: LOTTE | AM42: B | AN42: GT
C43: =IF($X43=1,COUNTIF($C$10:C42,">0")+1,"") | E43: LO-B03 | F43: 93NNLPWKZF6 | G43: DNNN22S3MCL | H43: Feng Jiao | I43: Lin | J43: Female | K43: USA | L43: 27531 | M43: 50 | N43: 562758501 | O43: 46531 | P43: TWIN | R43: 45918 | S43: 45923 | T43: =S43-R43 -> 5 | U43: 1 | V43: 1 | W43: 0 | X43: 0 | Y43: 0 | Z43: 0 | AA43: 0 | AC43: 45918 | AD43: 0.52777778 | AE43: CX 434 | AF43: 45923 | AG43: 0.83680556 | AH43: CX 419 | AI43: Chloe Xu | AL43: LOTTE | AM43: B | AN43: GT
...
