Workbook
Name _Order1: 255
Name _Sort: #REF!
Name JBA_CODE: [1]Allocation!$AC$2:$AC$3234
Name status_gray: #REF!
Name vertex42_copyright: "© 2015 Vertex42 LLC"
Name vertex42_id: "purchase-order-tracker.xlsx"
Name vertex42_title: "Purchase Order Tracker"

Sheet manifest_11Sep
A1: Group | B1: Confirmation | C1: Primary registrant | D1: Gender | E1: First Name | F1: Last Name | G1: Age | H1: CEO | I1: A.Airline | J1: A.Flt | K1: A.Date | L1: A.Time | M1: A.Airport | N1: D. Airline | O1: D. Flt | P1: D. Date | Q1: D. Time | R1: D. Airport | S1: Hotel | T1: REMARKS | W1: HOTEL CONFRIMATION NUMBER
A2: A | B2: CSNMQ7XNY2S | C2: CSNMQ7XNY2S | D2: Male | E2: Adeolu | F2: Durotoye | G2: 55 | H2: Adeolu Durotoye | I2: WestJet | J2: WS 86 | K2: 13-thg 9-25 | L2: 0.78125 | M2: ICN-T1 | N2: WestJet | O2: WS 87 | P2: 18-thg 9-25 | Q2: 0.86458333 | R2: ICN-T1 | S2: LOTTE | T2: Upgrade - Junior Suite | W2: 15262305 | X2: SINGLE
A3: A | B3: BQN5YMBRTZ9 | C3: BQN5YMBRTZ9 | D3: Male | E3: Olanrewaju | F3: Ogunkoya | G3: 55 | H3: Adeolu Durotoye | I3: Delta | J3: DL 189 | K3: 13-thg 9-25 | L3: 0.59027778 | M3: ICN-T2 | N3: Delta | O3: DL 188 | P3: 18-thg 9-25 | Q3: 0.68402778 | R3: ICN-T2 | S3: LOTTE | W3: 15262306 | X3: DOUBLE
A4: A | B4: 8SNRDRCQPHQ | C4: BQN5YMBRTZ9 | D4: Female | E4: Bridget | F4: Taylor | G4: 55 | H4: Adeolu Durotoye | I4: Delta | J4: DL 189 | K4: 13-thg 9-25 | L4: 0.59027778 | M4: ICN-T2 | N4: Delta | O4: DL 188 | P4: 18-thg 9-25 | Q4: 0.68402778 | R4: ICN-T2 | S4: LOTTE | W4: 15262306 | X4: DOUBLE
A5: A | B5: FLN6XZFQTLH | C5: FLN6XZFQTLH | D5: Female | E5: Abolade | F5: Akinropo | G5: 53 | H5: Adeolu Durotoye | I5: Delta | J5: DL 171 | K5: 13-thg 9-25 | L5: 0.72222222 | M5: ICN-T2 | N5: Delta | O5: DL 172 | P5: 18-thg 9-25 | Q5: 0.81944444 | R5: ICN-T2 | S5: LOTTE | W5: 15262307 | X5: DOUBLE
A6: A | B6: VRNPD384X6N | C6: FLN6XZFQTLH | D6: Female | E6: Shola Jumoke | F6: Olori | G6: 65 | H6: Adeolu Durotoye | I6: Delta | J6: DL 171 | K6: 13-thg 9-25 | L6: 0.72222222 | M6: ICN-T2 | N6: Delta | O6: DL 172 | P6: 18-thg 9-25 | Q6: 0.81944444 | R6: ICN-T2 | S6: LOTTE | W6: 15262307 | X6: DOUBLE
A7: A | B7: 4BNHL9C6RWT | C7: 4BNHL9C6RWT | D7: Male | E7: Onuwabhagbe Ayemere | F7: Ogudo | G7: 46 | H7: Adeolu Durotoye | I7: WestJet | J7: WS 86 | K7: 13-thg 9-25 | L7: 0.78125 | M7: ICN-T1 | N7: Air Canada | O7: AC 64 | P7: 18-thg 9-25 | Q7: 0.73958333 | R7: ICN-T1 | S7: LOTTE | W7: 15262308 | X7: TWIN
A8: A | B8: VCNYDFDGQ8C | C8: 4BNHL9C6RWT | D8: Male | E8: Jeffrey Jafaru | F8: Usman | G8: 44 | H8: Adeolu Durotoye | I8: Air Canada | J8: AC 61 | K8: 12-thg 9-25 | L8: 0.72916667 | M8: ICN-T1 | N8: Korean Air | O8: KE 719 | P8: 18-thg 9-25 | Q8: 0.85416667 | R8: ICN-T2 | S8: LOTTE | W8: 15262308 | X8: TWIN
A9: A | B9: 3FNT9CQ6CWC | C9: 3FNT9CQ6CWC | D9: Male | E9: Paul | F9: Adeyeye | G9: 39 | H9: Adeolu Durotoye | I9: WestJet | J9: WS 86 | K9: 13-thg 9-25 | L9: 0.78125 | M9: ICN-T1 | N9: Air Canada | O9: AC 64 | P9: 18-thg 9-25 | Q9: 0.73958333 | R9: ICN-T1 | S9: LOTTE | W9: 15262309 | X9: DOUBLE
A10: A | B10: D5NZNQTZ4S6 | C10: 3FNT9CQ6CWC | D10: Male | E10: Idowu Adekola | F10: Nafiu | G10: 46 | H10: Adeolu Durotoye | I10: WestJet | J10: WS 86 | K10: 12-thg 9-25 | L10: 0.78125 | M10: ICN-T1 | N10: Air Canada | O10: AC 64 | P10: 18-thg 9-25 | Q10: 0.73958333 | R10: ICN-T1 | S10: LOTTE | W10: 15262309 | X10: DOUBLE
A11: A | B11: 64NQP9SW72V | C11: 64NQP9SW72V | D11: Female | E11: Folashade | F11: Awosanmi | G11: 59 | H11: Adeolu Durotoye | I11: Air Canada | J11: AC 61 | K11: 13-thg 9-25 | L11: 0.72916667 | M11: ICN-T1 | N11: Air Canada | O11: AC 62 | P11: 18-thg 9-25 | Q11: 0.79513889 | R11: ICN-T1 | S11: LOTTE | W11: 15262310 | X11: DOUBLE
A12: A | B12: 98NGTVNHG2X | C12: 64NQP9SW72V | D12: Female | E12: Sheri | F12: Agunbiade | G12: 54 | H12: Adeolu Durotoye | I12: Air Canada | J12: AC 63 | K12: 13-thg 9-25 | L12: 0.67013889 | M12: ICN-T1 | N12: Air Canada | O12: AC 64 | P12: 18-thg 9-25 | Q12: 0.73958333 | R12: ICN-T1 | S12: LOTTE | W12: 15262310 | X12: DOUBLE
A13: A | B13: FDNK6HN7Z9W | C13: FDNK6HN7Z9W | D13: Male | E13: Reynolds | F13: Edokpayi | G13: 35 | H13: Adeolu Durotoye | I13: Korean Air | J13: KE 660 | K13: 12-thg 9-25 | L13: 0.72222222 | M13: ICN-T2 | N13: Korean Air | O13: KE 71 | P13: 18-thg 9-25 | Q13: 0.78125 | R13: ICN-T2 | S13: LOTTE | W13: 15262311 | X13: DOUBLE
A14: A | B14: MGNWBNQ27JY | C14: FDNK6HN7Z9W | D14: Female | E14: Osasogie Deborah | F14: Edokpayi | G14: 31 | H14: Adeolu Durotoye | I14: Korean Air | J14: KE 660 | K14: 12-thg 9-25 | L14: 0.72222222 | M14: ICN-T2 | N14: Korean Air | O14: KE 71 | P14: 18-thg 9-25 | Q14: 0.78125 | R14: ICN-T2 | S14: LOTTE | W14: 15262311 | X14: DOUBLE
... A33: A | B33: P8NSJDPN4XX | C33: NPNGSRN48GW | D33: Female | E33: Kofo Monsurah | F33: Keshinro | G33: 42 | H33: Adeolu Durotoye | I33: American Airlines | J33: AA 281 | K33: 13-thg 9-25 | L33: 0.64583333 | M33: ICN-T1 | N33: American Airlines | O33: AA 280 | P33: 18-thg 9-25 | Q33: 0.72569444 | R33: ICN-T1 | S33: LOTTE | W33: 15262320 | X33: TWIN
A34: A | B34: NZN2Z5XYY4M | C34: NZN2Z5XYY4M | D34: Male | E34: Himawan | F34: Brasali | G34: 60 | H34: Alicia Nguyen 1 | I34: Cathay Pacific | J34: CX 410 | K34: 13-thg 9-25 | L34: 0.58680556 | M34: ICN-T1 | N34: Cathay Pacific | O34: CX 411 | P34: 18-thg 9-25 | Q34: 0.63194444 | R34: ICN-T1 | S34: FAIRMONT | T34: Busan -> Incheon Airport train station, @ 18:00 | W34: 462710469 | X34: DOUBLE
A35: A | B35: W9NWGQ5DD7L | C35: NZN2Z5XYY4M | D35: Female | E35: Liliana Chandra | F35: Brasali | G35: 61 | H35: Alicia Nguyen 1 | I35: Cathay Pacific | J35: CX 410 | K35: 13-thg 9-25 | L35: 0.58680556 | M35: ICN-T1 | N35: Cathay Pacific | O35: CX 411 | P35: 18-thg 9-25 | Q35: 0.63194444 | R35: ICN-T1 | S35: FAIRMONT | T35: Busan -> Incheon Airport train station, @ 18:00 | W35: 462710469 | X35: DOUBLE
A36: A | B36: PYN6VPQG6T9 | C36: PYN6VPQG6T9 | D36: Female | E36: Shoufie Rusli | F36: Nakamura | G36: 64 | H36: Alicia Nguyen 1 | I36: United Airlines | J36: UA 893 | K36: 13-thg 9-25 | L36: 0.625 | M36: ICN-T1 | N36: Korean Air | O36: KE 627 | P36: 18-thg 9-25 | Q36: 0.63194444 | R36: ICN-T2 | S36: FAIRMONT | T36: Busan -> Incheon Airport train station, @ 18:00 | W36: 462710470 | X36: DOUBLE
A37: A | B37: 6NN3YPYWJMF | C37: PYN6VPQG6T9 | D37: Female | E37: Kennedydouglas | F37: Jean | G37: 70 | H37: Alicia Nguyen 1 | I37: Cathay Pacific | J37: CX 410 | K37: 13-thg 9-25 | L37: 0.58680556 | M37: ICN-T1 | N37: Cathay Pacific | O37: CX 411 | P37: 18-thg 9-25 | Q37: 0.63194444 | R37: ICN-T1 | S37: FAIRMONT | T37: Busan -> Incheon Airport train station, @ 18:00 | W37: 462710470 | X37: DOUBLE
A38: A | B38: BCNVYRX63CS | C38: BCNVYRX63CS | D38: Male | E38: Anhvu Tran | F38: Nguyen | G38: 34 | H38: Alicia Nguyen 1 | I38: Delta | J38: DL 173 | K38: 13-thg 9-25 | L38: 0.63888889 | M38: ICN-T2 | N38: Tigerair Taiwan | O38: IT 603 on 19 Sep | P38: 18-thg 9-25 | Q38: 0.94097222 | R38: ICN-T1 | S38: FAIRMONT | T38: depart on 19Sep, see-off on 18Sep @ 17:50, ICN-T1 | W38: 462710471 | X38: DOUBLE
A39: A | B39: B3NJRY93FX2 | C39: BCNVYRX63CS | D39: Female | E39: Ya Chen | F39: Chen | G39: 36 | H39: Alicia Nguyen 1 | I39: Delta | J39: DL 173 | K39: 13-thg 9-25 | L39: 0.63888889 | M39: ICN-T2 | N39: Tigerair Taiwan | O39: IT 603 on 19 Sep | P39: 18-thg 9-25 | Q39: 0.94097222 | R39: ICN-T1 | S39: FAIRMONT | T39: depart on 19Sep, see-off on 18Sep @ 17:50, ICN-T1 | W39: 462710471 | X39: DOUBLE
A40: A | B40: JQNQMVF25YP | C40: JQNQMVF25YP | D40: Male | E40: Brian Mercado | F40: Berdiago | G40: 34 | H40: Alicia Nguyen 1 | I40: United Airlines | J40: UA 805 | K40: 13-thg 9-25 | L40: 0.18055556 | M40: ICN-T1 | N40: United Airlines | O40: UA 892 | P40: 18-thg 9-25 | Q40: 0.70138889 | R40: ICN-T1 | S40: FAIRMONT | W40: 462710472 | X40: TWIN
A41: A | B41: CXNRJSK5PKF | C41: JQNQMVF25YP | D41: Male | E41: Alexis | F41: Camacho Sibrian | G41: 23 | H41: Alicia Nguyen 1 | I41: Asiana Airlines | J41: OZ 101 | K41: 13-thg 9-25 | L41: 0.65972222 | M41: ICN-T1 | N41: Asiana Airlines | O41: OZ 212 | P41: 18-thg 9-25 | Q41: 0.87152778 | R41: ICN-T1 | S41: FAIRMONT | W41: 462710472 | X41: TWIN
A42: A | B42: 95NN33GQCFZ | C42: 95NN33GQCFZ | D42: Male | E42: Daniel Gregory | F42: Chabino | G42: 54 | H42: Alicia Nguyen 1 | I42: Korean Air | J42: KE 5034 | K42: 13-thg 9-25 | L42: 0.72222222 | M42: ICN-T2 | N42: Philippine Airlines | O42: PR 485 | P42: 18-thg 9-25 | Q42: 0.28819444 | R42: ICN-T1 | S42: FAIRMONT | W42: 462710474 | X42: DOUBLE
A43: A | B43: D5NXLDNW5BB | C43: 95NN33GQCFZ | D43: Female | E43: Nheza Mirasol | F43: Samia | H43: Alicia Nguyen 1 | S43: FAIRMONT | W43: 462710474 | X43: DOUBLE
A44: A | B44: X7NFCHMYRSC | C44: X7NFCHMYRSC | D44: Male | E44: Gerald Cabatbat | F44: Pugal | G44: 40 | H44: Alicia Nguyen 1 | I44: Delta | J44: DL 197 | K44: 13-thg 9-25 | L44: 0.6875 | M44: ICN-T2 | N44: Delta | O44: DL 196 | P44: 18-thg 9-25 | Q44: 0.80555556 | R44: ICN-T2 | S44: FAIRMONT | W44: 462710475 | X44: DOUBLE
A45: A | B45: XMNGSK9RJW2 | C45: X7NFCHMYRSC | D45: Female | E45: Jennifermae Castillo | F45: Regacho | G45: 42 | H45: Alicia Nguyen 1 | I45: Korean Air | J45: KE 186 | K45: 13-thg 9-25 | L45: 0.70138889 | M45: ICN-T2 | N45: Delta | O45: DL 196 | P45: 18-thg 9-25 | Q45: 0.80555556 | R45: ICN-T2 | S45: FAIRMONT | W45: 462710475 | X45: DOUBLE
A46: A | B46: J3N99ML8RH3 | C46: J3N99ML8RH3 | D46: Male | E46: John Franco | F46: Quines | G46: 33 | H46: Alicia Nguyen 1 | I46: Asiana Airlines | J46: OZ 107 | K46: 13-thg 9-25 | L46: 0.47916667 | M46: ICN-T1 | N46: Asiana Airlines | O46: OZ 212 | P46: 18-thg 9-25 | Q46: 0.87152778 | R46: ICN-T1 | S46: FAIRMONT | W46: 462710476 | X46: DOUBLE
A47: A | B47: Z8NGNLRZ7TD | C47: J3N99ML8RH3 | D47: Male | E47: Kenneth | F47: Jung | G47: 24 | H47: Alicia Nguyen 1 | I47: Asiana Airlines | J47: OZ 107 | K47: 13-thg 9-25 | L47: 0.47916667 | M47: ICN-T1 | N47: Asiana Airlines | O47: OZ 212 | P47: 18-thg 9-25 | Q47: 0.87152778 | R47: ICN-T1 | S47: FAIRMONT | W47: 462710476 | X47: DOUBLE
A48: A | B48: QFN6T4JS4CP | C48: QFN6T4JS4CP | D48: Male | E48: Justin Kelly | F48: Mambaje | G48: 41 | H48: Alicia Nguyen 1 | I48: Asiana Airlines | J48: OZ 107 | K48: 13-thg 9-25 | L48: 0.47916667 | M48: ICN-T1 | N48: Asiana Airlines | O48: OZ 212 | P48: 18-thg 9-25 | Q48: 0.87152778 | R48: ICN-T1 | S48: FAIRMONT | T48: Upgrade - Signature Suite | W48: 462710727 | X48: DOUBLE
A49: A | B49: NJNXZSSPR99 | C49: QFN6T4JS4CP | D49: Female | E49: Maria Cecilia Lacap | F49: Mambaje | G49: 38 | H49: Alicia Nguyen 1 | I49: Asiana Airlines | J49: OZ 107 | K49: 13-thg 9-25 | L49: 0.47916667 | M49: ICN-T1 | N49: Asiana Airlines | O49: OZ 212 | P49: 18-thg 9-25 | Q49: 0.87152778 | R49: ICN-T1 | S49: FAIRMONT | W49: 462710727 | X49: DOUBLE
A50: A | B50: 7BNJ8DW86GS | C50: QFN6T4JS4CP | D50: Female | E50: Lily-Ann Lacap | F50: Mambaje | G50: 11 | H50: Alicia Nguyen 1 | I50: Asiana Airlines | J50: OZ 107 | K50: 13-thg 9-25 | L50: 0.47916667 | M50: ICN-T1 | N50: Asiana Airlines | O50: OZ 212 | P50: 18-thg 9-25 | Q50: 0.87152778 | R50: ICN-T1 | S50: FAIRMONT | W50: 462710727 | X50: DOUBLE
A51: A | B51: GHNKTHQG7VK | C51: QFN6T4JS4CP | D51: Female | E51: Amalia Lacap | F51: Mambaje | G51: 13 | H51: Alicia Nguyen 1 | I51: Asiana Airlines | J51: OZ 107 | K51: 13-thg 9-25 | L51: 0.47916667 | M51: ICN-T1 | N51: Asiana Airlines | O51: OZ 212 | P51: 18-thg 9-25 | Q51: 0.87152778 | R51: ICN-T1 | S51: FAIRMONT | W51: 462710728 | X51: DOUBLE
A52: A | B52: N7NJZY3WR94 | C52: QFN6T4JS4CP | D52: Female | E52: Ruth | F52: Gagarin | G52: 62 | H52: Alicia Nguyen 1 | I52: Asiana Airlines | J52: OZ 107 | K52: 13-thg 9-25 | L52: 0.47916667 | M52: ICN-T1 | N52: Asiana Airlines | O52: OZ 212 | P52: 18-thg 9-25 | Q52: 0.87152778 | R52: ICN-T1 | S52: FAIRMONT | W52: 462710728 | X52: DOUBLE
A53: A | B53: M4NTGBJQJY4 | C53: M4NTGBJQJY4 | D53: Male | E53: Lee Michael Castillo | F53: Montes | G53: 48 | H53: Alicia Nguyen 1 | I53: Asiana Airlines | J53: OZ 107 | K53: 13-thg 9-25 | L53: 0.47916667 | M53: ICN-T1 | N53: Asiana Airlines | O53: OZ 212 | P53: 18-thg 9-25 | Q53: 0.87152778 | R53: ICN-T1 | S53: FAIRMONT | W53: 462710729 | X53: DOUBLE
A54: A | B54: 4VNVY9GPZPW | C54: M4NTGBJQJY4 | D54: Female | E54: Trina Pacita | F54: Montes | G54: 45 | H54: Alicia Nguyen 1 | I54: Asiana Airlines | J54: OZ 107 | K54: 13-thg 9-25 | L54: 0.47916667 | M54: ICN-T1 | N54: Asiana Airlines | O54: OZ 212 | P54: 18-thg 9-25 | Q54: 0.87152778 | R54: ICN-T1 | S54: FAIRMONT | W54: 462710729 | X54: DOUBLE
A55: A | B55: JVNDQKFWDV5 | C55: M4NTGBJQJY4 | D55: Female | E55: Trinity Aleeya | F55: Montes | G55: 19 | H55: Alicia Nguyen 1 | I55: Asiana Airlines | J55: OZ 107 | K55: 13-thg 9-25 | L55: 0.47916667 | M55: ICN-T1 | N55: Asiana Airlines | O55: OZ 212 | P55: 18-thg 9-25 | Q55: 0.87152778 | R55: ICN-T1 | S55: FAIRMONT | W55: 462710730 | X55: TWIN
A56: A | B56: 45N3BSS6BDX | C56: M4NTGBJQJY4 | D56: Female | E56: Stephanie Montes | F56: Dumandan | G56: 46 | H56: Alicia Nguyen 1 | I56: Korean Air | J56: KE 24 | K56: 13-thg 9-25 | L56: 0.72222222 | M56: ICN-T2 | N56: Korean Air | O56: KE 23 | P56: 18-thg 9-25 | Q56: 0.66666667 | R56: ICN-T2 | S56: FAIRMONT | W56: 462710730 | X56: TWIN
A57: A | B57: SFNCLTQZ2HS | C57: M4NTGBJQJY4 | D57: Female | E57: Teresa Pacita | F57: Walsh | G57: 71 | H57: Alicia Nguyen 1 | I57: Asiana Airlines | J57: OZ 107 | K57: 13-thg 9-25 | L57: 0.47916667 | M57: ICN-T1 | N57: Asiana Airlines | O57: OZ 212 | P57: 18-thg 9-25 | Q57: 0.87152778 | R57: ICN-T1 | S57: FAIRMONT | W57: 462710731 | X57: TWIN
A58: A | B58: S6NKVSF3B3K | C58: M4NTGBJQJY4 | D58: Male | E58: Mason Lee | F58: Montes | G58: 13 | H58: Alicia Nguyen 1 | I58: Asiana Airlines | J58: OZ 107 | K58: 13-thg 9-25 | L58: 0.47916667 | M58: ICN-T1 | N58: Asiana Airlines | O58: OZ 212 | P58: 18-thg 9-25 | Q58: 0.87152778 | R58: ICN-T1 | S58: FAIRMONT | W58: 462710731 | X58: TWIN
...

Sheet A.Arr9sepList
A1: Group | B1: Confirmation | C1: Primary registrant | D1: Gender | E1: First Name | F1: Last Name | G1: Age | H1: CEO | I1: A.Airline | J1: A.Flt | K1: A.Date | L1: A.Time | M1: A.Airport | N1: Hotel | O1: TOTAL PAX EACH GROUPING | P1: SHUTTLE TIME | Q1: Hotel confirmation no. | R1: Bedding type | S1: REMARKS
A2: GIMPO - DOMESTIC & INTERNATIONAL
A3: {=INDEX(manifest_11Sep!$A$1:$V$3202,MATCH($B3,manifest_11Sep!$B$1:$B$3202,0),MATCH(A.Arr9sepList!A$1,manifest_11Sep!$A$1:$V$1,0))} -> A | B3: TKNTFR2VQ5P | C3: {=INDEX(manifest_11Sep!$A$1:$V$3202,MATCH($B3,manifest_11Sep!$B$1:$B$3202,0),MATCH(A.Arr9sepList!C$1,manifest_11Sep!$A$1:$V$1,0))} -> TKNTFR2VQ5P | D3: {=INDEX(manifest_11Sep!$A$1:$V$3202,MATCH($B3,manifest_11Sep!$B$1:$B$3202,0),MATCH(A.Arr9sepList!D$1,manifest_11Sep!$A$1:$V$1,0))} -> Male | E3: {=INDEX(manifest_11Sep!$A$1:$V$3202,MATCH($B3,manifest_11Sep!$B$1:$B$3202,0),MATCH(A.Arr9sepList!E$1,manifest_11Sep!$A$1:$V$1,0))} -> Jesus Equila | F3: {=INDEX(manifest_11Sep!$A$1:$V$3202,MATCH($B3,manifest_11Sep!$B$1:$B$3202,0),MATCH(A.Arr9sepList!F$1,manifest_11Sep!$A$1:$V$1,0))} -> Asuncion Jr | G3: {=INDEX(manifest_11Sep!$A$1:$V$3202,MATCH($B3,manifest_11Sep!$B$1:$B$3202,0),MATCH(A.Arr9sepList!G$1,manifest_11Sep!$A$1:$V$1,0))} -> 42 | H3: {=INDEX(manifest_11Sep!$A$1:$V$3202,MATCH($B3,manifest_11Sep!$B$1:$B$3202,0),MATCH(A.Arr9sepList!H$1,manifest_11Sep!$A$1:$V$1,0))} -> Dondon Dimailig | I3: {=INDEX(manifest_11Sep!$A$1:$V$3202,MATCH($B3,manifest_11Sep!$B$1:$B$3202,0),MATCH(A.Arr9sepList!I$1,manifest_11Sep!$A$1:$V$1,0))} -> Korean Air | J3: {=INDEX(manifest_11Sep!$A$1:$V$3202,MATCH($B3,manifest_11Sep!$B$1:$B$3202,0),MATCH(A.Arr9sepList!J$1,manifest_11Sep!$A$1:$V$1,0))} -> KE 5214 | ... N3: {=INDEX(manifest_11Sep!$A$1:$V$3202,MATCH($B3,manifest_11Sep!$B$1:$B$3202,0),MATCH(A.Arr9sepList!N$1,manifest_11Sep!$A$1:$V$1,0))} -> LOTTE | O3: =COUNTA(N3:N8) -> 6 | Q3: 15262385 | R3: DOUBLE | S3: {=INDEX(manifest_11Sep!$A$1:$V$3202,MATCH($B3,manifest_11Sep!$B$1:$B$3202,0),MATCH(A.Arr9sepList!S$1,manifest_11Sep!$A$1:$V$1,0))} -> 0
A4: {=INDEX(manifest_11Sep!$A$1:$V$3202,MATCH($B4,manifest_11Sep!$B$1:$B$3202,0),MATCH(A.Arr9sepList!A$1,manifest_11Sep!$A$1:$V$1,0))} -> A | B4: 2RN8DQFMK3Q | C4: {=INDEX(manifest_11Sep!$A$1:$V$3202,MATCH($B4,manifest_11Sep!$B$1:$B$3202,0),MATCH(A.Arr9sepList!C$1,manifest_11Sep!$A$1:$V$1,0))} -> BNN7YW76R4V | D4: {=INDEX(manifest_11Sep!$A$1:$V$3202,MATCH($B4,manifest_11Sep!$B$1:$B$3202,0),MATCH(A.Arr9sepList!D$1,manifest_11Sep!$A$1:$V$1,0))} -> Female | E4: {=INDEX(manifest_11Sep!$A$1:$V$3202,MATCH($B4,manifest_11Sep!$B$1:$B$3202,0),MATCH(A.Arr9sepList!E$1,manifest_11Sep!$A$1:$V$1,0))} -> Florencia Amacna | F4: {=INDEX(manifest_11Sep!$A$1:$V$3202,MATCH($B4,manifest_11Sep!$B$1:$B$3202,0),MATCH(A.Arr9sepList!F$1,manifest_11Sep!$A$1:$V$1,0))} -> Griffin | G4: {=INDEX(manifest_11Sep!$A$1:$V$3202,MATCH($B4,manifest_11Sep!$B$1:$B$3202,0),MATCH(A.Arr9sepList!G$1,manifest_11Sep!$A$1:$V$1,0))} -> 55 | H4: {=INDEX(manifest_11Sep!$A$1:$V$3202,MATCH($B4,manifest_11Sep!$B$1:$B$3202,0),MATCH(A.Arr9sepList!H$1,manifest_11Sep!$A$1:$V$1,0))} -> Dondon Dimailig | I4: {=INDEX(manifest_11Sep!$A$1:$V$3202,MATCH($B4,manifest_11Sep!$B$1:$B$3202,0),MATCH(A.Arr9sepList!I$1,manifest_11Sep!$A$1:$V$1,0))} -> Korean Air | J4: {=INDEX(manifest_11Sep!$A$1:$V$3202,MATCH($B4,manifest_11Sep!$B$1:$B$3202,0),MATCH(A.Arr9sepList!J$1,manifest_11Sep!$A$1:$V$1,0))} -> KE 5214 | ... N4: {=INDEX(manifest_11Sep!$A$1:$V$3202,MATCH($B4,manifest_11Sep!$B$1:$B$3202,0),MATCH(A.Arr9sepList!N$1,manifest_11Sep!$A$1:$V$1,0))} -> LOTTE | Q4: 15262388 | R4: TWIN | S4: {=INDEX(manifest_11Sep!$A$1:$V$3202,MATCH($B4,manifest_11Sep!$B$1:$B$3202,0),MATCH(A.Arr9sepList!S$1,manifest_11Sep!$A$1:$V$1,0))} -> 0
A5: {=INDEX(manifest_11Sep!$A$1:$V$3202,MATCH($B5,manifest_11Sep!$B$1:$B$3202,0),MATCH(A.Arr9sepList!A$1,manifest_11Sep!$A$1:$V$1,0))} -> A | B5: 4CNS4TKSHJ7 | C5: {=INDEX(manifest_11Sep!$A$1:$V$3202,MATCH($B5,manifest_11Sep!$B$1:$B$3202,0),MATCH(A.Arr9sepList!C$1,manifest_11Sep!$A$1:$V$1,0))} -> 4CNS4TKSHJ7 | D5: {=INDEX(manifest_11Sep!$A$1:$V$3202,MATCH($B5,manifest_11Sep!$B$1:$B$3202,0),MATCH(A.Arr9sepList!D$1,manifest_11Sep!$A$1:$V$1,0))} -> Female | E5: {=INDEX(manifest_11Sep!$A$1:$V$3202,MATCH($B5,manifest_11Sep!$B$1:$B$3202,0),MATCH(A.Arr9sepList!E$1,manifest_11Sep!$A$1:$V$1,0))} -> Olajumoke Sherifat | F5: {=INDEX(manifest_11Sep!$A$1:$V$3202,MATCH($B5,manifest_11Sep!$B$1:$B$3202,0),MATCH(A.Arr9sepList!F$1,manifest_11Sep!$A$1:$V$1,0))} -> Seriki | G5: {=INDEX(manifest_11Sep!$A$1:$V$3202,MATCH($B5,manifest_11Sep!$B$1:$B$3202,0),MATCH(A.Arr9sepList!G$1,manifest_11Sep!$A$1:$V$1,0))} -> 59 | H5: {=INDEX(manifest_11Sep!$A$1:$V$3202,MATCH($B5,manifest_11Sep!$B$1:$B$3202,0),MATCH(A.Arr9sepList!H$1,manifest_11Sep!$A$1:$V$1,0))} -> Olajumoke Seriki | I5: {=INDEX(manifest_11Sep!$A$1:$V$3202,MATCH($B5,manifest_11Sep!$B$1:$B$3202,0),MATCH(A.Arr9sepList!I$1,manifest_11Sep!$A$1:$V$1,0))} -> Jeju Air | J5: {=INDEX(manifest_11Sep!$A$1:$V$3202,MATCH($B5,manifest_11Sep!$B$1:$B$3202,0),MATCH(A.Arr9sepList!J$1,manifest_11Sep!$A$1:$V$1,0))} -> 7C 106 | ... N5: {=INDEX(manifest_11Sep!$A$1:$V$3202,MATCH($B5,manifest_11Sep!$B$1:$B$3202,0),MATCH(A.Arr9sepList!N$1,manifest_11Sep!$A$1:$V$1,0))} -> LOTTE | Q5: 15262464 | R5: DOUBLE | S5: {=INDEX(manifest_11Sep!$A$1:$V$3202,MATCH($B5,manifest_11Sep!$B$1:$B$3202,0),MATCH(A.Arr9sepList!S$1,manifest_11Sep!$A$1:$V$1,0))} -> 0
A6: {=INDEX(manifest_11Sep!$A$1:$V$3202,MATCH($B6,manifest_11Sep!$B$1:$B$3202,0),MATCH(A.Arr9sepList!A$1,manifest_11Sep!$A$1:$V$1,0))} -> A | B6: 3QNKCBGWBR2 | C6: {=INDEX(manifest_11Sep!$A$1:$V$3202,MATCH($B6,manifest_11Sep!$B$1:$B$3202,0),MATCH(A.Arr9sepList!C$1,manifest_11Sep!$A$1:$V$1,0))} -> 4CNS4TKSHJ7 | D6: {=INDEX(manifest_11Sep!$A$1:$V$3202,MATCH($B6,manifest_11Sep!$B$1:$B$3202,0),MATCH(A.Arr9sepList!D$1,manifest_11Sep!$A$1:$V$1,0))} -> Male | E6: {=INDEX(manifest_11Sep!$A$1:$V$3202,MATCH($B6,manifest_11Sep!$B$1:$B$3202,0),MATCH(A.Arr9sepList!E$1,manifest_11Sep!$A$1:$V$1,0))} -> Waheed Akanni | F6: {=INDEX(manifest_11Sep!$A$1:$V$3202,MATCH($B6,manifest_11Sep!$B$1:$B$3202,0),MATCH(A.Arr9sepList!F$1,manifest_11Sep!$A$1:$V$1,0))} -> Seriki | G6: {=INDEX(manifest_11Sep!$A$1:$V$3202,MATCH($B6,manifest_11Sep!$B$1:$B$3202,0),MATCH(A.Arr9sepList!G$1,manifest_11Sep!$A$1:$V$1,0))} -> 61 | H6: {=INDEX(manifest_11Sep!$A$1:$V$3202,MATCH($B6,manifest_11Sep!$B$1:$B$3202,0),MATCH(A.Arr9sepList!H$1,manifest_11Sep!$A$1:$V$1,0))} -> Olajumoke Seriki | I6: {=INDEX(manifest_11Sep!$A$1:$V$3202,MATCH($B6,manifest_11Sep!$B$1:$B$3202,0),MATCH(A.Arr9sepList!I$1,manifest_11Sep!$A$1:$V$1,0))} -> Jeju Air | J6: {=INDEX(manifest_11Sep!$A$1:$V$3202,MATCH($B6,manifest_11Sep!$B$1:$B$3202,0),MATCH(A.Arr9sepList!J$1,manifest_11Sep!$A$1:$V$1,0))} -> 7C 106 | ... N6: {=INDEX(manifest_11Sep!$A$1:$V$3202,MATCH($B6,manifest_11Sep!$B$1:$B$3202,0),MATCH(A.Arr9sepList!N$1,manifest_11Sep!$A$1:$V$1,0))} -> LOTTE | Q6: 15262464 | R6: DOUBLE | S6: {=INDEX(manifest_11Sep!$A$1:$V$3202,MATCH($B6,manifest_11Sep!$B$1:$B$3202,0),MATCH(A.Arr9sepList!S$1,manifest_11Sep!$A$1:$V$1,0))} -> 0
A7: {=INDEX(manifest_11Sep!$A$1:$V$3202,MATCH($B7,manifest_11Sep!$B$1:$B$3202,0),MATCH(A.Arr9sepList!A$1,manifest_11Sep!$A$1:$V$1,0))} -> A | B7: TXNC5MZFN98 | C7: {=INDEX(manifest_11Sep!$A$1:$V$3202,MATCH($B7,manifest_11Sep!$B$1:$B$3202,0),MATCH(A.Arr9sepList!C$1,manifest_11Sep!$A$1:$V$1,0))} -> TXNC5MZFN98 | D7: {=INDEX(manifest_11Sep!$A$1:$V$3202,MATCH($B7,manifest_11Sep!$B$1:$B$3202,0),MATCH(A.Arr9sepList!D$1,manifest_11Sep!$A$1:$V$1,0))} -> Female | E7: {=INDEX(manifest_11Sep!$A$1:$V$3202,MATCH($B7,manifest_11Sep!$B$1:$B$3202,0),MATCH(A.Arr9sepList!E$1,manifest_11Sep!$A$1:$V$1,0))} -> Maria Jan Luv Santos | F7: {=INDEX(manifest_11Sep!$A$1:$V$3202,MATCH($B7,manifest_11Sep!$B$1:$B$3202,0),MATCH(A.Arr9sepList!F$1,manifest_11Sep!$A$1:$V$1,0))} -> Lagasca Borja | G7: {=INDEX(manifest_11Sep!$A$1:$V$3202,MATCH($B7,manifest_11Sep!$B$1:$B$3202,0),MATCH(A.Arr9sepList!G$1,manifest_11Sep!$A$1:$V$1,0))} -> 53 | H7: {=INDEX(manifest_11Sep!$A$1:$V$3202,MATCH($B7,manifest_11Sep!$B$1:$B$3202,0),MATCH(A.Arr9sepList!H$1,manifest_11Sep!$A$1:$V$1,0))} -> Joen De Las Penas | I7: {=INDEX(manifest_11Sep!$A$1:$V$3202,MATCH($B7,manifest_11Sep!$B$1:$B$3202,0),MATCH(A.Arr9sepList!I$1,manifest_11Sep!$A$1:$V$1,0))} -> Jeju Air | J7: {=INDEX(manifest_11Sep!$A$1:$V$3202,MATCH($B7,manifest_11Sep!$B$1:$B$3202,0),MATCH(A.Arr9sepList!J$1,manifest_11Sep!$A$1:$V$1,0))} -> 7C 1328 ON 12 SEP | ... N7: {=INDEX(manifest_11Sep!$A$1:$V$3202,MATCH($B7,manifest_11Sep!$B$1:$B$3202,0),MATCH(A.Arr9sepList!N$1,manifest_11Sep!$A$1:$V$1,0))} -> FAIRMONT | Q7: 462710820 | R7: DOUBLE | S7: {=INDEX(manifest_11Sep!$A$1:$V$3202,MATCH($B7,manifest_11Sep!$B$1:$B$3202,0),MATCH(A.Arr9sepList!S$1,manifest_11Sep!$A$1:$V$1,0))} -> arrive 12Sep - GMP, pick-up on 13Sep @ 11:30, GMP-D
A8: {=INDEX(manifest_11Sep!$A$1:$V$3202,MATCH($B8,manifest_11Sep!$B$1:$B$3202,0),MATCH(A.Arr9sepList!A$1,manifest_11Sep!$A$1:$V$1,0))} -> A | B8: 9NN3PLSWKD5 | C8: {=INDEX(manifest_11Sep!$A$1:$V$3202,MATCH($B8,manifest_11Sep!$B$1:$B$3202,0),MATCH(A.Arr9sepList!C$1,manifest_11Sep!$A$1:$V$1,0))} -> TXNC5MZFN98 | D8: {=INDEX(manifest_11Sep!$A$1:$V$3202,MATCH($B8,manifest_11Sep!$B$1:$B$3202,0),MATCH(A.Arr9sepList!D$1,manifest_11Sep!$A$1:$V$1,0))} -> Male | E8: {=INDEX(manifest_11Sep!$A$1:$V$3202,MATCH($B8,manifest_11Sep!$B$1:$B$3202,0),MATCH(A.Arr9sepList!E$1,manifest_11Sep!$A$1:$V$1,0))} -> Amado James Boco | F8: {=INDEX(manifest_11Sep!$A$1:$V$3202,MATCH($B8,manifest_11Sep!$B$1:$B$3202,0),MATCH(A.Arr9sepList!F$1,manifest_11Sep!$A$1:$V$1,0))} -> Borja | G8: {=INDEX(manifest_11Sep!$A$1:$V$3202,MATCH($B8,manifest_11Sep!$B$1:$B$3202,0),MATCH(A.Arr9sepList!G$1,manifest_11Sep!$A$1:$V$1,0))} -> 54 | H8: {=INDEX(manifest_11Sep!$A$1:$V$3202,MATCH($B8,manifest_11Sep!$B$1:$B$3202,0),MATCH(A.Arr9sepList!H$1,manifest_11Sep!$A$1:$V$1,0))} -> Joen De Las Penas | I8: {=INDEX(manifest_11Sep!$A$1:$V$3202,MATCH($B8,manifest_11Sep!$B$1:$B$3202,0),MATCH(A.Arr9sepList!I$1,manifest_11Sep!$A$1:$V$1,0))} -> Jeju Air | J8: {=INDEX(manifest_11Sep!$A$1:$V$3202,MATCH($B8,manifest_11Sep!$B$1:$B$3202,0),MATCH(A.Arr9sepList!J$1,manifest_11Sep!$A$1:$V$1,0))} -> 7C 1328 ON 12 SEP | ... N8: {=INDEX(manifest_11Sep!$A$1:$V$3202,MATCH($B8,manifest_11Sep!$B$1:$B$3202,0),MATCH(A.Arr9sepList!N$1,manifest_11Sep!$A$1:$V$1,0))} -> FAIRMONT | Q8: 462710820 | R8: DOUBLE | S8: {=INDEX(manifest_11Sep!$A$1:$V$3202,MATCH($B8,manifest_11Sep!$B$1:$B$3202,0),MATCH(A.Arr9sepList!S$1,manifest_11Sep!$A$1:$V$1,0))} -> arrive 12Sep - GMP, pick-up on 13Sep @ 11:30, GMP-D
A9: {=INDEX(manifest_11Sep!$A$1:$V$3202,MATCH($B9,manifest_11Sep!$B$1:$B$3202,0),MATCH(A.Arr9sepList!A$1,manifest_11Sep!$A$1:$V$1,0))} -> A | B9: MXN8BWBJK8T | C9: {=INDEX(manifest_11Sep!$A$1:$V$3202,MATCH($B9,manifest_11Sep!$B$1:$B$3202,0),MATCH(A.Arr9sepList!C$1,manifest_11Sep!$A$1:$V$1,0))} -> MXN8BWBJK8T | D9: {=INDEX(manifest_11Sep!$A$1:$V$3202,MATCH($B9,manifest_11Sep!$B$1:$B$3202,0),MATCH(A.Arr9sepList!D$1,manifest_11Sep!$A$1:$V$1,0))} -> Male | E9: {=INDEX(manifest_11Sep!$A$1:$V$3202,MATCH($B9,manifest_11Sep!$B$1:$B$3202,0),MATCH(A.Arr9sepList!E$1,manifest_11Sep!$A$1:$V$1,0))} -> Siu Yu | F9: {=INDEX(manifest_11Sep!$A$1:$V$3202,MATCH($B9,manifest_11Sep!$B$1:$B$3202,0),MATCH(A.Arr9sepList!F$1,manifest_11Sep!$A$1:$V$1,0))} -> Lee | G9: {=INDEX(manifest_11Sep!$A$1:$V$3202,MATCH($B9,manifest_11Sep!$B$1:$B$3202,0),MATCH(A.Arr9sepList!G$1,manifest_11Sep!$A$1:$V$1,0))} -> 59 | H9: {=INDEX(manifest_11Sep!$A$1:$V$3202,MATCH($B9,manifest_11Sep!$B$1:$B$3202,0),MATCH(A.Arr9sepList!H$1,manifest_11Sep!$A$1:$V$1,0))} -> Lisa Oktavia | I9: {=INDEX(manifest_11Sep!$A$1:$V$3202,MATCH($B9,manifest_11Sep!$B$1:$B$3202,0),MATCH(A.Arr9sepList!I$1,manifest_11Sep!$A$1:$V$1,0))} -> Korean Air | J9: {=INDEX(manifest_11Sep!$A$1:$V$3202,MATCH($B9,manifest_11Sep!$B$1:$B$3202,0),MATCH(A.Arr9sepList!J$1,manifest_11Sep!$A$1:$V$1,0))} -> KE 1174 | ... N9: {=INDEX(manifest_11Sep!$A$1:$V$3202,MATCH($B9,manifest_11Sep!$B$1:$B$3202,0),MATCH(A.Arr9sepList!N$1,manifest_11Sep!$A$1:$V$1,0))} -> JW MARRIOTT | O9: =COUNTA(N9) -> 1 | Q9: 75989141 | R9: SINGLE | S9: {=INDEX(manifest_11Sep!$A$1:$V$3202,MATCH($B9,manifest_11Sep!$B$1:$B$3202,0),MATCH(A.Arr9sepList!S$1,manifest_11Sep!$A$1:$V$1,0))} -> 0
A10: {=INDEX(manifest_11Sep!$A$1:$V$3202,MATCH($B10,manifest_11Sep!$B$1:$B$3202,0),MATCH(A.Arr9sepList!A$1,manifest_11Sep!$A$1:$V$1,0))} -> A | B10: 7JN92SVFBXK | C10: {=INDEX(manifest_11Sep!$A$1:$V$3202,MATCH($B10,manifest_11Sep!$B$1:$B$3202,0),MATCH(A.Arr9sepList!C$1,manifest_11Sep!$A$1:$V$1,0))} -> 7JN92SVFBXK | D10: {=INDEX(manifest_11Sep!$A$1:$V$3202,MATCH($B10,manifest_11Sep!$B$1:$B$3202,0),MATCH(A.Arr9sepList!D$1,manifest_11Sep!$A$1:$V$1,0))} -> Male | E10: {=INDEX(manifest_11Sep!$A$1:$V$3202,MATCH($B10,manifest_11Sep!$B$1:$B$3202,0),MATCH(A.Arr9sepList!E$1,manifest_11Sep!$A$1:$V$1,0))} -> Justin Douglas | F10: {=INDEX(manifest_11Sep!$A$1:$V$3202,MATCH($B10,manifest_11Sep!$B$1:$B$3202,0),MATCH(A.Arr9sepList!F$1,manifest_11Sep!$A$1:$V$1,0))} -> Yee | G10: {=INDEX(manifest_11Sep!$A$1:$V$3202,MATCH($B10,manifest_11Sep!$B$1:$B$3202,0),MATCH(A.Arr9sepList!G$1,manifest_11Sep!$A$1:$V$1,0))} -> 44 | H10: {=INDEX(manifest_11Sep!$A$1:$V$3202,MATCH($B10,manifest_11Sep!$B$1:$B$3202,0),MATCH(A.Arr9sepList!H$1,manifest_11Sep!$A$1:$V$1,0))} -> Alicia Nguyen 3 | I10: {=INDEX(manifest_11Sep!$A$1:$V$3202,MATCH($B10,manifest_11Sep!$B$1:$B$3202,0),MATCH(A.Arr9sepList!I$1,manifest_11Sep!$A$1:$V$1,0))} -> Asiana Airlines | J10: {=INDEX(manifest_11Sep!$A$1:$V$3202,MATCH($B10,manifest_11Sep!$B$1:$B$3202,0),MATCH(A.Arr9sepList!J$1,manifest_11Sep!$A$1:$V$1,0))} -> OZ 1135 | ... N10: {=INDEX(manifest_11Sep!$A$1:$V$3202,MATCH($B10,manifest_11Sep!$B$1:$B$3202,0),MATCH(A.Arr9sepList!N$1,manifest_11Sep!$A$1:$V$1,0))} -> JW MARRIOTT | O10: =COUNTA(N10:N17) -> 8 | Q10: 75985339 | R10: DOUBLE | S10: {=INDEX(manifest_11Sep!$A$1:$V$3202,MATCH($B10,manifest_11Sep!$B$1:$B$3202,0),MATCH(A.Arr9sepList!S$1,manifest_11Sep!$A$1:$V$1,0))} -> Rooming: next door with DMN6ZNXS4TH + YWN37HR2SQL (dad & mom of Justin Yee & the daughter Elisa Ha Yee - SPNYHGY9GJG)
A11: {=INDEX(manifest_11Sep!$A$1:$V$3202,MATCH($B11,manifest_11Sep!$B$1:$B$3202,0),MATCH(A.Arr9sepList!A$1,manifest_11Sep!$A$1:$V$1,0))} -> A | B11: 3PNSTRBJCNL | C11: {=INDEX(manifest_11Sep!$A$1:$V$3202,MATCH($B11,manifest_11Sep!$B$1:$B$3202,0),MATCH(A.Arr9sepList!C$1,manifest_11Sep!$A$1:$V$1,0))} -> 7JN92SVFBXK | D11: {=INDEX(manifest_11Sep!$A$1:$V$3202,MATCH($B11,manifest_11Sep!$B$1:$B$3202,0),MATCH(A.Arr9sepList!D$1,manifest_11Sep!$A$1:$V$1,0))} -> Female | E11: {=INDEX(manifest_11Sep!$A$1:$V$3202,MATCH($B11,manifest_11Sep!$B$1:$B$3202,0),MATCH(A.Arr9sepList!E$1,manifest_11Sep!$A$1:$V$1,0))} -> Phoebe Ha-Thanh | F11: {=INDEX(manifest_11Sep!$A$1:$V$3202,MATCH($B11,manifest_11Sep!$B$1:$B$3202,0),MATCH(A.Arr9sepList!F$1,manifest_11Sep!$A$1:$V$1,0))} -> Nguyen | G11: {=INDEX(manifest_11Sep!$A$1:$V$3202,MATCH($B11,manifest_11Sep!$B$1:$B$3202,0),MATCH(A.Arr9sepList!G$1,manifest_11Sep!$A$1:$V$1,0))} -> 41 | H11: {=INDEX(manifest_11Sep!$A$1:$V$3202,MATCH($B11,manifest_11Sep!$B$1:$B$3202,0),MATCH(A.Arr9sepList!H$1,manifest_11Sep!$A$1:$V$1,0))} -> Alicia Nguyen 3 | I11: {=INDEX(manifest_11Sep!$A$1:$V$3202,MATCH($B11,manifest_11Sep!$B$1:$B$3202,0),MATCH(A.Arr9sepList!I$1,manifest_11Sep!$A$1:$V$1,0))} -> Asiana Airlines | J11: {=INDEX(manifest_11Sep!$A$1:$V$3202,MATCH($B11,manifest_11Sep!$B$1:$B$3202,0),MATCH(A.Arr9sepList!J$1,manifest_11Sep!$A$1:$V$1,0))} -> OZ 1135 | ... N11: {=INDEX(manifest_11Sep!$A$1:$V$3202,MATCH($B11,manifest_11Sep!$B$1:$B$3202,0),MATCH(A.Arr9sepList!N$1,manifest_11Sep!$A$1:$V$1,0))} -> JW MARRIOTT | Q11: 75985339 | R11: DOUBLE | S11: {=INDEX(manifest_11Sep!$A$1:$V$3202,MATCH($B11,manifest_11Sep!$B$1:$B$3202,0),MATCH(A.Arr9sepList!S$1,manifest_11Sep!$A$1:$V$1,0))} -> 0
A12: {=INDEX(manifest_11Sep!$A$1:$V$3202,MATCH($B12,manifest_11Sep!$B$1:$B$3202,0),MATCH(A.Arr9sepList!A$1,manifest_11Sep!$A$1:$V$1,0))} -> A | B12: PYNQTJPDF5Z | C12: {=INDEX(manifest_11Sep!$A$1:$V$3202,MATCH($B12,manifest_11Sep!$B$1:$B$3202,0),MATCH(A.Arr9sepList!C$1,manifest_11Sep!$A$1:$V$1,0))} -> 7JN92SVFBXK | D12: {=INDEX(manifest_11Sep!$A$1:$V$3202,MATCH($B12,manifest_11Sep!$B$1:$B$3202,0),MATCH(A.Arr9sepList!D$1,manifest_11Sep!$A$1:$V$1,0))} -> Female | E12: {=INDEX(manifest_11Sep!$A$1:$V$3202,MATCH($B12,manifest_11Sep!$B$1:$B$3202,0),MATCH(A.Arr9sepList!E$1,manifest_11Sep!$A$1:$V$1,0))} -> Amelia Ha | F12: {=INDEX(manifest_11Sep!$A$1:$V$3202,MATCH($B12,manifest_11Sep!$B$1:$B$3202,0),MATCH(A.Arr9sepList!F$1,manifest_11Sep!$A$1:$V$1,0))} -> Yee | G12: {=INDEX(manifest_11Sep!$A$1:$V$3202,MATCH($B12,manifest_11Sep!$B$1:$B$3202,0),MATCH(A.Arr9sepList!G$1,manifest_11Sep!$A$1:$V$1,0))} -> 9 | H12: {=INDEX(manifest_11Sep!$A$1:$V$3202,MATCH($B12,manifest_11Sep!$B$1:$B$3202,0),MATCH(A.Arr9sepList!H$1,manifest_11Sep!$A$1:$V$1,0))} -> Alicia Nguyen 3 | I12: {=INDEX(manifest_11Sep!$A$1:$V$3202,MATCH($B12,manifest_11Sep!$B$1:$B$3202,0),MATCH(A.Arr9sepList!I$1,manifest_11Sep!$A$1:$V$1,0))} -> Asiana Airlines | J12: {=INDEX(manifest_11Sep!$A$1:$V$3202,MATCH($B12,manifest_11Sep!$B$1:$B$3202,0),MATCH(A.Arr9sepList!J$1,manifest_11Sep!$A$1:$V$1,0))} -> OZ 1135 | ... N12: {=INDEX(manifest_11Sep!$A$1:$V$3202,MATCH($B12,manifest_11Sep!$B$1:$B$3202,0),MATCH(A.Arr9sepList!N$1,manifest_11Sep!$A$1:$V$1,0))} -> JW MARRIOTT | Q12: 75985339 | R12: DOUBLE | S12: {=INDEX(manifest_11Sep!$A$1:$V$3202,MATCH($B12,manifest_11Sep!$B$1:$B$3202,0),MATCH(A.Arr9sepList!S$1,manifest_11Sep!$A$1:$V$1,0))} -> 0
A13: {=INDEX(manifest_11Sep!$A$1:$V$3202,MATCH($B13,manifest_11Sep!$B$1:$B$3202,0),MATCH(A.Arr9sepList!A$1,manifest_11Sep!$A$1:$V$1,0))} -> A | B13: DMN6ZNXS4TH | C13: {=INDEX(manifest_11Sep!$A$1:$V$3202,MATCH($B13,manifest_11Sep!$B$1:$B$3202,0),MATCH(A.Arr9sepList!C$1,manifest_11Sep!$A$1:$V$1,0))} -> DMN6ZNXS4TH | D13: {=INDEX(manifest_11Sep!$A$1:$V$3202,MATCH($B13,manifest_11Sep!$B$1:$B$3202,0),MATCH(A.Arr9sepList!D$1,manifest_11Sep!$A$1:$V$1,0))} -> Male | E13: {=INDEX(manifest_11Sep!$A$1:$V$3202,MATCH($B13,manifest_11Sep!$B$1:$B$3202,0),MATCH(A.Arr9sepList!E$1,manifest_11Sep!$A$1:$V$1,0))} -> Kent J | F13: {=INDEX(manifest_11Sep!$A$1:$V$3202,MATCH($B13,manifest_11Sep!$B$1:$B$3202,0),MATCH(A.Arr9sepList!F$1,manifest_11Sep!$A$1:$V$1,0))} -> Yee | G13: {=INDEX(manifest_11Sep!$A$1:$V$3202,MATCH($B13,manifest_11Sep!$B$1:$B$3202,0),MATCH(A.Arr9sepList!G$1,manifest_11Sep!$A$1:$V$1,0))} -> 74 | H13: {=INDEX(manifest_11Sep!$A$1:$V$3202,MATCH($B13,manifest_11Sep!$B$1:$B$3202,0),MATCH(A.Arr9sepList!H$1,manifest_11Sep!$A$1:$V$1,0))} -> Alicia Nguyen 3 | I13: {=INDEX(manifest_11Sep!$A$1:$V$3202,MATCH($B13,manifest_11Sep!$B$1:$B$3202,0),MATCH(A.Arr9sepList!I$1,manifest_11Sep!$A$1:$V$1,0))} -> Asiana Airlines | J13: {=INDEX(manifest_11Sep!$A$1:$V$3202,MATCH($B13,manifest_11Sep!$B$1:$B$3202,0),MATCH(A.Arr9sepList!J$1,manifest_11Sep!$A$1:$V$1,0))} -> OZ 1135 | ... N13: {=INDEX(manifest_11Sep!$A$1:$V$3202,MATCH($B13,manifest_11Sep!$B$1:$B$3202,0),MATCH(A.Arr9sepList!N$1,manifest_11Sep!$A$1:$V$1,0))} -> JW MARRIOTT | Q13: 75985357 | R13: DOUBLE | S13: {=INDEX(manifest_11Sep!$A$1:$V$3202,MATCH($B13,manifest_11Sep!$B$1:$B$3202,0),MATCH(A.Arr9sepList!S$1,manifest_11Sep!$A$1:$V$1,0))} -> Rooming: Mom & Dad of Justin Yee - 7JN92SVFBXK
A14: {=INDEX(manifest_11Sep!$A$1:$V$3202,MATCH($B14,manifest_11Sep!$B$1:$B$3202,0),MATCH(A.Arr9sepList!A$1,manifest_11Sep!$A$1:$V$1,0))} -> A | B14: CFN78HK3C5B | C14: {=INDEX(manifest_11Sep!$A$1:$V$3202,MATCH($B14,manifest_11Sep!$B$1:$B$3202,0),MATCH(A.Arr9sepList!C$1,manifest_11Sep!$A$1:$V$1,0))} -> DMN6ZNXS4TH | D14: {=INDEX(manifest_11Sep!$A$1:$V$3202,MATCH($B14,manifest_11Sep!$B$1:$B$3202,0),MATCH(A.Arr9sepList!D$1,manifest_11Sep!$A$1:$V$1,0))} -> Female | E14: {=INDEX(manifest_11Sep!$A$1:$V$3202,MATCH($B14,manifest_11Sep!$B$1:$B$3202,0),MATCH(A.Arr9sepList!E$1,manifest_11Sep!$A$1:$V$1,0))} -> Betty N | F14: {=INDEX(manifest_11Sep!$A$1:$V$3202,MATCH($B14,manifest_11Sep!$B$1:$B$3202,0),MATCH(A.Arr9sepList!F$1,manifest_11Sep!$A$1:$V$1,0))} -> Yee | G14: {=INDEX(manifest_11Sep!$A$1:$V$3202,MATCH($B14,manifest_11Sep!$B$1:$B$3202,0),MATCH(A.Arr9sepList!G$1,manifest_11Sep!$A$1:$V$1,0))} -> 73 | H14: {=INDEX(manifest_11Sep!$A$1:$V$3202,MATCH($B14,manifest_11Sep!$B$1:$B$3202,0),MATCH(A.Arr9sepList!H$1,manifest_11Sep!$A$1:$V$1,0))} -> Alicia Nguyen 3 | I14: {=INDEX(manifest_11Sep!$A$1:$V$3202,MATCH($B14,manifest_11Sep!$B$1:$B$3202,0),MATCH(A.Arr9sepList!I$1,manifest_11Sep!$A$1:$V$1,0))} -> Asiana Airlines | J14: {=INDEX(manifest_11Sep!$A$1:$V$3202,MATCH($B14,manifest_11Sep!$B$1:$B$3202,0),MATCH(A.Arr9sepList!J$1,manifest_11Sep!$A$1:$V$1,0))} -> OZ 1135 | ... N14: {=INDEX(manifest_11Sep!$A$1:$V$3202,MATCH($B14,manifest_11Sep!$B$1:$B$3202,0),MATCH(A.Arr9sepList!N$1,manifest_11Sep!$A$1:$V$1,0))} -> JW MARRIOTT | Q14: 75985357 | R14: DOUBLE | S14: {=INDEX(manifest_11Sep!$A$1:$V$3202,MATCH($B14,manifest_11Sep!$B$1:$B$3202,0),MATCH(A.Arr9sepList!S$1,manifest_11Sep!$A$1:$V$1,0))} -> 0
A15: {=INDEX(manifest_11Sep!$A$1:$V$3202,MATCH($B15,manifest_11Sep!$B$1:$B$3202,0),MATCH(A.Arr9sepList!A$1,manifest_11Sep!$A$1:$V$1,0))} -> A | B15: 48NJJQHZ2HJ | C15: {=INDEX(manifest_11Sep!$A$1:$V$3202,MATCH($B15,manifest_11Sep!$B$1:$B$3202,0),MATCH(A.Arr9sepList!C$1,manifest_11Sep!$A$1:$V$1,0))} -> DMN6ZNXS4TH | D15: {=INDEX(manifest_11Sep!$A$1:$V$3202,MATCH($B15,manifest_11Sep!$B$1:$B$3202,0),MATCH(A.Arr9sepList!D$1,manifest_11Sep!$A$1:$V$1,0))} -> Male | E15: {=INDEX(manifest_11Sep!$A$1:$V$3202,MATCH($B15,manifest_11Sep!$B$1:$B$3202,0),MATCH(A.Arr9sepList!E$1,manifest_11Sep!$A$1:$V$1,0))} -> Emerson Quince | F15: {=INDEX(manifest_11Sep!$A$1:$V$3202,MATCH($B15,manifest_11Sep!$B$1:$B$3202,0),MATCH(A.Arr9sepList!F$1,manifest_11Sep!$A$1:$V$1,0))} -> Yee | G15: {=INDEX(manifest_11Sep!$A$1:$V$3202,MATCH($B15,manifest_11Sep!$B$1:$B$3202,0),MATCH(A.Arr9sepList!G$1,manifest_11Sep!$A$1:$V$1,0))} -> 8 | H15: {=INDEX(manifest_11Sep!$A$1:$V$3202,MATCH($B15,manifest_11Sep!$B$1:$B$3202,0),MATCH(A.Arr9sepList!H$1,manifest_11Sep!$A$1:$V$1,0))} -> Alicia Nguyen 3 | I15: {=INDEX(manifest_11Sep!$A$1:$V$3202,MATCH($B15,manifest_11Sep!$B$1:$B$3202,0),MATCH(A.Arr9sepList!I$1,manifest_11Sep!$A$1:$V$1,0))} -> Asiana Airlines | J15: {=INDEX(manifest_11Sep!$A$1:$V$3202,MATCH($B15,manifest_11Sep!$B$1:$B$3202,0),MATCH(A.Arr9sepList!J$1,manifest_11Sep!$A$1:$V$1,0))} -> OZ 1135 | ... N15: {=INDEX(manifest_11Sep!$A$1:$V$3202,MATCH($B15,manifest_11Sep!$B$1:$B$3202,0),MATCH(A.Arr9sepList!N$1,manifest_11Sep!$A$1:$V$1,0))} -> JW MARRIOTT | Q15: 75985357 | R15: DOUBLE | S15: {=INDEX(manifest_11Sep!$A$1:$V$3202,MATCH($B15,manifest_11Sep!$B$1:$B$3202,0),MATCH(A.Arr9sepList!S$1,manifest_11Sep!$A$1:$V$1,0))} -> Flight: depart with his father - Justin Yee and Phoebe Yee
A16: {=INDEX(manifest_11Sep!$A$1:$V$3202,MATCH($B16,manifest_11Sep!$B$1:$B$3202,0),MATCH(A.Arr9sepList!A$1,manifest_11Sep!$A$1:$V$1,0))} -> A | B16: SPNYHGY9GJG | C16: {=INDEX(manifest_11Sep!$A$1:$V$3202,MATCH($B16,manifest_11Sep!$B$1:$B$3202,0),MATCH(A.Arr9sepList!C$1,manifest_11Sep!$A$1:$V$1,0))} -> YWN37HR2SQL | D16: {=INDEX(manifest_11Sep!$A$1:$V$3202,MATCH($B16,manifest_11Sep!$B$1:$B$3202,0),MATCH(A.Arr9sepList!D$1,manifest_11Sep!$A$1:$V$1,0))} -> Female | E16: {=INDEX(manifest_11Sep!$A$1:$V$3202,MATCH($B16,manifest_11Sep!$B$1:$B$3202,0),MATCH(A.Arr9sepList!E$1,manifest_11Sep!$A$1:$V$1,0))} -> Elise Ha | F16: {=INDEX(manifest_11Sep!$A$1:$V$3202,MATCH($B16,manifest_11Sep!$B$1:$B$3202,0),MATCH(A.Arr9sepList!F$1,manifest_11Sep!$A$1:$V$1,0))} -> Yee | G16: {=INDEX(manifest_11Sep!$A$1:$V$3202,MATCH($B16,manifest_11Sep!$B$1:$B$3202,0),MATCH(A.Arr9sepList!G$1,manifest_11Sep!$A$1:$V$1,0))} -> 5 | H16: {=INDEX(manifest_11Sep!$A$1:$V$3202,MATCH($B16,manifest_11Sep!$B$1:$B$3202,0),MATCH(A.Arr9sepList!H$1,manifest_11Sep!$A$1:$V$1,0))} -> Alicia Nguyen 3 | I16: {=INDEX(manifest_11Sep!$A$1:$V$3202,MATCH($B16,manifest_11Sep!$B$1:$B$3202,0),MATCH(A.Arr9sepList!I$1,manifest_11Sep!$A$1:$V$1,0))} -> Asiana Airlines | J16: {=INDEX(manifest_11Sep!$A$1:$V$3202,MATCH($B16,manifest_11Sep!$B$1:$B$3202,0),MATCH(A.Arr9sepList!J$1,manifest_11Sep!$A$1:$V$1,0))} -> OZ 1135 | ... N16: {=INDEX(manifest_11Sep!$A$1:$V$3202,MATCH($B16,manifest_11Sep!$B$1:$B$3202,0),MATCH(A.Arr9sepList!N$1,manifest_11Sep!$A$1:$V$1,0))} -> JW MARRIOTT | Q16: 75985368 | R16: TWIN | S16: {=INDEX(manifest_11Sep!$A$1:$V$3202,MATCH($B16,manifest_11Sep!$B$1:$B$3202,0),MATCH(A.Arr9sepList!S$1,manifest_11Sep!$A$1:$V$1,0))} -> daughter of Justin Yee - 7JN92SVFBXK
A17: {=INDEX(manifest_11Sep!$A$1:$V$3202,MATCH($B17,manifest_11Sep!$B$1:$B$3202,0),MATCH(A.Arr9sepList!A$1,manifest_11Sep!$A$1:$V$1,0))} -> A | B17: QDN35YPZYN9 | C17: {=INDEX(manifest_11Sep!$A$1:$V$3202,MATCH($B17,manifest_11Sep!$B$1:$B$3202,0),MATCH(A.Arr9sepList!C$1,manifest_11Sep!$A$1:$V$1,0))} -> QDN35YPZYN9 | D17: {=INDEX(manifest_11Sep!$A$1:$V$3202,MATCH($B17,manifest_11Sep!$B$1:$B$3202,0),MATCH(A.Arr9sepList!D$1,manifest_11Sep!$A$1:$V$1,0))} -> Male | E17: {=INDEX(manifest_11Sep!$A$1:$V$3202,MATCH($B17,manifest_11Sep!$B$1:$B$3202,0),MATCH(A.Arr9sepList!E$1,manifest_11Sep!$A$1:$V$1,0))} -> Khanh Quoc | F17: {=INDEX(manifest_11Sep!$A$1:$V$3202,MATCH($B17,manifest_11Sep!$B$1:$B$3202,0),MATCH(A.Arr9sepList!F$1,manifest_11Sep!$A$1:$V$1,0))} -> Mac | G17: {=INDEX(manifest_11Sep!$A$1:$V$3202,MATCH($B17,manifest_11Sep!$B$1:$B$3202,0),MATCH(A.Arr9sepList!G$1,manifest_11Sep!$A$1:$V$1,0))} -> 33 | H17: {=INDEX(manifest_11Sep!$A$1:$V$3202,MATCH($B17,manifest_11Sep!$B$1:$B$3202,0),MATCH(A.Arr9sepList!H$1,manifest_11Sep!$A$1:$V$1,0))} -> Xuan Nguyen 2 | I17: {=INDEX(manifest_11Sep!$A$1:$V$3202,MATCH($B17,manifest_11Sep!$B$1:$B$3202,0),MATCH(A.Arr9sepList!I$1,manifest_11Sep!$A$1:$V$1,0))} -> Korean Air | J17: {=INDEX(manifest_11Sep!$A$1:$V$3202,MATCH($B17,manifest_11Sep!$B$1:$B$3202,0),MATCH(A.Arr9sepList!J$1,manifest_11Sep!$A$1:$V$1,0))} -> KE 1814 | ... N17: {=INDEX(manifest_11Sep!$A$1:$V$3202,MATCH($B17,manifest_11Sep!$B$1:$B$3202,0),MATCH(A.Arr9sepList!N$1,manifest_11Sep!$A$1:$V$1,0))} -> INTER PARNAS | Q17: 81715865 | R17: TWIN | S17: {=INDEX(manifest_11Sep!$A$1:$V$3202,MATCH($B17,manifest_11Sep!$B$1:$B$3202,0),MATCH(A.Arr9sepList!S$1,manifest_11Sep!$A$1:$V$1,0))} -> 0
A18: {=INDEX(manifest_11Sep!$A$1:$V$3202,MATCH($B18,manifest_11Sep!$B$1:$B$3202,0),MATCH(A.Arr9sepList!A$1,manifest_11Sep!$A$1:$V$1,0))} -> A | B18: 9SNCXXKHP4H | C18: {=INDEX(manifest_11Sep!$A$1:$V$3202,MATCH($B18,manifest_11Sep!$B$1:$B$3202,0),MATCH(A.Arr9sepList!C$1,manifest_11Sep!$A$1:$V$1,0))} -> JMNQK6XNKRC | D18: {=INDEX(manifest_11Sep!$A$1:$V$3202,MATCH($B18,manifest_11Sep!$B$1:$B$3202,0),MATCH(A.Arr9sepList!D$1,manifest_11Sep!$A$1:$V$1,0))} -> Female | E18: {=INDEX(manifest_11Sep!$A$1:$V$3202,MATCH($B18,manifest_11Sep!$B$1:$B$3202,0),MATCH(A.Arr9sepList!E$1,manifest_11Sep!$A$1:$V$1,0))} -> Joyce | F18: {=INDEX(manifest_11Sep!$A$1:$V$3202,MATCH($B18,manifest_11Sep!$B$1:$B$3202,0),MATCH(A.Arr9sepList!F$1,manifest_11Sep!$A$1:$V$1,0))} -> Yang | G18: {=INDEX(manifest_11Sep!$A$1:$V$3202,MATCH($B18,manifest_11Sep!$B$1:$B$3202,0),MATCH(A.Arr9sepList!G$1,manifest_11Sep!$A$1:$V$1,0))} -> 21 | H18: {=INDEX(manifest_11Sep!$A$1:$V$3202,MATCH($B18,manifest_11Sep!$B$1:$B$3202,0),MATCH(A.Arr9sepList!H$1,manifest_11Sep!$A$1:$V$1,0))} -> Joen De Las Penas | I18: {=INDEX(manifest_11Sep!$A$1:$V$3202,MATCH($B18,manifest_11Sep!$B$1:$B$3202,0),MATCH(A.Arr9sepList!I$1,manifest_11Sep!$A$1:$V$1,0))} -> EVA Air | J18: {=INDEX(manifest_11Sep!$A$1:$V$3202,MATCH($B18,manifest_11Sep!$B$1:$B$3202,0),MATCH(A.Arr9sepList!J$1,manifest_11Sep!$A$1:$V$1,0))} -> BR 156 | ... N18: {=INDEX(manifest_11Sep!$A$1:$V$3202,MATCH($B18,manifest_11Sep!$B$1:$B$3202,0),MATCH(A.Arr9sepList!N$1,manifest_11Sep!$A$1:$V$1,0))} -> FAIRMONT | O18: =COUNTA(N18:N21) -> 4 | Q18: 462710834 | R18: DOUBLE | S18: {=INDEX(manifest_11Sep!$A$1:$V$3202,MATCH($B18,manifest_11Sep!$B$1:$B$3202,0),MATCH(A.Arr9sepList!S$1,manifest_11Sep!$A$1:$V$1,0))} -> 0
A19: {=INDEX(manifest_11Sep!$A$1:$V$3202,MATCH($B19,manifest_11Sep!$B$1:$B$3202,0),MATCH(A.Arr9sepList!A$1,manifest_11Sep!$A$1:$V$1,0))} -> A | B19: 7FNKMG8CTXB | C19: {=INDEX(manifest_11Sep!$A$1:$V$3202,MATCH($B19,manifest_11Sep!$B$1:$B$3202,0),MATCH(A.Arr9sepList!C$1,manifest_11Sep!$A$1:$V$1,0))} -> JMNQK6XNKRC | D19: {=INDEX(manifest_11Sep!$A$1:$V$3202,MATCH($B19,manifest_11Sep!$B$1:$B$3202,0),MATCH(A.Arr9sepList!D$1,manifest_11Sep!$A$1:$V$1,0))} -> Female | E19: {=INDEX(manifest_11Sep!$A$1:$V$3202,MATCH($B19,manifest_11Sep!$B$1:$B$3202,0),MATCH(A.Arr9sepList!E$1,manifest_11Sep!$A$1:$V$1,0))} -> Jessica | F19: {=INDEX(manifest_11Sep!$A$1:$V$3202,MATCH($B19,manifest_11Sep!$B$1:$B$3202,0),MATCH(A.Arr9sepList!F$1,manifest_11Sep!$A$1:$V$1,0))} -> Yang | G19: {=INDEX(manifest_11Sep!$A$1:$V$3202,MATCH($B19,manifest_11Sep!$B$1:$B$3202,0),MATCH(A.Arr9sepList!G$1,manifest_11Sep!$A$1:$V$1,0))} -> 21 | H19: {=INDEX(manifest_11Sep!$A$1:$V$3202,MATCH($B19,manifest_11Sep!$B$1:$B$3202,0),MATCH(A.Arr9sepList!H$1,manifest_11Sep!$A$1:$V$1,0))} -> Joen De Las Penas | I19: {=INDEX(manifest_11Sep!$A$1:$V$3202,MATCH($B19,manifest_11Sep!$B$1:$B$3202,0),MATCH(A.Arr9sepList!I$1,manifest_11Sep!$A$1:$V$1,0))} -> EVA Air | J19: {=INDEX(manifest_11Sep!$A$1:$V$3202,MATCH($B19,manifest_11Sep!$B$1:$B$3202,0),MATCH(A.Arr9sepList!J$1,manifest_11Sep!$A$1:$V$1,0))} -> BR 156 | ... N19: {=INDEX(manifest_11Sep!$A$1:$V$3202,MATCH($B19,manifest_11Sep!$B$1:$B$3202,0),MATCH(A.Arr9sepList!N$1,manifest_11Sep!$A$1:$V$1,0))} -> FAIRMONT | Q19: 462710834 | R19: DOUBLE | S19: {=INDEX(manifest_11Sep!$A$1:$V$3202,MATCH($B19,manifest_11Sep!$B$1:$B$3202,0),MATCH(A.Arr9sepList!S$1,manifest_11Sep!$A$1:$V$1,0))} -> 0
A20: {=INDEX(manifest_11Sep!$A$1:$V$3202,MATCH($B20,manifest_11Sep!$B$1:$B$3202,0),MATCH(A.Arr9sepList!A$1,manifest_11Sep!$A$1:$V$1,0))} -> A | B20: PXNCBMZMDW5 | C20: {=INDEX(manifest_11Sep!$A$1:$V$3202,MATCH($B20,manifest_11Sep!$B$1:$B$3202,0),MATCH(A.Arr9sepList!C$1,manifest_11Sep!$A$1:$V$1,0))} -> PXNCBMZMDW5 | D20: {=INDEX(manifest_11Sep!$A$1:$V$3202,MATCH($B20,manifest_11Sep!$B$1:$B$3202,0),MATCH(A.Arr9sepList!D$1,manifest_11Sep!$A$1:$V$1,0))} -> Male | E20: {=INDEX(manifest_11Sep!$A$1:$V$3202,MATCH($B20,manifest_11Sep!$B$1:$B$3202,0),MATCH(A.Arr9sepList!E$1,manifest_11Sep!$A$1:$V$1,0))} -> Ahsan | F20: {=INDEX(manifest_11Sep!$A$1:$V$3202,MATCH($B20,manifest_11Sep!$B$1:$B$3202,0),MATCH(A.Arr9sepList!F$1,manifest_11Sep!$A$1:$V$1,0))} -> Qutub | G20: {=INDEX(manifest_11Sep!$A$1:$V$3202,MATCH($B20,manifest_11Sep!$B$1:$B$3202,0),MATCH(A.Arr9sepList!G$1,manifest_11Sep!$A$1:$V$1,0))} -> 63 | H20: {=INDEX(manifest_11Sep!$A$1:$V$3202,MATCH($B20,manifest_11Sep!$B$1:$B$3202,0),MATCH(A.Arr9sepList!H$1,manifest_11Sep!$A$1:$V$1,0))} -> John Woo 2 | I20: {=INDEX(manifest_11Sep!$A$1:$V$3202,MATCH($B20,manifest_11Sep!$B$1:$B$3202,0),MATCH(A.Arr9sepList!I$1,manifest_11Sep!$A$1:$V$1,0))} -> Jeju Air | J20: {=INDEX(manifest_11Sep!$A$1:$V$3202,MATCH($B20,manifest_11Sep!$B$1:$B$3202,0),MATCH(A.Arr9sepList!J$1,manifest_11Sep!$A$1:$V$1,0))} -> 7C 118 | ... N20: {=INDEX(manifest_11Sep!$A$1:$V$3202,MATCH($B20,manifest_11Sep!$B$1:$B$3202,0),MATCH(A.Arr9sepList!N$1,manifest_11Sep!$A$1:$V$1,0))} -> LOTTE | Q20: 15262430 | R20: TWIN | S20: {=INDEX(manifest_11Sep!$A$1:$V$3202,MATCH($B20,manifest_11Sep!$B$1:$B$3202,0),MATCH(A.Arr9sepList!S$1,manifest_11Sep!$A$1:$V$1,0))} -> 0
A21: {=INDEX(manifest_11Sep!$A$1:$V$3202,MATCH($B21,manifest_11Sep!$B$1:$B$3202,0),MATCH(A.Arr9sepList!A$1,manifest_11Sep!$A$1:$V$1,0))} -> A | B21: 6QN7PT6JST9 | C21: {=INDEX(manifest_11Sep!$A$1:$V$3202,MATCH($B21,manifest_11Sep!$B$1:$B$3202,0),MATCH(A.Arr9sepList!C$1,manifest_11Sep!$A$1:$V$1,0))} -> PXNCBMZMDW5 | D21: {=INDEX(manifest_11Sep!$A$1:$V$3202,MATCH($B21,manifest_11Sep!$B$1:$B$3202,0),MATCH(A.Arr9sepList!D$1,manifest_11Sep!$A$1:$V$1,0))} -> Female | E21: {=INDEX(manifest_11Sep!$A$1:$V$3202,MATCH($B21,manifest_11Sep!$B$1:$B$3202,0),MATCH(A.Arr9sepList!E$1,manifest_11Sep!$A$1:$V$1,0))} -> Kamrun | F21: {=INDEX(manifest_11Sep!$A$1:$V$3202,MATCH($B21,manifest_11Sep!$B$1:$B$3202,0),MATCH(A.Arr9sepList!F$1,manifest_11Sep!$A$1:$V$1,0))} -> Nahar | G21: {=INDEX(manifest_11Sep!$A$1:$V$3202,MATCH($B21,manifest_11Sep!$B$1:$B$3202,0),MATCH(A.Arr9sepList!G$1,manifest_11Sep!$A$1:$V$1,0))} -> 57 | H21: {=INDEX(manifest_11Sep!$A$1:$V$3202,MATCH($B21,manifest_11Sep!$B$1:$B$3202,0),MATCH(A.Arr9sepList!H$1,manifest_11Sep!$A$1:$V$1,0))} -> John Woo 2 | I21: {=INDEX(manifest_11Sep!$A$1:$V$3202,MATCH($B21,manifest_11Sep!$B$1:$B$3202,0),MATCH(A.Arr9sepList!I$1,manifest_11Sep!$A$1:$V$1,0))} -> Jeju Air | J21: {=INDEX(manifest_11Sep!$A$1:$V$3202,MATCH($B21,manifest_11Sep!$B$1:$B$3202,0),MATCH(A.Arr9sepList!J$1,manifest_11Sep!$A$1:$V$1,0))} -> 7C 118 | ... N21: {=INDEX(manifest_11Sep!$A$1:$V$3202,MATCH($B21,manifest_11Sep!$B$1:$B$3202,0),MATCH(A.Arr9sepList!N$1,manifest_11Sep!$A$1:$V$1,0))} -> LOTTE | Q21: 15262430 | R21: TWIN | S21: {=INDEX(manifest_11Sep!$A$1:$V$3202,MATCH($B21,manifest_11Sep!$B$1:$B$3202,0),MATCH(A.Arr9sepList!S$1,manifest_11Sep!$A$1:$V$1,0))} -> 0
A22: {=INDEX(manifest_11Sep!$A$1:$V$3202,MATCH($B22,manifest_11Sep!$B$1:$B$3202,0),MATCH(A.Arr9sepList!A$1,manifest_11Sep!$A$1:$V$1,0))} -> A | B22: 7TN5Q8CM4HS | C22: {=INDEX(manifest_11Sep!$A$1:$V$3202,MATCH($B22,manifest_11Sep!$B$1:$B$3202,0),MATCH(A.Arr9sepList!C$1,manifest_11Sep!$A$1:$V$1,0))} -> 7TN5Q8CM4HS | D22: {=INDEX(manifest_11Sep!$A$1:$V$3202,MATCH($B22,manifest_11Sep!$B$1:$B$3202,0),MATCH(A.Arr9sepList!D$1,manifest_11Sep!$A$1:$V$1,0))} -> Female | E22: {=INDEX(manifest_11Sep!$A$1:$V$3202,MATCH($B22,manifest_11Sep!$B$1:$B$3202,0),MATCH(A.Arr9sepList!E$1,manifest_11Sep!$A$1:$V$1,0))} -> Alicia | F22: {=INDEX(manifest_11Sep!$A$1:$V$3202,MATCH($B22,manifest_11Sep!$B$1:$B$3202,0),MATCH(A.Arr9sepList!F$1,manifest_11Sep!$A$1:$V$1,0))} -> Dalao | G22: {=INDEX(manifest_11Sep!$A$1:$V$3202,MATCH($B22,manifest_11Sep!$B$1:$B$3202,0),MATCH(A.Arr9sepList!G$1,manifest_11Sep!$A$1:$V$1,0))} -> 61 | H22: {=INDEX(manifest_11Sep!$A$1:$V$3202,MATCH($B22,manifest_11Sep!$B$1:$B$3202,0),MATCH(A.Arr9sepList!H$1,manifest_11Sep!$A$1:$V$1,0))} -> Joen De Las Penas | I22: {=INDEX(manifest_11Sep!$A$1:$V$3202,MATCH($B22,manifest_11Sep!$B$1:$B$3202,0),MATCH(A.Arr9sepList!I$1,manifest_11Sep!$A$1:$V$1,0))} -> Jeju Air | J22: {=INDEX(manifest_11Sep!$A$1:$V$3202,MATCH($B22,manifest_11Sep!$B$1:$B$3202,0),MATCH(A.Arr9sepList!J$1,manifest_11Sep!$A$1:$V$1,0))} -> 7C 120 | ... N22: {=INDEX(manifest_11Sep!$A$1:$V$3202,MATCH($B22,manifest_11Sep!$B$1:$B$3202,0),MATCH(A.Arr9sepList!N$1,manifest_11Sep!$A$1:$V$1,0))} -> FAIRMONT | O22: =COUNTA(N22:N43) -> 22 | Q22: 462710812 | R22: DOUBLE | S22: {=INDEX(manifest_11Sep!$A$1:$V$3202,MATCH($B22,manifest_11Sep!$B$1:$B$3202,0),MATCH(A.Arr9sepList!S$1,manifest_11Sep!$A$1:$V$1,0))} -> 0
A23: {=INDEX(manifest_11Sep!$A$1:$V$3202,MATCH($B23,manifest_11Sep!$B$1:$B$3202,0),MATCH(A.Arr9sepList!A$1,manifest_11Sep!$A$1:$V$1,0))} -> A | B23: YFNPJ37HLGN | C23: {=INDEX(manifest_11Sep!$A$1:$V$3202,MATCH($B23,manifest_11Sep!$B$1:$B$3202,0),MATCH(A.Arr9sepList!C$1,manifest_11Sep!$A$1:$V$1,0))} -> 7TN5Q8CM4HS | D23: {=INDEX(manifest_11Sep!$A$1:$V$3202,MATCH($B23,manifest_11Sep!$B$1:$B$3202,0),MATCH(A.Arr9sepList!D$1,manifest_11Sep!$A$1:$V$1,0))} -> Female | E23: {=INDEX(manifest_11Sep!$A$1:$V$3202,MATCH($B23,manifest_11Sep!$B$1:$B$3202,0),MATCH(A.Arr9sepList!E$1,manifest_11Sep!$A$1:$V$1,0))} -> Priscilla | F23: {=INDEX(manifest_11Sep!$A$1:$V$3202,MATCH($B23,manifest_11Sep!$B$1:$B$3202,0),MATCH(A.Arr9sepList!F$1,manifest_11Sep!$A$1:$V$1,0))} -> Galicia | G23: {=INDEX(manifest_11Sep!$A$1:$V$3202,MATCH($B23,manifest_11Sep!$B$1:$B$3202,0),MATCH(A.Arr9sepList!G$1,manifest_11Sep!$A$1:$V$1,0))} -> 69 | H23: {=INDEX(manifest_11Sep!$A$1:$V$3202,MATCH($B23,manifest_11Sep!$B$1:$B$3202,0),MATCH(A.Arr9sepList!H$1,manifest_11Sep!$A$1:$V$1,0))} -> Joen De Las Penas | I23: {=INDEX(manifest_11Sep!$A$1:$V$3202,MATCH($B23,manifest_11Sep!$B$1:$B$3202,0),MATCH(A.Arr9sepList!I$1,manifest_11Sep!$A$1:$V$1,0))} -> Jeju Air | J23: {=INDEX(manifest_11Sep!$A$1:$V$3202,MATCH($B23,manifest_11Sep!$B$1:$B$3202,0),MATCH(A.Arr9sepList!J$1,manifest_11Sep!$A$1:$V$1,0))} -> 7C 120 | ... N23: {=INDEX(manifest_11Sep!$A$1:$V$3202,MATCH($B23,manifest_11Sep!$B$1:$B$3202,0),MATCH(A.Arr9sepList!N$1,manifest_11Sep!$A$1:$V$1,0))} -> FAIRMONT | Q23: 462710812 | R23: DOUBLE | S23: {=INDEX(manifest_11Sep!$A$1:$V$3202,MATCH($B23,manifest_11Sep!$B$1:$B$3202,0),MATCH(A.Arr9sepList!S$1,manifest_11Sep!$A$1:$V$1,0))} -> 0
A24: {=INDEX(manifest_11Sep!$A$1:$V$3202,MATCH($B24,manifest_11Sep!$B$1:$B$3202,0),MATCH(A.Arr9sepList!A$1,manifest_11Sep!$A$1:$V$1,0))} -> A | B24: YCN43KDXZS6 | C24: {=INDEX(manifest_11Sep!$A$1:$V$3202,MATCH($B24,manifest_11Sep!$B$1:$B$3202,0),MATCH(A.Arr9sepList!C$1,manifest_11Sep!$A$1:$V$1,0))} -> BLNR9SJYXPX | D24: {=INDEX(manifest_11Sep!$A$1:$V$3202,MATCH($B24,manifest_11Sep!$B$1:$B$3202,0),MATCH(A.Arr9sepList!D$1,manifest_11Sep!$A$1:$V$1,0))} -> Female | E24: {=INDEX(manifest_11Sep!$A$1:$V$3202,MATCH($B24,manifest_11Sep!$B$1:$B$3202,0),MATCH(A.Arr9sepList!E$1,manifest_11Sep!$A$1:$V$1,0))} -> Rose Mary | F24: {=INDEX(manifest_11Sep!$A$1:$V$3202,MATCH($B24,manifest_11Sep!$B$1:$B$3202,0),MATCH(A.Arr9sepList!F$1,manifest_11Sep!$A$1:$V$1,0))} -> Scott | G24: {=INDEX(manifest_11Sep!$A$1:$V$3202,MATCH($B24,manifest_11Sep!$B$1:$B$3202,0),MATCH(A.Arr9sepList!G$1,manifest_11Sep!$A$1:$V$1,0))} -> 61 | H24: {=INDEX(manifest_11Sep!$A$1:$V$3202,MATCH($B24,manifest_11Sep!$B$1:$B$3202,0),MATCH(A.Arr9sepList!H$1,manifest_11Sep!$A$1:$V$1,0))} -> Joen De Las Penas | I24: {=INDEX(manifest_11Sep!$A$1:$V$3202,MATCH($B24,manifest_11Sep!$B$1:$B$3202,0),MATCH(A.Arr9sepList!I$1,manifest_11Sep!$A$1:$V$1,0))} -> Jeju Air | J24: {=INDEX(manifest_11Sep!$A$1:$V$3202,MATCH($B24,manifest_11Sep!$B$1:$B$3202,0),MATCH(A.Arr9sepList!J$1,manifest_11Sep!$A$1:$V$1,0))} -> 7C 120 | ... N24: {=INDEX(manifest_11Sep!$A$1:$V$3202,MATCH($B24,manifest_11Sep!$B$1:$B$3202,0),MATCH(A.Arr9sepList!N$1,manifest_11Sep!$A$1:$V$1,0))} -> FAIRMONT | Q24: 462710819 | R24: TWIN | S24: {=INDEX(manifest_11Sep!$A$1:$V$3202,MATCH($B24,manifest_11Sep!$B$1:$B$3202,0),MATCH(A.Arr9sepList!S$1,manifest_11Sep!$A$1:$V$1,0))} -> 0
A25: {=INDEX(manifest_11Sep!$A$1:$V$3202,MATCH($B25,manifest_11Sep!$B$1:$B$3202,0),MATCH(A.Arr9sepList!A$1,manifest_11Sep!$A$1:$V$1,0))} -> A | B25: 72NVG3BWNVW | C25: {=INDEX(manifest_11Sep!$A$1:$V$3202,MATCH($B25,manifest_11Sep!$B$1:$B$3202,0),MATCH(A.Arr9sepList!C$1,manifest_11Sep!$A$1:$V$1,0))} -> 72NVG3BWNVW | D25: {=INDEX(manifest_11Sep!$A$1:$V$3202,MATCH($B25,manifest_11Sep!$B$1:$B$3202,0),MATCH(A.Arr9sepList!D$1,manifest_11Sep!$A$1:$V$1,0))} -> Female | E25: {=INDEX(manifest_11Sep!$A$1:$V$3202,MATCH($B25,manifest_11Sep!$B$1:$B$3202,0),MATCH(A.Arr9sepList!E$1,manifest_11Sep!$A$1:$V$1,0))} -> Syntra Audra | F25: {=INDEX(manifest_11Sep!$A$1:$V$3202,MATCH($B25,manifest_11Sep!$B$1:$B$3202,0),MATCH(A.Arr9sepList!F$1,manifest_11Sep!$A$1:$V$1,0))} -> John | G25: {=INDEX(manifest_11Sep!$A$1:$V$3202,MATCH($B25,manifest_11Sep!$B$1:$B$3202,0),MATCH(A.Arr9sepList!G$1,manifest_11Sep!$A$1:$V$1,0))} -> 54 | H25: {=INDEX(manifest_11Sep!$A$1:$V$3202,MATCH($B25,manifest_11Sep!$B$1:$B$3202,0),MATCH(A.Arr9sepList!H$1,manifest_11Sep!$A$1:$V$1,0))} -> Racquel Slawinski | I25: {=INDEX(manifest_11Sep!$A$1:$V$3202,MATCH($B25,manifest_11Sep!$B$1:$B$3202,0),MATCH(A.Arr9sepList!I$1,manifest_11Sep!$A$1:$V$1,0))} -> T'way Air | J25: {=INDEX(manifest_11Sep!$A$1:$V$3202,MATCH($B25,manifest_11Sep!$B$1:$B$3202,0),MATCH(A.Arr9sepList!J$1,manifest_11Sep!$A$1:$V$1,0))} -> TW 720 | ... N25: {=INDEX(manifest_11Sep!$A$1:$V$3202,MATCH($B25,manifest_11Sep!$B$1:$B$3202,0),MATCH(A.Arr9sepList!N$1,manifest_11Sep!$A$1:$V$1,0))} -> INTER PARNAS | Q25: 81702052 | R25: DOUBLE | S25: {=INDEX(manifest_11Sep!$A$1:$V$3202,MATCH($B25,manifest_11Sep!$B$1:$B$3202,0),MATCH(A.Arr9sepList!S$1,manifest_11Sep!$A$1:$V$1,0))} -> Upgrade - Club Junior Suite
A26: {=INDEX(manifest_11Sep!$A$1:$V$3202,MATCH($B26,manifest_11Sep!$B$1:$B$3202,0),MATCH(A.Arr9sepList!A$1,manifest_11Sep!$A$1:$V$1,0))} -> A | B26: WFN487T9RRS | C26: {=INDEX(manifest_11Sep!$A$1:$V$3202,MATCH($B26,manifest_11Sep!$B$1:$B$3202,0),MATCH(A.Arr9sepList!C$1,manifest_11Sep!$A$1:$V$1,0))} -> 72NVG3BWNVW | D26: {=INDEX(manifest_11Sep!$A$1:$V$3202,MATCH($B26,manifest_11Sep!$B$1:$B$3202,0),MATCH(A.Arr9sepList!D$1,manifest_11Sep!$A$1:$V$1,0))} -> Male | E26: {=INDEX(manifest_11Sep!$A$1:$V$3202,MATCH($B26,manifest_11Sep!$B$1:$B$3202,0),MATCH(A.Arr9sepList!E$1,manifest_11Sep!$A$1:$V$1,0))} -> Basdeo | F26: {=INDEX(manifest_11Sep!$A$1:$V$3202,MATCH($B26,manifest_11Sep!$B$1:$B$3202,0),MATCH(A.Arr9sepList!F$1,manifest_11Sep!$A$1:$V$1,0))} -> John | G26: {=INDEX(manifest_11Sep!$A$1:$V$3202,MATCH($B26,manifest_11Sep!$B$1:$B$3202,0),MATCH(A.Arr9sepList!G$1,manifest_11Sep!$A$1:$V$1,0))} -> 56 | H26: {=INDEX(manifest_11Sep!$A$1:$V$3202,MATCH($B26,manifest_11Sep!$B$1:$B$3202,0),MATCH(A.Arr9sepList!H$1,manifest_11Sep!$A$1:$V$1,0))} -> Racquel Slawinski | I26: {=INDEX(manifest_11Sep!$A$1:$V$3202,MATCH($B26,manifest_11Sep!$B$1:$B$3202,0),MATCH(A.Arr9sepList!I$1,manifest_11Sep!$A$1:$V$1,0))} -> T'way Air | J26: {=INDEX(manifest_11Sep!$A$1:$V$3202,MATCH($B26,manifest_11Sep!$B$1:$B$3202,0),MATCH(A.Arr9sepList!J$1,manifest_11Sep!$A$1:$V$1,0))} -> TW 720 | ... N26: {=INDEX(manifest_11Sep!$A$1:$V$3202,MATCH($B26,manifest_11Sep!$B$1:$B$3202,0),MATCH(A.Arr9sepList!N$1,manifest_11Sep!$A$1:$V$1,0))} -> INTER PARNAS | Q26: 81702052 | R26: DOUBLE | S26: {=INDEX(manifest_11Sep!$A$1:$V$3202,MATCH($B26,manifest_11Sep!$B$1:$B$3202,0),MATCH(A.Arr9sepList!S$1,manifest_11Sep!$A$1:$V$1,0))} -> 0
A27: {=INDEX(manifest_11Sep!$A$1:$V$3202,MATCH($B27,manifest_11Sep!$B$1:$B$3202,0),MATCH(A.Arr9sepList!A$1,manifest_11Sep!$A$1:$V$1,0))} -> A | B27: 76NFBLGRYJC | C27: {=INDEX(manifest_11Sep!$A$1:$V$3202,MATCH($B27,manifest_11Sep!$B$1:$B$3202,0),MATCH(A.Arr9sepList!C$1,manifest_11Sep!$A$1:$V$1,0))} -> 6YNQJJKHX3V | D27: {=INDEX(manifest_11Sep!$A$1:$V$3202,MATCH($B27,manifest_11Sep!$B$1:$B$3202,0),MATCH(A.Arr9sepList!D$1,manifest_11Sep!$A$1:$V$1,0))} -> Male | E27: {=INDEX(manifest_11Sep!$A$1:$V$3202,MATCH($B27,manifest_11Sep!$B$1:$B$3202,0),MATCH(A.Arr9sepList!E$1,manifest_11Sep!$A$1:$V$1,0))} -> Yao Zong | F27: {=INDEX(manifest_11Sep!$A$1:$V$3202,MATCH($B27,manifest_11Sep!$B$1:$B$3202,0),MATCH(A.Arr9sepList!F$1,manifest_11Sep!$A$1:$V$1,0))} -> Lu | G27: {=INDEX(manifest_11Sep!$A$1:$V$3202,MATCH($B27,manifest_11Sep!$B$1:$B$3202,0),MATCH(A.Arr9sepList!G$1,manifest_11Sep!$A$1:$V$1,0))} -> 44 | H27: {=INDEX(manifest_11Sep!$A$1:$V$3202,MATCH($B27,manifest_11Sep!$B$1:$B$3202,0),MATCH(A.Arr9sepList!H$1,manifest_11Sep!$A$1:$V$1,0))} -> Joen De Las Penas | I27: {=INDEX(manifest_11Sep!$A$1:$V$3202,MATCH($B27,manifest_11Sep!$B$1:$B$3202,0),MATCH(A.Arr9sepList!I$1,manifest_11Sep!$A$1:$V$1,0))} -> Jeju Air | J27: {=INDEX(manifest_11Sep!$A$1:$V$3202,MATCH($B27,manifest_11Sep!$B$1:$B$3202,0),MATCH(A.Arr9sepList!J$1,manifest_11Sep!$A$1:$V$1,0))} -> 7C 122 | ... N27: {=INDEX(manifest_11Sep!$A$1:$V$3202,MATCH($B27,manifest_11Sep!$B$1:$B$3202,0),MATCH(A.Arr9sepList!N$1,manifest_11Sep!$A$1:$V$1,0))} -> FAIRMONT | Q27: 462710818 | R27: TWIN | S27: {=INDEX(manifest_11Sep!$A$1:$V$3202,MATCH($B27,manifest_11Sep!$B$1:$B$3202,0),MATCH(A.Arr9sepList!S$1,manifest_11Sep!$A$1:$V$1,0))} -> assign photo book for guest, Yao Lu
A28: {=INDEX(manifest_11Sep!$A$1:$V$3202,MATCH($B28,manifest_11Sep!$B$1:$B$3202,0),MATCH(A.Arr9sepList!A$1,manifest_11Sep!$A$1:$V$1,0))} -> A | B28: BLNR9SJYXPX | C28: {=INDEX(manifest_11Sep!$A$1:$V$3202,MATCH($B28,manifest_11Sep!$B$1:$B$3202,0),MATCH(A.Arr9sepList!C$1,manifest_11Sep!$A$1:$V$1,0))} -> BLNR9SJYXPX | D28: {=INDEX(manifest_11Sep!$A$1:$V$3202,MATCH($B28,manifest_11Sep!$B$1:$B$3202,0),MATCH(A.Arr9sepList!D$1,manifest_11Sep!$A$1:$V$1,0))} -> Female | E28: {=INDEX(manifest_11Sep!$A$1:$V$3202,MATCH($B28,manifest_11Sep!$B$1:$B$3202,0),MATCH(A.Arr9sepList!E$1,manifest_11Sep!$A$1:$V$1,0))} -> Susan Wambui | F28: {=INDEX(manifest_11Sep!$A$1:$V$3202,MATCH($B28,manifest_11Sep!$B$1:$B$3202,0),MATCH(A.Arr9sepList!F$1,manifest_11Sep!$A$1:$V$1,0))} -> Kamau | G28: {=INDEX(manifest_11Sep!$A$1:$V$3202,MATCH($B28,manifest_11Sep!$B$1:$B$3202,0),MATCH(A.Arr9sepList!G$1,manifest_11Sep!$A$1:$V$1,0))} -> 30 | H28: {=INDEX(manifest_11Sep!$A$1:$V$3202,MATCH($B28,manifest_11Sep!$B$1:$B$3202,0),MATCH(A.Arr9sepList!H$1,manifest_11Sep!$A$1:$V$1,0))} -> Joen De Las Penas | I28: {=INDEX(manifest_11Sep!$A$1:$V$3202,MATCH($B28,manifest_11Sep!$B$1:$B$3202,0),MATCH(A.Arr9sepList!I$1,manifest_11Sep!$A$1:$V$1,0))} -> Jeju Air | J28: {=INDEX(manifest_11Sep!$A$1:$V$3202,MATCH($B28,manifest_11Sep!$B$1:$B$3202,0),MATCH(A.Arr9sepList!J$1,manifest_11Sep!$A$1:$V$1,0))} -> 7C 122 | ... N28: {=INDEX(manifest_11Sep!$A$1:$V$3202,MATCH($B28,manifest_11Sep!$B$1:$B$3202,0),MATCH(A.Arr9sepList!N$1,manifest_11Sep!$A$1:$V$1,0))} -> FAIRMONT | Q28: 462710819 | R28: TWIN | S28: {=INDEX(manifest_11Sep!$A$1:$V$3202,MATCH($B28,manifest_11Sep!$B$1:$B$3202,0),MATCH(A.Arr9sepList!S$1,manifest_11Sep!$A$1:$V$1,0))} -> 0
